Workbook
Name Macrobond_Object1: Macrobond!$A$3:$PB$957

Sheet Print Summary
A1: ="CPI PRINT SUMMARY — "&UPPER(TEXT(Engine!$B$5,"mmmm yyyy")) -> CPI PRINT SUMMARY — MAY 2026
A2: 5-minute desk read | All figures seasonally adjusted | Detail: Momentum · Breadth · PCE Bridge tabs
B3: ="CORE: "&Engine!$AG$12&" | HEADLINE: "&Engine!$AG$11&" | SUPERCORE: "&Engine!$AG$19 -> CORE: ▼ TURN DN | HEADLINE: ▼ TURN DN | SUPERCORE: ▲▲ ACCEL
B5: HEADLINE M/M | D5: CORE M/M | F5: HEADLINE Y/Y | H5: CORE Y/Y | J5: CORE 3M SAAR | L5: IMPLIED CORE PCE M/M
B6: =Engine!$W$11 -> 0.0047291423 | D6: =Engine!$W$12 -> 0.0020809545 | F6: =Engine!$Z$11 -> 0.041666147 | H6: =Engine!$Z$12 -> 0.028229421 | J6: =Engine!$AC$12 -> 0.031660324 | L6: ='PCE Bridge'!$D$50 -> 0.0021865118
B8: MOMENTUM STACK (SAAR)
C9: 1m SAAR | D9: 3m SAAR | E9: 6m SAAR | F9: Y/Y | G9: Signal
B10: Headline CPI | C10: =Engine!$AB$11 -> 0.058249301 | D10: =Engine!$AC$11 -> 0.082040733 | E10: =Engine!$AD$11 -> 0.055609383 | F10: =Engine!$Z$11 -> 0.041666147 | G10: =Engine!$AG$11 -> ▼ TURN DN
B11: Core CPI | C11: =Engine!$AB$12 -> 0.02525925 | D11: =Engine!$AC$12 -> 0.031660324 | E11: =Engine!$AD$12 -> 0.030914091 | F11: =Engine!$Z$12 -> 0.028229421 | G11: =Engine!$AG$12 -> ▼ TURN DN
B12: Supercore (svcs ex shelter/energy) | C12: =Engine!$AB$19 -> 0.070995747 | D12: =Engine!$AC$19 -> 0.045879594 | E12: =Engine!$AD$19 -> 0.039115572 | F12: =Engine!$Z$19 -> 0.035482623 | G12: =Engine!$AG$19 -> ▲▲ ACCEL
B13: Core Goods ex Used Veh. | C13: =Engine!$AB$17 -> -0.017778419 | D13: =Engine!$AC$17 -> 0.0033956747 | E13: =Engine!$AD$17 -> 0.015289127 | F13: =Engine!$Z$17 -> 0.015732175 | G13: =Engine!$AG$17 -> ▼▼ DECEL
B14: Shelter | C14: =Engine!$AB$23 -> 0.038813528 | D14: =Engine!$AC$23 -> 0.048681725 | E14: =Engine!$AD$23 -> 0.041267773 | F14: =Engine!$Z$23 -> 0.033539479 | G14: =Engine!$AG$23 -> ▼ TURN DN
B16: TAKEAWAYS
B17: ="• Headline "&TEXT(Engine!$W$11,"+0.0%;-0.0%")&" m/m / "&TEXT(Engine!$Z$11,"0.0%")&" y/y; core "&TEXT(Engine!$W$12,"+0.00%;-0.00%")&" m/m / "&TEXT(Engine!$Z$12,"0.0%")&" y/y." -> • Headline +0.5% m/m / 4.2% y/y; core +0.21% m/m / 2.8% y/y.
B18: ="• Energy "&TEXT(Engine!$W$14,"+0.0%;-0.0%")&" m/m ("&TEXT(Engine!$AH$14,"+0.00;-0.00")&"pp of headline); food "&TEXT(Engine!$W$13,"+0.0%;-0.0%")&" ("&TEXT(Engine!$AH$13,"+0.00;-0.00")&"pp)." -> • Energy +3.8% m/m (+0.28pp of headline); food +0.2% (+0.02pp).
B19: ="• Core momentum: 1m SAAR "&TEXT(Engine!$AB$12,"0.0%")&" vs 3m "&TEXT(Engine!$AC$12,"0.0%")&" vs 6m "&TEXT(Engine!$AD$12,"0.0%")&"; supercore 1m "&TEXT(Engine!$AB$19,"0.0%")&" vs 3m "&TEXT(Engine!$AC$19,"0.0%")&"." -> • Core momentum: 1m SAAR 2.5% vs 3m 3.2% vs 6m 3.1%; supercore 1m 7.1% vs 3m 4.6%.
B20: ="• Breadth: "&TEXT(Breadth!$D$22,"0%")&" of components accelerating m/m (prior "&TEXT(Breadth!$E$22,"0%")&"); "&TEXT(Breadth!$D$25,"0%")&" running >4% on 3m SAAR; median m/m "&TEXT(Breadth!$D$26,"0.00%")&"." -> • Breadth: 32% of components accelerating m/m (prior 57%); 46% running >4% on 3m SAAR; median m/m 0.29%.
B21: ="• Top contributor: "&Breadth!$A$6&" ("&TEXT(Breadth!$D$6,"+0.000;-0.000")&"pp); top drag: "&Breadth!$G$6&" ("&TEXT(Breadth!$J$6,"+0.000;-0.000")&"pp). Top core: "&Breadth!$A$14&" ("&TEXT(Breadth!$D$14,"+0.000;-0.000")&"pp)." -> • Top contributor: Motor Fuel (+0.266pp); top drag: MV Insurance (-0.044pp). Top core: Owners' Equivalent Rent (+0.098pp).
B22: ="• PCE read-through: implied core PCE "&TEXT('PCE Bridge'!$D$50,"+0.00%;-0.00%")&" m/m ("&TEXT('PCE Bridge'!$D$51,"0.0%")&" annualized) — "&'PCE Bridge'!$D$54&"." -> • PCE read-through: implied core PCE +0.22% m/m (2.7% annualized) — WARM — modestly above 2% target pace.
B24: ="Auto-generated from Macrobond BLS pull (latest: "&TEXT(Engine!$B$5,"mmm-yy")&") and BEA nominal PCE (weights: "&TEXT('PCE Bridge'!$B$5,"mmm-yy")&"). New months flow through automatically. Weights: BLS RI Dec-2025; PCE = nominal core shares." -> Auto-generated from Macrobond BLS pull (latest: May-26) and BEA nominal PCE (weights: Mar-26). New months flow through automatically. Weights: BLS RI Dec-2025; PCE = nominal core shares.

Sheet Momentum
A1: CPI MOMENTUM & TREND TRACKER
A2: ="Latest print: "&TEXT(Engine!$B$5,"mmmm yyyy")&" | All SAAR figures are seasonally adjusted annualized rates | Heatmap = m/m % chg, trailing 13 months" -> Latest print: May 2026 | All SAAR figures are seasonally adjusted annualized rates | Heatmap = m/m % chg, trailing 13 months
N4: 1 | O4: 2 | P4: 3 | Q4: 4 | R4: 5 | S4: 6 | T4: 7 | U4: 8 | V4: 9 | W4: 10 | X4: 11 | Y4: 12 | Z4: 13
A5: Component | B5: Bucket | C5: Wt % | D5: M/M | E5: M/M -1 | F5: Y/Y | G5: Y/Y -1 | H5: 1m SAAR | I5: 3m SAAR | J5: 6m SAAR | K5: Δ 1m-3m | L5: Δ 3m-6m | M5: SIGNAL | N5: =TEXT(EDATE(Engine!$B$5,1-N$4),"mmm-yy") -> May-26 | O5: =TEXT(EDATE(Engine!$B$5,1-O$4),"mmm-yy") -> Apr-26 | P5: =TEXT(EDATE(Engine!$B$5,1-P$4),"mmm-yy") -> Mar-26 | Q5: =TEXT(EDATE(Engine!$B$5,1-Q$4),"mmm-yy") -> Feb-26 | R5: =TEXT(EDATE(Engine!$B$5,1-R$4),"mmm-yy") -> Jan-26 | S5: =TEXT(EDATE(Engine!$B$5,1-S$4),"mmm-yy") -> Dec-25 | T5: =TEXT(EDATE(Engine!$B$5,1-T$4),"mmm-yy") -> Nov-25 | U5: =TEXT(EDATE(Engine!$B$5,1-U$4),"mmm-yy") -> Oct-25 | ... Z5: =TEXT(EDATE(Engine!$B$5,1-Z$4),"mmm-yy") -> May-25
A6: =Engine!A11 -> All Items (CPI-U) | B6: =Engine!B11 -> AGG | C6: =Engine!V11 -> 100 | D6: =Engine!W11 -> 0.0047291423 | E6: =Engine!X11 -> 0.0064003778 | F6: =Engine!Z11 -> 0.041666147 | G6: =Engine!AA11 -> 0.037792458 | H6: =Engine!AB11 -> 0.058249301 | I6: =Engine!AC11 -> 0.082040733 | J6: =Engine!AD11 -> 0.055609383 | K6: =Engine!AE11 -> -0.023791432 | L6: =Engine!AF11 -> 0.026431351 | M6: =Engine!AG11 -> ▼ TURN DN | N6: {=INDEX(Engine!$H11:$U11,1,N$4)/INDEX(Engine!$H11:$U11,1,N$4+1)-1} -> 0.0047291423 | O6: {=INDEX(Engine!$H11:$U11,1,O$4)/INDEX(Engine!$H11:$U11,1,O$4+1)-1} -> 0.0064003778 | P6: {=INDEX(Engine!$H11:$U11,1,P$4)/INDEX(Engine!$H11:$U11,1,P$4+1)-1} -> 0.0086514383 | Q6: {=INDEX(Engine!$H11:$U11,1,Q$4)/INDEX(Engine!$H11:$U11,1,Q$4+1)-1} -> 0.0026700307 | R6: {=INDEX(Engine!$H11:$U11,1,R$4)/INDEX(Engine!$H11:$U11,1,R$4+1)-1} -> 0.0017084265 | S6: {=INDEX(Engine!$H11:$U11,1,S$4)/INDEX(Engine!$H11:$U11,1,S$4+1)-1} -> 0.0029778843 | T6: {=INDEX(Engine!$H11:$U11,1,T$4)/INDEX(Engine!$H11:$U11,1,T$4+1)-1} -> 0.0025227837 | U6: {=INDEX(Engine!$H11:$U11,1,U$4)/INDEX(Engine!$H11:$U11,1,U$4+1)-1} -> 0 | ... Z6: {=INDEX(Engine!$H11:$U11,1,Z$4)/INDEX(Engine!$H11:$U11,1,Z$4+1)-1} -> 0.00099281303
A7: =Engine!A12 -> Core CPI (ex Food & Energy) | B7: =Engine!B12 -> AGG | C7: =Engine!V12 -> 79.02977 | D7: =Engine!W12 -> 0.0020809545 | E7: =Engine!X12 -> 0.0037646073 | F7: =Engine!Z12 -> 0.028229421 | G7: =Engine!AA12 -> 0.027433094 | H7: =Engine!AB12 -> 0.02525925 | I7: =Engine!AC12 -> 0.031660324 | J7: =Engine!AD12 -> 0.030914091 | K7: =Engine!AE12 -> -0.0064010741 | L7: =Engine!AF12 -> 0.00074623331 | M7: =Engine!AG12 -> ▼ TURN DN | N7: {=INDEX(Engine!$H12:$U12,1,N$4)/INDEX(Engine!$H12:$U12,1,N$4+1)-1} -> 0.0020809545 | O7: {=INDEX(Engine!$H12:$U12,1,O$4)/INDEX(Engine!$H12:$U12,1,O$4+1)-1} -> 0.0037646073 | P7: {=INDEX(Engine!$H12:$U12,1,P$4)/INDEX(Engine!$H12:$U12,1,P$4+1)-1} -> 0.0019579505 | Q7: {=INDEX(Engine!$H12:$U12,1,Q$4)/INDEX(Engine!$H12:$U12,1,Q$4+1)-1} -> 0.0021605022 | R7: {=INDEX(Engine!$H12:$U12,1,R$4)/INDEX(Engine!$H12:$U12,1,R$4+1)-1} -> 0.0029504481 | S7: {=INDEX(Engine!$H12:$U12,1,S$4)/INDEX(Engine!$H12:$U12,1,S$4+1)-1} -> 0.0023290026 | T7: {=INDEX(Engine!$H12:$U12,1,T$4)/INDEX(Engine!$H12:$U12,1,T$4+1)-1} -> 0.0018915434 | U7: {=INDEX(Engine!$H12:$U12,1,U$4)/INDEX(Engine!$H12:$U12,1,U$4+1)-1} -> 0 | ... Z7: {=INDEX(Engine!$H12:$U12,1,Z$4)/INDEX(Engine!$H12:$U12,1,Z$4+1)-1} -> 0.0013048792
A8: =Engine!A13 -> Food | B8: =Engine!B13 -> FOOD | C8: =Engine!V13 -> 13.537308 | D8: =Engine!W13 -> 0.0015587816 | E8: =Engine!X13 -> 0.0050374636 | F8: =Engine!Z13 -> 0.030779321 | G8: =Engine!AA13 -> 0.032166593 | H8: =Engine!AB13 -> 0.018866582 | I8: =Engine!AC13 -> 0.026454138 | J8: =Engine!AD13 -> 0.038364964 | K8: =Engine!AE13 -> -0.0075875566 | L8: =Engine!AF13 -> -0.011910826 | M8: =Engine!AG13 -> ▼▼ DECEL | N8: {=INDEX(Engine!$H13:$U13,1,N$4)/INDEX(Engine!$H13:$U13,1,N$4+1)-1} -> 0.0015587816 | O8: {=INDEX(Engine!$H13:$U13,1,O$4)/INDEX(Engine!$H13:$U13,1,O$4+1)-1} -> 0.0050374636 | P8: {=INDEX(Engine!$H13:$U13,1,P$4)/INDEX(Engine!$H13:$U13,1,P$4+1)-1} -> -5.4814755e-05 | Q8: {=INDEX(Engine!$H13:$U13,1,Q$4)/INDEX(Engine!$H13:$U13,1,Q$4+1)-1} -> 0.0039128684 | R8: {=INDEX(Engine!$H13:$U13,1,R$4)/INDEX(Engine!$H13:$U13,1,R$4+1)-1} -> 0.0018541517 | S8: {=INDEX(Engine!$H13:$U13,1,S$4)/INDEX(Engine!$H13:$U13,1,S$4+1)-1} -> 0.0065598477 | T8: {=INDEX(Engine!$H13:$U13,1,T$4)/INDEX(Engine!$H13:$U13,1,T$4+1)-1} -> 0.00087697246 | U8: {=INDEX(Engine!$H13:$U13,1,U$4)/INDEX(Engine!$H13:$U13,1,U$4+1)-1} -> 0 | ... Z8: {=INDEX(Engine!$H13:$U13,1,Z$4)/INDEX(Engine!$H13:$U13,1,Z$4+1)-1} -> 0.002906727
A9: =Engine!A14 -> Energy (derived composite) | B9: =Engine!B14 -> ENERGY | C9: =Engine!V14 -> 7.3459231 | D9: =Engine!W14 -> 0.037692312 | E9: =Engine!X14 -> 0.037373436 | F9: =Engine!Z14 -> 0.22279599 | G9: =Engine!AA14 -> 0.1701922 | H9: =Engine!AB14 -> 0.55891771 | I9: =Engine!AC14 -> 1.002602 | J9: =Engine!AD14 -> 0.39999134 | K9: =Engine!AE14 -> -0.4436843 | L9: =Engine!AF14 -> 0.60261068 | M9: =Engine!AG14 -> ▼ TURN DN | N9: {=INDEX(Engine!$H14:$U14,1,N$4)/INDEX(Engine!$H14:$U14,1,N$4+1)-1} -> 0.037692312 | O9: {=INDEX(Engine!$H14:$U14,1,O$4)/INDEX(Engine!$H14:$U14,1,O$4+1)-1} -> 0.037373436 | P9: {=INDEX(Engine!$H14:$U14,1,P$4)/INDEX(Engine!$H14:$U14,1,P$4+1)-1} -> 0.10508311 | Q9: {=INDEX(Engine!$H14:$U14,1,Q$4)/INDEX(Engine!$H14:$U14,1,Q$4+1)-1} -> 0.0062895223 | R9: {=INDEX(Engine!$H14:$U14,1,R$4)/INDEX(Engine!$H14:$U14,1,R$4+1)-1} -> -0.015018152 | S9: {=INDEX(Engine!$H14:$U14,1,S$4)/INDEX(Engine!$H14:$U14,1,S$4+1)-1} -> 0.0034895044 | T9: {=INDEX(Engine!$H14:$U14,1,T$4)/INDEX(Engine!$H14:$U14,1,T$4+1)-1} -> 0.014070024 | U9: {=INDEX(Engine!$H14:$U14,1,U$4)/INDEX(Engine!$H14:$U14,1,U$4+1)-1} -> 0 | ... Z9: {=INDEX(Engine!$H14:$U14,1,Z$4)/INDEX(Engine!$H14:$U14,1,Z$4+1)-1} -> -0.0069484507
A10: =Engine!A15 -> All Items ex Shelter | B10: =Engine!B15 -> AGG | C10: =Engine!V15 -> 64.646156 | D10: =Engine!W15 -> 0.0055755185 | E10: =Engine!X15 -> 0.0065812274 | F10: =Engine!Z15 -> 0.046135496 | G10: =Engine!AA15 -> 0.040454487 | H10: =Engine!AB15 -> 0.068996539 | I10: =Engine!AC15 -> 0.10072847 | J10: =Engine!AD15 -> 0.063526498 | K10: =Engine!AE15 -> -0.031731927 | L10: =Engine!AF15 -> 0.037201968 | M10: =Engine!AG15 -> ▼ TURN DN | N10: {=INDEX(Engine!$H15:$U15,1,N$4)/INDEX(Engine!$H15:$U15,1,N$4+1)-1} -> 0.0055755185 | O10: {=INDEX(Engine!$H15:$U15,1,O$4)/INDEX(Engine!$H15:$U15,1,O$4+1)-1} -> 0.0065812274 | P10: {=INDEX(Engine!$H15:$U15,1,P$4)/INDEX(Engine!$H15:$U15,1,P$4+1)-1} -> 0.01194412 | Q10: {=INDEX(Engine!$H15:$U15,1,Q$4)/INDEX(Engine!$H15:$U15,1,Q$4+1)-1} -> 0.0028682549 | R10: {=INDEX(Engine!$H15:$U15,1,R$4)/INDEX(Engine!$H15:$U15,1,R$4+1)-1} -> 0.0014327627 | S10: {=INDEX(Engine!$H15:$U15,1,S$4)/INDEX(Engine!$H15:$U15,1,S$4+1)-1} -> 0.0025093415 | T10: {=INDEX(Engine!$H15:$U15,1,T$4)/INDEX(Engine!$H15:$U15,1,T$4+1)-1} -> 0.0025845655 | U10: {=INDEX(Engine!$H15:$U15,1,U$4)/INDEX(Engine!$H15:$U15,1,U$4+1)-1} -> 0 | ... Z10: {=INDEX(Engine!$H15:$U15,1,Z$4)/INDEX(Engine!$H15:$U15,1,Z$4+1)-1} -> 0.00011476944
A11: =Engine!A16 -> All ex Food, Shelter & Energy | B11: =Engine!B16 -> AGG | C11: =Engine!V16 -> 43.679279 | D11: =Engine!W16 -> 0.0011968902 | E11: =Engine!X16 -> 0.001920108 | F11: =Engine!Z16 -> 0.023990982 | G11: =Engine!AA16 -> 0.023053306 | H11: =Engine!AB16 -> 0.014457609 | I11: =Engine!AC16 -> 0.018181288 | J11: =Engine!AD16 -> 0.022689519 | K11: =Engine!AE16 -> -0.0037236798 | L11: =Engine!AF16 -> -0.0045082308 | M11: =Engine!AG16 -> ▼▼ DECEL | N11: {=INDEX(Engine!$H16:$U16,1,N$4)/INDEX(Engine!$H16:$U16,1,N$4+1)-1} -> 0.0011968902 | O11: {=INDEX(Engine!$H16:$U16,1,O$4)/INDEX(Engine!$H16:$U16,1,O$4+1)-1} -> 0.001920108 | P11: {=INDEX(Engine!$H16:$U16,1,P$4)/INDEX(Engine!$H16:$U16,1,P$4+1)-1} -> 0.0013910214 | Q11: {=INDEX(Engine!$H16:$U16,1,Q$4)/INDEX(Engine!$H16:$U16,1,Q$4+1)-1} -> 0.0020360849 | R11: {=INDEX(Engine!$H16:$U16,1,R$4)/INDEX(Engine!$H16:$U16,1,R$4+1)-1} -> 0.0035554548 | S11: {=INDEX(Engine!$H16:$U16,1,S$4)/INDEX(Engine!$H16:$U16,1,S$4+1)-1} -> 0.001130949 | T11: {=INDEX(Engine!$H16:$U16,1,T$4)/INDEX(Engine!$H16:$U16,1,T$4+1)-1} -> 0.0014734652 | U11: {=INDEX(Engine!$H16:$U16,1,U$4)/INDEX(Engine!$H16:$U16,1,U$4+1)-1} -> 0 | ... Z11: {=INDEX(Engine!$H16:$U16,1,Z$4)/INDEX(Engine!$H16:$U16,1,Z$4+1)-1} -> 0.0002800869
A12: =Engine!A17 -> Core Goods ex Used Vehicles | B12: =Engine!B17 -> AGG | C12: =Engine!V17 -> 16.122398 | D12: =Engine!W17 -> -0.0014937461 | E12: =Engine!X17 -> 0.00040209329 | F12: =Engine!Z17 -> 0.015732175 | G12: =Engine!AA17 -> 0.017698845 | H12: =Engine!AB17 -> -0.017778419 | I12: =Engine!AC17 -> 0.0033956747 | J12: =Engine!AD17 -> 0.015289127 | K12: =Engine!AE17 -> -0.021174094 | L12: =Engine!AF17 -> -0.011893453 | M12: =Engine!AG17 -> ▼▼ DECEL | N12: {=INDEX(Engine!$H17:$U17,1,N$4)/INDEX(Engine!$H17:$U17,1,N$4+1)-1} -> -0.0014937461 | O12: {=INDEX(Engine!$H17:$U17,1,O$4)/INDEX(Engine!$H17:$U17,1,O$4+1)-1} -> 0.00040209329 | P12: {=INDEX(Engine!$H17:$U17,1,P$4)/INDEX(Engine!$H17:$U17,1,P$4+1)-1} -> 0.0019422146 | Q12: {=INDEX(Engine!$H17:$U17,1,Q$4)/INDEX(Engine!$H17:$U17,1,Q$4+1)-1} -> 0.0015598087 | R12: {=INDEX(Engine!$H17:$U17,1,R$4)/INDEX(Engine!$H17:$U17,1,R$4+1)-1} -> 0.0035780338 | S12: {=INDEX(Engine!$H17:$U17,1,S$4)/INDEX(Engine!$H17:$U17,1,S$4+1)-1} -> 0.0016102865 | T12: {=INDEX(Engine!$H17:$U17,1,T$4)/INDEX(Engine!$H17:$U17,1,T$4+1)-1} -> -0.00039938519 | U12: {=INDEX(Engine!$H17:$U17,1,U$4)/INDEX(Engine!$H17:$U17,1,U$4+1)-1} -> 0 | ... Z12: {=INDEX(Engine!$H17:$U17,1,Z$4)/INDEX(Engine!$H17:$U17,1,Z$4+1)-1} -> 0.00043957117
A13: =Engine!A18 -> Services ex Rent of Shelter | B13: =Engine!B18 -> AGG | C13: =Engine!V18 -> 28.525555 | D13: =Engine!W18 -> 0.0054837393 | E13: =Engine!X18 -> 0.0038479559 | F13: =Engine!Z18 -> 0.037420901 | G13: =Engine!AA18 -> 0.035182765 | H13: =Engine!AB18 -> 0.067826314 | I13: =Engine!AC18 -> 0.051888458 | J13: =Engine!AD18 -> 0.04339725 | K13: =Engine!AE18 -> 0.015937856 | L13: =Engine!AF18 -> 0.0084912078 | M13: =Engine!AG18 -> ▲▲ ACCEL | N13: {=INDEX(Engine!$H18:$U18,1,N$4)/INDEX(Engine!$H18:$U18,1,N$4+1)-1} -> 0.0054837393 | O13: {=INDEX(Engine!$H18:$U18,1,O$4)/INDEX(Engine!$H18:$U18,1,O$4+1)-1} -> 0.0038479559 | P13: {=INDEX(Engine!$H18:$U18,1,P$4)/INDEX(Engine!$H18:$U18,1,P$4+1)-1} -> 0.0033430157 | Q13: {=INDEX(Engine!$H18:$U18,1,Q$4)/INDEX(Engine!$H18:$U18,1,Q$4+1)-1} -> 0.0028172286 | R13: {=INDEX(Engine!$H18:$U18,1,R$4)/INDEX(Engine!$H18:$U18,1,R$4+1)-1} -> 0.0034760709 | S13: {=INDEX(Engine!$H18:$U18,1,S$4)/INDEX(Engine!$H18:$U18,1,S$4+1)-1} -> 0.0023135793 | T13: {=INDEX(Engine!$H18:$U18,1,T$4)/INDEX(Engine!$H18:$U18,1,T$4+1)-1} -> 0.0042280575 | U13: {=INDEX(Engine!$H18:$U18,1,U$4)/INDEX(Engine!$H18:$U18,1,U$4+1)-1} -> 0 | ... Z13: {=INDEX(Engine!$H18:$U18,1,Z$4)/INDEX(Engine!$H18:$U18,1,Z$4+1)-1} -> 0.0033145045
A14: =Engine!A19 -> Supercore — Svcs ex Shelter & Energy (derived) | B14: =Engine!B19 -> AGG | C14: =Engine!V19 -> 25.252733 | D14: =Engine!W19 -> 0.0057321011 | E14: =Engine!X19 -> 0.0022658923 | F14: =Engine!Z19 -> 0.035482623 | G14: =Engine!AA19 -> 0.032820694 | H14: =Engine!AB19 -> 0.070995747 | I14: =Engine!AC19 -> 0.045879594 | J14: =Engine!AD19 -> 0.039115572 | K14: =Engine!AE19 -> 0.025116154 | L14: =Engine!AF19 -> 0.0067640223 | M14: =Engine!AG19 -> ▲▲ ACCEL | N14: {=INDEX(Engine!$H19:$U19,1,N$4)/INDEX(Engine!$H19:$U19,1,N$4+1)-1} -> 0.0057321011 | O14: {=INDEX(Engine!$H19:$U19,1,O$4)/INDEX(Engine!$H19:$U19,1,O$4+1)-1} -> 0.0022658923 | P14: {=INDEX(Engine!$H19:$U19,1,P$4)/INDEX(Engine!$H19:$U19,1,P$4+1)-1} -> 0.0032407378 | Q14: {=INDEX(Engine!$H19:$U19,1,Q$4)/INDEX(Engine!$H19:$U19,1,Q$4+1)-1} -> 0.0029607527 | R14: {=INDEX(Engine!$H19:$U19,1,R$4)/INDEX(Engine!$H19:$U19,1,R$4+1)-1} -> 0.0036736906 | S14: {=INDEX(Engine!$H19:$U19,1,S$4)/INDEX(Engine!$H19:$U19,1,S$4+1)-1} -> 0.0013479779 | T14: {=INDEX(Engine!$H19:$U19,1,T$4)/INDEX(Engine!$H19:$U19,1,T$4+1)-1} -> 0.0028706232 | U14: {=INDEX(Engine!$H19:$U19,1,U$4)/INDEX(Engine!$H19:$U19,1,U$4+1)-1} -> 0 | ... Z14: {=INDEX(Engine!$H19:$U19,1,Z$4)/INDEX(Engine!$H19:$U19,1,Z$4+1)-1} -> 0.0031466528
A15: =Engine!A20 -> Food at Home | B15: =Engine!B20 -> FOOD | C15: =Engine!V20 -> 8.2256925 | D15: =Engine!W20 -> 0.0006331226 | E15: =Engine!X20 -> 0.0068171399 | F15: =Engine!Z20 -> 0.027345851 | G15: =Engine!AA20 -> 0.029517724 | H15: =Engine!AB20 -> 0.0076239829 | I15: =Engine!AC20 -> 0.023413939 | J15: =Engine!AD20 -> 0.037397217 | K15: =Engine!AE20 -> -0.015789956 | L15: =Engine!AF20 -> -0.013983278 | M15: =Engine!AG20 -> ▼▼ DECEL | N15: {=INDEX(Engine!$H20:$U20,1,N$4)/INDEX(Engine!$H20:$U20,1,N$4+1)-1} -> 0.0006331226 | O15: {=INDEX(Engine!$H20:$U20,1,O$4)/INDEX(Engine!$H20:$U20,1,O$4+1)-1} -> 0.0068171399 | P15: {=INDEX(Engine!$H20:$U20,1,P$4)/INDEX(Engine!$H20:$U20,1,P$4+1)-1} -> -0.0016395755 | Q15: {=INDEX(Engine!$H20:$U20,1,Q$4)/INDEX(Engine!$H20:$U20,1,Q$4+1)-1} -> 0.0043956182 | R15: {=INDEX(Engine!$H20:$U20,1,R$4)/INDEX(Engine!$H20:$U20,1,R$4+1)-1} -> 0.0019149352 | S15: {=INDEX(Engine!$H20:$U20,1,S$4)/INDEX(Engine!$H20:$U20,1,S$4+1)-1} -> 0.0062920635 | T15: {=INDEX(Engine!$H20:$U20,1,T$4)/INDEX(Engine!$H20:$U20,1,T$4+1)-1} -> -0.001711352 | U15: {=INDEX(Engine!$H20:$U20,1,U$4)/INDEX(Engine!$H20:$U20,1,U$4+1)-1} -> 0 | ... Z15: {=INDEX(Engine!$H20:$U20,1,Z$4)/INDEX(Engine!$H20:$U20,1,Z$4+1)-1} -> 0.002748523
A16: =Engine!A21 -> Food Away from Home | B16: =Engine!B21 -> FOOD | C16: =Engine!V21 -> 5.3102324 | D16: =Engine!W21 -> 0.0030034608 | E16: =Engine!X21 -> 0.0022768253 | F16: =Engine!Z21 -> 0.03541188 | G16: =Engine!AA21 -> 0.035541089 | H16: =Engine!AB21 -> 0.036642902 | I16: =Engine!AC21 -> 0.031218845 | J16: =Engine!AD21 -> 0.039251559 | K16: =Engine!AE21 -> 0.0054240579 | L16: =Engine!AF21 -> -0.0080327141 | M16: =Engine!AG21 -> ▲ TURN UP | N16: {=INDEX(Engine!$H21:$U21,1,N$4)/INDEX(Engine!$H21:$U21,1,N$4+1)-1} -> 0.0030034608 | O16: {=INDEX(Engine!$H21:$U21,1,O$4)/INDEX(Engine!$H21:$U21,1,O$4+1)-1} -> 0.0022768253 | P16: {=INDEX(Engine!$H21:$U21,1,P$4)/INDEX(Engine!$H21:$U21,1,P$4+1)-1} -> 0.0024150766 | Q16: {=INDEX(Engine!$H21:$U21,1,Q$4)/INDEX(Engine!$H21:$U21,1,Q$4+1)-1} -> 0.0031628469 | R16: {=INDEX(Engine!$H21:$U21,1,R$4)/INDEX(Engine!$H21:$U21,1,R$4+1)-1} -> 0.0014927325 | S16: {=INDEX(Engine!$H21:$U21,1,S$4)/INDEX(Engine!$H21:$U21,1,S$4+1)-1} -> 0.0069395303 | T16: {=INDEX(Engine!$H21:$U21,1,T$4)/INDEX(Engine!$H21:$U21,1,T$4+1)-1} -> 0.0045427305 | U16: {=INDEX(Engine!$H21:$U21,1,U$4)/INDEX(Engine!$H21:$U21,1,U$4+1)-1} -> 0 | ... Z16: {=INDEX(Engine!$H21:$U21,1,Z$4)/INDEX(Engine!$H21:$U21,1,Z$4+1)-1} -> 0.0031286263
A17: =Engine!A22 -> Alcoholic Beverages | B17: =Engine!B22 -> CORE GOODS | C17: =Engine!V22 -> 0.82727496 | D17: =Engine!W22 -> 0.00056894745 | E17: =Engine!X22 -> 0.0027926251 | F17: =Engine!Z22 -> 0.021217205 | G17: =Engine!AA22 -> 0.019245117 | H17: =Engine!AB22 -> 0.0068487742 | I17: =Engine!AC22 -> 0.023975769 | J17: =Engine!AD22 -> 0.016263508 | K17: =Engine!AE22 -> -0.017126995 | L17: =Engine!AF22 -> 0.0077122611 | M17: =Engine!AG22 -> ▼ TURN DN | N17: {=INDEX(Engine!$H22:$U22,1,N$4)/INDEX(Engine!$H22:$U22,1,N$4+1)-1} -> 0.00056894745 | O17: {=INDEX(Engine!$H22:$U22,1,O$4)/INDEX(Engine!$H22:$U22,1,O$4+1)-1} -> 0.0027926251 | P17: {=INDEX(Engine!$H22:$U22,1,P$4)/INDEX(Engine!$H22:$U22,1,P$4+1)-1} -> 0.0025689915 | Q17: {=INDEX(Engine!$H22:$U22,1,Q$4)/INDEX(Engine!$H22:$U22,1,Q$4+1)-1} -> 0.0010950262 | R17: {=INDEX(Engine!$H22:$U22,1,R$4)/INDEX(Engine!$H22:$U22,1,R$4+1)-1} -> 0.0018048543 | S17: {=INDEX(Engine!$H22:$U22,1,S$4)/INDEX(Engine!$H22:$U22,1,S$4+1)-1} -> -0.00075424894 | T17: {=INDEX(Engine!$H22:$U22,1,T$4)/INDEX(Engine!$H22:$U22,1,T$4+1)-1} -> 0.0026990962 | U17: {=INDEX(Engine!$H22:$U22,1,U$4)/INDEX(Engine!$H22:$U22,1,U$4+1)-1} -> 0 | ... Z17: {=INDEX(Engine!$H22:$U22,1,Z$4)/INDEX(Engine!$H22:$U22,1,Z$4+1)-1} -> -0.0013632664
... A60: =Engine!A65 -> Misc Personal Services | B60: =Engine!B65 -> CORE SVCS | C60: =Engine!V65 -> 0.94741989 | D60: =Engine!W65 -> 0.02067842 | E60: =Engine!X65 -> 0.025607971 | F60: =Engine!Z65 -> 0.065204033 | G60: =Engine!AA65 -> 0.04700111 | H60: =Engine!AB65 -> 0.27840127 | I60: =Engine!AC65 -> 0.14193158 | J60: =Engine!AD65 -> 0.089866461 | K60: =Engine!AE65 -> 0.13646968 | L60: =Engine!AF65 -> 0.052065123 | M60: =Engine!AG65 -> ▲▲ ACCEL | N60: {=INDEX(Engine!$H65:$U65,1,N$4)/INDEX(Engine!$H65:$U65,1,N$4+1)-1} -> 0.02067842 | O60: {=INDEX(Engine!$H65:$U65,1,O$4)/INDEX(Engine!$H65:$U65,1,O$4+1)-1} -> 0.025607971 | P60: {=INDEX(Engine!$H65:$U65,1,P$4)/INDEX(Engine!$H65:$U65,1,P$4+1)-1} -> -0.012494095 | Q60: {=INDEX(Engine!$H65:$U65,1,Q$4)/INDEX(Engine!$H65:$U65,1,Q$4+1)-1} -> -0.004953548 | R60: {=INDEX(Engine!$H65:$U65,1,R$4)/INDEX(Engine!$H65:$U65,1,R$4+1)-1} -> 0.023336494 | S60: {=INDEX(Engine!$H65:$U65,1,S$4)/INDEX(Engine!$H65:$U65,1,S$4+1)-1} -> -0.0082212358 | T60: {=INDEX(Engine!$H65:$U65,1,T$4)/INDEX(Engine!$H65:$U65,1,T$4+1)-1} -> 0.01059225 | U60: {=INDEX(Engine!$H65:$U65,1,U$4)/INDEX(Engine!$H65:$U65,1,U$4+1)-1} -> 0 | ... Z60: {=INDEX(Engine!$H65:$U65,1,Z$4)/INDEX(Engine!$H65:$U65,1,Z$4+1)-1} -> 0.0032363804
A63: TOP 10 ACCELERATORS — ranked by Δ 1m vs 3m SAAR (non-overlapping components) | F63: TOP 10 DECELERATORS — ranked by Δ 1m vs 3m SAAR (non-overlapping components)
A64: Component | B64: 1m SAAR | C64: 3m SAAR | D64: Δ 1m-3m | F64: Component | G64: 1m SAAR | H64: 3m SAAR | I64: Δ 1m-3m
A65: {=_xlfn.TAKE(_xlfn.SORTBY(_xlfn._xlws.FILTER(_xlfn.HSTACK(Engine!$A$11:$A$65,Engine!$AB$11:$AB$65,Engine!$AC$11:$AC$65,Engine!$AE$11:$AE$65),Engine!$E$11:$E$65="Y"),_xlfn._xlws.FILTER(Engine!$AE$11:$AE$65,Engine!$E$11:$E$65="Y"),-1),10)} -> Communication | B65: 0.17049302 | C65: 0.050945337 | D65: 0.11954768 | F65: {=_xlfn.TAKE(_xlfn.SORTBY(_xlfn._xlws.FILTER(_xlfn.HSTACK(Engine!$A$11:$A$65,Engine!$AB$11:$AB$65,Engine!$AC$11:$AC$65,Engine!$AE$11:$AE$65),Engine!$E$11:$E$65="Y"),_xlfn._xlws.FILTER(Engine!$AE$11:$AE$65,Engine!$E$11:$E$65="Y"),1),10)} -> Motor Fuel | G65: 1.2125524 | H65: 2.5373237 | I65: -1.3247714
A66: Personal Care | B66: 0.12421365 | C66: 0.050478642 | D66: 0.073735007 | F66: Fuel Oil & Other Fuels | G66: 0.48434562 | H66: 1.6913584 | I66: -1.2070128
A67: Tobacco & Smoking Products | B67: 0.12780668 | C67: 0.063604542 | D67: 0.064202134 | F67: Car & Truck Rental | G67: -0.40344227 | H67: -0.23965128 | I67: -0.16379099
A68: Medical Care Services | B68: 0.065286115 | C68: 0.021506395 | D68: 0.04377972 | F68: MV Insurance | G68: -0.18481379 | H68: -0.06196998 | I68: -0.12284381
A69: Used Cars & Trucks | B69: 0.012280662 | C69: -0.012872838 | D69: 0.0251535 | F69: Public Transportation | G69: 0.040988797 | H69: 0.14809334 | I69: -0.10710454
A70: MV Maintenance & Repair | B70: 0.099505199 | C70: 0.076650214 | D70: 0.022854985 | F70: Household Furnishings & Ops | G70: -0.065072774 | H70: 0.014856503 | I70: -0.079929277
A71: Recreation | B71: 0.035038695 | C71: 0.013349801 | D71: 0.021688894 | F71: Lodging Away from Home | G71: 0.051340734 | H71: 0.13077298 | I71: -0.079432247
A72: Leased Cars & Trucks | B72: -0.00084839375 | C72: -0.0080579838 | D72: 0.00720959 | F72: Electricity | G72: 0.077942171 | H72: 0.15282887 | I72: -0.0748867
A73: Food Away from Home | B73: 0.036642902 | C73: 0.031218845 | D73: 0.0054240579 | F73: MV Parts & Equipment | G73: -0.085217783 | H73: -0.01067339 | I73: -0.074544393
A74: Rent of Primary Residence | B74: 0.044306235 | C74: 0.04476394 | D74: -0.00045770501 | F74: Apparel | G74: 0.035601329 | H74: 0.081220663 | I74: -0.045619334

Sheet Breadth
A1: CPI BREADTH & CONTRIBUTIONS
A2: {="Latest print: "&TEXT(Engine!$B$5,"mmmm yyyy")&" | Contributions use price-updated BLS relative-importance weights | Breadth measured over "&SUMPRODUCT((Engine!$E$11:$E$65="Y")*1)&" non-overlapping components"} -> Latest print: May 2026 | Contributions use price-updated BLS relative-importance weights | Breadth measured over 28 non-overlapping components
A4: TOP 5 CONTRIBUTORS — HEADLINE M/M (pp) | G4: TOP 5 DRAGS — HEADLINE M/M (pp)
A5: Component | B5: Wt % | C5: M/M | D5: Contrib | G5: Component | H5: Wt % | I5: M/M | J5: Contrib
A6: {=_xlfn.TAKE(_xlfn.SORTBY(_xlfn._xlws.FILTER(_xlfn.HSTACK(Engine!$A$11:$A$65,Engine!$V$11:$V$65,Engine!$W$11:$W$65,Engine!$AH$11:$AH$65),Engine!$E$11:$E$65="Y"),_xlfn._xlws.FILTER(Engine!$AH$11:$AH$65,Engine!$E$11:$E$65="Y"),-1),5)} -> Motor Fuel | B6: 3.8947123 | C6: 0.068417838 | D6: 0.26646779 | G6: {=_xlfn.TAKE(_xlfn.SORTBY(_xlfn._xlws.FILTER(_xlfn.HSTACK(Engine!$A$11:$A$65,Engine!$V$11:$V$65,Engine!$W$11:$W$65,Engine!$AH$11:$AH$65),Engine!$E$11:$E$65="Y"),_xlfn._xlws.FILTER(Engine!$AH$11:$AH$65,Engine!$E$11:$E$65="Y"),1),5)} -> MV Insurance | H6: 2.6255895 | I6: -0.016884065 | J6: -0.044330625
A7: Owners' Equivalent Rent | B7: 25.981247 | C7: 0.002967825 | D7: 0.077107795 | G7: Household Furnishings & Ops | H7: 4.223049 | I7: -0.0055915244 | J7: -0.023613282
A8: Communication | B8: 3.2070096 | C8: 0.013205182 | D8: 0.042349144 | G8: Medical Care Commodities | H8: 1.4226413 | I8: -0.0071164716 | J8: -0.010124186
A9: Medical Care Services | B9: 6.8701473 | C9: 0.005284197 | D9: 0.036303212 | G9: New Vehicles | H9: 3.7419316 | I9: -0.0025784991 | J9: -0.0096485673
A10: Rent of Primary Residence | B10: 7.7671333 | C10: 0.003619265 | D10: 0.028111314 | G10: Car & Truck Rental | H10: 0.13574905 | I10: -0.042134849 | J10: -0.0057197659
A12: TOP 5 CONTRIBUTORS — CORE M/M (pp) | G12: TOP 5 DRAGS — CORE M/M (pp)
A13: Component | B13: Wt % | C13: M/M | D13: Contrib | G13: Component | H13: Wt % | I13: M/M | J13: Contrib
A14: {=_xlfn.TAKE(_xlfn.SORTBY(_xlfn._xlws.FILTER(_xlfn.HSTACK(Engine!$A$11:$A$65,Engine!$V$11:$V$65,Engine!$W$11:$W$65,Engine!$AI$11:$AI$65),(Engine!$E$11:$E$65="Y")*(Engine!$C$11:$C$65="Y")),_xlfn._xlws.FILTER(Engine!$AI$11:$AI$65,(Engine!$E$11:$E$65="Y")*(Engine!$C$11:$C$65="Y")),-1),5)} -> Owners' Equivalent Rent | B14: 25.981247 | C14: 0.002967825 | D14: 0.097568037 | G14: {=_xlfn.TAKE(_xlfn.SORTBY(_xlfn._xlws.FILTER(_xlfn.HSTACK(Engine!$A$11:$A$65,Engine!$V$11:$V$65,Engine!$W$11:$W$65,Engine!$AI$11:$AI$65),(Engine!$E$11:$E$65="Y")*(Engine!$C$11:$C$65="Y")),_xlfn._xlws.FILTER(Engine!$AI$11:$AI$65,(Engine!$E$11:$E$65="Y")*(Engine!$C$11:$C$65="Y")),1),5)} -> MV Insurance | H14: 2.6255895 | I14: -0.016884065 | J14: -0.056093577
A15: Communication | B15: 3.2070096 | C15: 0.013205182 | D15: 0.053586319 | G15: Household Furnishings & Ops | H15: 4.223049 | I15: -0.0055915244 | J15: -0.029878971
A16: Medical Care Services | B16: 6.8701473 | C16: 0.005284197 | D16: 0.045936123 | G16: Medical Care Commodities | H16: 1.4226413 | I16: -0.0071164716 | J16: -0.012810598
A17: Rent of Primary Residence | B17: 7.7671333 | C17: 0.003619265 | D17: 0.035570537 | G17: New Vehicles | H17: 3.7419316 | I17: -0.0025784991 | J17: -0.012208776
A18: Personal Care | B18: 2.4522759 | C18: 0.009804739 | D18: 0.030423884 | G18: Car & Truck Rental | H18: 0.13574905 | I18: -0.042134849 | J18: -0.0072374826
A20: BREADTH OF THE PRINT | D20: Latest | E20: Prior mo
A21: % of components rising m/m | D21: {=SUMPRODUCT((Engine!$E$11:$E$65="Y")*(Engine!$W$11:$W$65>0))/SUMPRODUCT((Engine!$E$11:$E$65="Y")*1)} -> 0.71428571 | E21: {=SUMPRODUCT((Engine!$E$11:$E$65="Y")*(Engine!$X$11:$X$65>0))/SUMPRODUCT((Engine!$E$11:$E$65="Y")*1)} -> 0.67857143
A22: % of components accelerating m/m | D22: {=SUMPRODUCT((Engine!$E$11:$E$65="Y")*(Engine!$W$11:$W$65>Engine!$X$11:$X$65))/SUMPRODUCT((Engine!$E$11:$E$65="Y")*1)} -> 0.32142857 | E22: {=SUMPRODUCT((Engine!$E$11:$E$65="Y")*(Engine!$X$11:$X$65>Engine!$Y$11:$Y$65))/SUMPRODUCT((Engine!$E$11:$E$65="Y")*1)} -> 0.57142857
A23: Weighted share accelerating (by RI weight) | D23: {=SUMPRODUCT(Engine!$V$11:$V$65*(Engine!$W$11:$W$65>Engine!$X$11:$X$65)*(Engine!$E$11:$E$65="Y"))/SUMPRODUCT(Engine!$V$11:$V$65*(Engine!$E$11:$E$65="Y"))} -> 0.31215184 | E23: {=SUMPRODUCT(Engine!$V$11:$V$65*(Engine!$X$11:$X$65>Engine!$Y$11:$Y$65)*(Engine!$E$11:$E$65="Y"))/SUMPRODUCT(Engine!$V$11:$V$65*(Engine!$E$11:$E$65="Y"))} -> 0.68871876
A24: % running above 2% (3m SAAR) | D24: {=SUMPRODUCT((Engine!$E$11:$E$65="Y")*((Engine!$H$11:$H$65/Engine!$K$11:$K$65)^4-1>0.02))/SUMPRODUCT((Engine!$E$11:$E$65="Y")*1)} -> 0.64285714 | E24: {=SUMPRODUCT((Engine!$E$11:$E$65="Y")*((Engine!$I$11:$I$65/Engine!$L$11:$L$65)^4-1>0.02))/SUMPRODUCT((Engine!$E$11:$E$65="Y")*1)} -> 0.67857143
A25: % running above 4% (3m SAAR) | D25: {=SUMPRODUCT((Engine!$E$11:$E$65="Y")*((Engine!$H$11:$H$65/Engine!$K$11:$K$65)^4-1>0.04))/SUMPRODUCT((Engine!$E$11:$E$65="Y")*1)} -> 0.46428571 | E25: {=SUMPRODUCT((Engine!$E$11:$E$65="Y")*((Engine!$I$11:$I$65/Engine!$L$11:$L$65)^4-1>0.04))/SUMPRODUCT((Engine!$E$11:$E$65="Y")*1)} -> 0.39285714
A26: Median component m/m | D26: {=MEDIAN(_xlfn._xlws.FILTER(Engine!$W$11:$W$65,Engine!$E$11:$E$65="Y"))} -> 0.0028967321 | E26: {=MEDIAN(_xlfn._xlws.FILTER(Engine!$X$11:$X$65,Engine!$E$11:$E$65="Y"))} -> 0.0024447096
A29: BREADTH TREND — trailing 12 months
B30: =Momentum!N$5 -> May-26 | C30: =Momentum!O$5 -> Apr-26 | D30: =Momentum!P$5 -> Mar-26 | E30: =Momentum!Q$5 -> Feb-26 | F30: =Momentum!R$5 -> Jan-26 | G30: =Momentum!S$5 -> Dec-25 | H30: =Momentum!T$5 -> Nov-25 | I30: =Momentum!U$5 -> Oct-25 | ... M30: =Momentum!Y$5 -> Jun-25
A31: % rising m/m | B31: {=SUMPRODUCT((Engine!$E$11:$E$65="Y")*(Momentum!N$6:N$60>0))/SUMPRODUCT((Engine!$E$11:$E$65="Y")*1)} -> 0.71428571 | C31: {=SUMPRODUCT((Engine!$E$11:$E$65="Y")*(Momentum!O$6:O$60>0))/SUMPRODUCT((Engine!$E$11:$E$65="Y")*1)} -> 0.67857143 | D31: {=SUMPRODUCT((Engine!$E$11:$E$65="Y")*(Momentum!P$6:P$60>0))/SUMPRODUCT((Engine!$E$11:$E$65="Y")*1)} -> 0.71428571 | E31: {=SUMPRODUCT((Engine!$E$11:$E$65="Y")*(Momentum!Q$6:Q$60>0))/SUMPRODUCT((Engine!$E$11:$E$65="Y")*1)} -> 0.78571429 | F31: {=SUMPRODUCT((Engine!$E$11:$E$65="Y")*(Momentum!R$6:R$60>0))/SUMPRODUCT((Engine!$E$11:$E$65="Y")*1)} -> 0.67857143 | G31: {=SUMPRODUCT((Engine!$E$11:$E$65="Y")*(Momentum!S$6:S$60>0))/SUMPRODUCT((Engine!$E$11:$E$65="Y")*1)} -> 0.64285714 | H31: {=SUMPRODUCT((Engine!$E$11:$E$65="Y")*(Momentum!T$6:T$60>0))/SUMPRODUCT((Engine!$E$11:$E$65="Y")*1)} -> 0.64285714 | I31: {=SUMPRODUCT((Engine!$E$11:$E$65="Y")*(Momentum!U$6:U$60>0))/SUMPRODUCT((Engine!$E$11:$E$65="Y")*1)} -> 0.071428571 | ... M31: {=SUMPRODUCT((Engine!$E$11:$E$65="Y")*(Momentum!Y$6:Y$60>0))/SUMPRODUCT((Engine!$E$11:$E$65="Y")*1)} -> 0.85714286
A32: % accelerating m/m | B32: {=SUMPRODUCT((Engine!$E$11:$E$65="Y")*(Momentum!N$6:N$60>Momentum!O$6:O$60))/SUMPRODUCT((Engine!$E$11:$E$65="Y")*1)} -> 0.32142857 | C32: {=SUMPRODUCT((Engine!$E$11:$E$65="Y")*(Momentum!O$6:O$60>Momentum!P$6:P$60))/SUMPRODUCT((Engine!$E$11:$E$65="Y")*1)} -> 0.57142857 | D32: {=SUMPRODUCT((Engine!$E$11:$E$65="Y")*(Momentum!P$6:P$60>Momentum!Q$6:Q$60))/SUMPRODUCT((Engine!$E$11:$E$65="Y")*1)} -> 0.46428571 | E32: {=SUMPRODUCT((Engine!$E$11:$E$65="Y")*(Momentum!Q$6:Q$60>Momentum!R$6:R$60))/SUMPRODUCT((Engine!$E$11:$E$65="Y")*1)} -> 0.57142857 | F32: {=SUMPRODUCT((Engine!$E$11:$E$65="Y")*(Momentum!R$6:R$60>Momentum!S$6:S$60))/SUMPRODUCT((Engine!$E$11:$E$65="Y")*1)} -> 0.42857143 | G32: {=SUMPRODUCT((Engine!$E$11:$E$65="Y")*(Momentum!S$6:S$60>Momentum!T$6:T$60))/SUMPRODUCT((Engine!$E$11:$E$65="Y")*1)} -> 0.42857143 | H32: {=SUMPRODUCT((Engine!$E$11:$E$65="Y")*(Momentum!T$6:T$60>Momentum!U$6:U$60))/SUMPRODUCT((Engine!$E$11:$E$65="Y")*1)} -> 0.60714286 | I32: {=SUMPRODUCT((Engine!$E$11:$E$65="Y")*(Momentum!U$6:U$60>Momentum!V$6:V$60))/SUMPRODUCT((Engine!$E$11:$E$65="Y")*1)} -> 0.32142857 | ... M32: {=SUMPRODUCT((Engine!$E$11:$E$65="Y")*(Momentum!Y$6:Y$60>Momentum!Z$6:Z$60))/SUMPRODUCT((Engine!$E$11:$E$65="Y")*1)} -> 0.53571429

Sheet PCE Bridge
A1: CPI → CORE PCE PASS-THROUGH BRIDGE
A2: ="CPI print: "&TEXT(Engine!$B$5,"mmmm yyyy")&" | PCE weights = BEA nominal shares of CORE PCE (Macrobond cols KT:PB) | Source-index mapping per BEA Table 2.4.4U-D (see 'PCE Source Data' tab)" -> CPI print: May 2026 | PCE weights = BEA nominal shares of CORE PCE (Macrobond cols KT:PB) | Source-index mapping per BEA Table 2.4.4U-D (see 'PCE Source Data' tab)
A4: Last PCE nominal data row | B4: =COUNT(Macrobond!$KU:$KU)+4 -> 955
A5: PCE weight month (nominal vintage) | B5: {=INDEX(Macrobond!$A:$A,$B$4)} -> 46082
A6: Core PCE nominal denominator | B6: {=INDEX(Macrobond!$KU:$KU,$B$4)-INDEX(Macrobond!$LT:$LT,$B$4)-INDEX(Macrobond!$MD:$MD,$B$4)-INDEX(Macrobond!$MY:$MY,$B$4)} -> 6.4275123e+12 | C6: USD mm (total less food off-premises less energy goods & utilities)
A8: PCE Component (core PCE) | B8: BEA Col# | C8: Wt % of Core PCE | D8: Source index (per 2.4.4U-D) | E8: CPI Proxy (Engine) | F8: Eng Row | G8: CPI M/M | H8: CPI 3m SAAR | I8: Contrib to Core PCE M/M (pp)
A9: New motor vehicles | B9: 311 | C9: {=INDEX(Macrobond!$A:$PB,$B$4,$B9)/$B$6*100} -> 1.976939 | D9: CPI: New vehicles | E9: New Vehicles | F9: =MATCH($E9,Engine!$A$11:$A$65,0)+10 -> 35 | G9: {=INDEX(Engine!$W:$W,$F9)} -> -0.0025784991 | H9: {=INDEX(Engine!$AC:$AC,$F9)} -> -0.012568754 | I9: =$C9*$G9 -> -0.0050975355
A10: Net purchases of used motor vehicles | B10: 312 | C10: {=INDEX(Macrobond!$A:$PB,$B$4,$B10)/$B$6*100} -> 1.2188178 | D10: CPI: Used cars and trucks | E10: Used Cars & Trucks | F10: =MATCH($E10,Engine!$A$11:$A$65,0)+10 -> 36 | G10: {=INDEX(Engine!$W:$W,$F10)} -> 0.001017673 | H10: {=INDEX(Engine!$AC:$AC,$F10)} -> -0.012872838 | I10: =$C10*$G10 -> 0.001240358
A11: Motor vehicle parts & accessories | B11: 313 | C11: {=INDEX(Macrobond!$A:$PB,$B$4,$B11)/$B$6*100} -> 0.696231 | D11: CPI: MV parts & equipment | E11: MV Parts & Equipment | F11: =MATCH($E11,Engine!$A$11:$A$65,0)+10 -> 38 | G11: {=INDEX(Engine!$W:$W,$F11)} -> -0.0073949598 | H11: {=INDEX(Engine!$AC:$AC,$F11)} -> -0.01067339 | I11: =$C11*$G11 -> -0.0051486002
A12: Furnishings & durable household equip. | B12: 314 | C12: {=INDEX(Macrobond!$A:$PB,$B$4,$B12)/$B$6*100} -> 2.7065889 | D12: CPI: HH furnishings indexes | E12: Household Furnishings & Ops | F12: =MATCH($E12,Engine!$A$11:$A$65,0)+10 -> 41 | G12: {=INDEX(Engine!$W:$W,$F12)} -> -0.0055915244 | H12: {=INDEX(Engine!$AC:$AC,$F12)} -> 0.014856503 | I12: =$C12*$G12 -> -0.015133958
A13: Recreational goods & vehicles | B13: 319 | C13: {=INDEX(Macrobond!$A:$PB,$B$4,$B13)/$B$6*100} -> 3.8124651 | D13: CPI: video/audio/IT & rec goods (partial) | E13: Video & Audio | F13: =MATCH($E13,Engine!$A$11:$A$65,0)+10 -> 45 | G13: {=INDEX(Engine!$W:$W,$F13)} -> -0.0021687906 | H13: {=INDEX(Engine!$AC:$AC,$F13)} -> 0.019417953 | I13: =$C13*$G13 -> -0.0082684386
A14: Clothing & footwear | B14: 336 | C14: {=INDEX(Macrobond!$A:$PB,$B$4,$B14)/$B$6*100} -> 3.0337968 | D14: CPI: apparel indexes | E14: Apparel | F14: =MATCH($E14,Engine!$A$11:$A$65,0)+10 -> 34 | G14: {=INDEX(Engine!$W:$W,$F14)} -> 0.002919441 | H14: {=INDEX(Engine!$AC:$AC,$F14)} -> 0.081220663 | I14: =$C14*$G14 -> 0.0088569909
A15: Pharmaceutical & other medical products | B15: 346 | C15: {=INDEX(Macrobond!$A:$PB,$B$4,$B15)/$B$6*100} -> 3.8322758 | D15: CPI: medical care commodities | E15: Medical Care Commodities | F15: =MATCH($E15,Engine!$A$11:$A$65,0)+10 -> 40 | G15: {=INDEX(Engine!$W:$W,$F15)} -> -0.0071164716 | H15: {=INDEX(Engine!$AC:$AC,$F15)} -> -0.078736518 | I15: =$C15*$G15 -> -0.027272282
A16: Recreational items | B16: 347 | C16: {=INDEX(Macrobond!$A:$PB,$B$4,$B16)/$B$6*100} -> 1.8232819 | D16: CPI: recreation commodities (partial) | E16: Recreation | F16: =MATCH($E16,Engine!$A$11:$A$65,0)+10 -> 57 | G16: {=INDEX(Engine!$W:$W,$F16)} -> 0.0028740231 | H16: {=INDEX(Engine!$AC:$AC,$F16)} -> 0.013349801 | I16: =$C16*$G16 -> 0.0052401543
A17: Household supplies | B17: 348 | C17: {=INDEX(Macrobond!$A:$PB,$B$4,$B17)/$B$6*100} -> 1.0580091 | D17: CPI: housekeeping supplies | E17: Housekeeping Supplies | F17: =MATCH($E17,Engine!$A$11:$A$65,0)+10 -> 44 | G17: {=INDEX(Engine!$W:$W,$F17)} -> 0.0052710375 | H17: {=INDEX(Engine!$AC:$AC,$F17)} -> 0.013629784 | I17: =$C17*$G17 -> 0.0055768057
A18: Personal care products | B18: 349 | C18: {=INDEX(Macrobond!$A:$PB,$B$4,$B18)/$B$6*100} -> 1.1423652 | D18: CPI: personal care products | E18: Personal Care | F18: =MATCH($E18,Engine!$A$11:$A$65,0)+10 -> 64 | G18: {=INDEX(Engine!$W:$W,$F18)} -> 0.009804739 | H18: {=INDEX(Engine!$AC:$AC,$F18)} -> 0.050478642 | I18: =$C18*$G18 -> 0.011200593
A19: Tobacco | B19: 350 | C19: {=INDEX(Macrobond!$A:$PB,$B$4,$B19)/$B$6*100} -> 0.58397399 | D19: CPI: tobacco & smoking products | E19: Tobacco & Smoking Products | F19: =MATCH($E19,Engine!$A$11:$A$65,0)+10 -> 46 | G19: {=INDEX(Engine!$W:$W,$F19)} -> 0.010073293 | H19: {=INDEX(Engine!$AC:$AC,$F19)} -> 0.063604542 | I19: =$C19*$G19 -> 0.0058825413
A20: Rental of tenant-occupied housing | B20: 357 | C20: {=INDEX(Macrobond!$A:$PB,$B$4,$B20)/$B$6*100} -> 4.1102372 | D20: CPI: rent of primary residence | E20: Rent of Primary Residence | F20: =MATCH($E20,Engine!$A$11:$A$65,0)+10 -> 24 | G20: {=INDEX(Engine!$W:$W,$F20)} -> 0.003619265 | H20: {=INDEX(Engine!$AC:$AC,$F20)} -> 0.04476394 | I20: =$C20*$G20 -> 0.014876037
... A32: Personal care & clothing services | B32: 306 | C32: {=INDEX(Macrobond!$A:$PB,$B$4,$B32)/$B$6*100} -> 1.3425671 | D32: CPI: personal care & laundry svcs | E32: Personal Care | F32: =MATCH($E32,Engine!$A$11:$A$65,0)+10 -> 64 | G32: {=INDEX(Engine!$W:$W,$F32)} -> 0.009804739 | H32: {=INDEX(Engine!$AC:$AC,$F32)} -> 0.050478642 | I32: =$C32*$G32 -> 0.01316352
A33: CPI-MAPPED SUBTOTAL | C33: =SUM(C9:C32) -> 60.926962 | I33: =SUM(I9:I32) -> 0.12277879
A35: NON-CPI-SOURCED CORE PCE COMPONENTS — m/m assumptions in BLUE, update after PPI print
A36: Health care services | B36: 366 | C36: {=INDEX(Macrobond!$A:$PB,$B$4,$B36)/$B$6*100} -> 19.095817 | D36: PPI: hospitals/physicians; Medicare-Medicaid rates | G36: 0.0025 | H36: =(1+$G36)^12-1 -> 0.030415957 | I36: =$C36*$G36 -> 0.047739543
A37: Financial services & insurance | B37: 392 | C37: {=INDEX(Macrobond!$A:$PB,$B$4,$B37)/$B$6*100} -> 9.3176536 | D37: Imputed (FISIM)/PPI; portfolio mgmt tracks equities | G37: 0.003 | H37: =(1+$G37)^12-1 -> 0.03659998 | I37: =$C37*$G37 -> 0.027952961
A38: Other durable goods | B38: 325 | C38: {=INDEX(Macrobond!$A:$PB,$B$4,$B38)/$B$6*100} -> 1.6343752 | D38: CPI jewelry/therapeutic/books mix (unmapped) | G38: 0.0015 | H38: =(1+$G38)^12-1 -> 0.018149245 | I38: =$C38*$G38 -> 0.0024515628
A39: Professional & other services | B39: 410 | C39: {=INDEX(Macrobond!$A:$PB,$B$4,$B39)/$B$6*100} -> 1.5986641 | D39: PPI legal/accounting (partial CPI) | G39: 0.002 | H39: =(1+$G39)^12-1 -> 0.024265768 | I39: =$C39*$G39 -> 0.0031973282
A40: Social services & religious activities | B40: 411 | C40: {=INDEX(Macrobond!$A:$PB,$B$4,$B40)/$B$6*100} -> 1.8788606 | D40: Input-cost based | G40: 0.002 | H40: =(1+$G40)^12-1 -> 0.024265768 | I40: =$C40*$G40 -> 0.0037577213
A41: Household maintenance | B41: 412 | C41: {=INDEX(Macrobond!$A:$PB,$B$4,$B41)/$B$6*100} -> 0.64412167 | D41: Input-cost / partial CPI | G41: 0.0015 | H41: =(1+$G41)^12-1 -> 0.018149245 | I41: =$C41*$G41 -> 0.00096618251
A42: Net foreign travel | B42: 413 | C42: {=INDEX(Macrobond!$A:$PB,$B$4,$B42)/$B$6*100} -> 0.3743802 | D42: Foreign CPIs / FX (negative weight) | G42: 0.002 | H42: =(1+$G42)^12-1 -> 0.024265768 | I42: =$C42*$G42 -> 0.00074876039
A43: Final consumption of NPISHs | B43: 416 | C43: {=INDEX(Macrobond!$A:$PB,$B$4,$B43)/$B$6*100} -> 3.3473396 | D43: Input-cost based | G43: 0.002 | H43: =(1+$G43)^12-1 -> 0.024265768 | I43: =$C43*$G43 -> 0.0066946792
A44: Residual — unmapped core components | C44: =100-$C$33-SUM(C36:C43) -> 1.1818258 | D44: Group housing, employee meals, misc unmapped | G44: 0.002 | H44: =(1+$G44)^12-1 -> 0.024265768 | I44: =$C44*$G44 -> 0.0023636516
A45: NON-CPI SUBTOTAL | C45: =SUM(C36:C44) -> 39.073038 | I45: =SUM(I36:I44) -> 0.09587239
A47: IMPLIED CORE PCE M/M — WEIGHTED TOTAL | C47: =C33+C45 -> 100 | I47: =I33+I45 -> 0.21865118
A49: BOTTOM LINE — CORE PCE READ-THROUGH
A50: Implied core PCE m/m (CPI pass-through + assumptions) | D50: =$I$47/100 -> 0.0021865118
A51: Annualized pace | D51: =(1+$I$47/100)^12-1 -> 0.026555987
A52: CPI-mapped basket only — m/m | D52: =$I$33/$C$33 -> 0.0020151799
A53: CPI-mapped basket — 3m SAAR trend | D53: =SUMPRODUCT($C$9:$C$32,$H$9:$H$32)/$C$33 -> 0.033375975
A54: Directional bias for upcoming core PCE print | D54: =IF($I$47/100>=0.0025,"HOT — clear upside risk vs 2% pace",IF($I$47/100>=0.0017,"WARM — modestly above 2% target pace",IF($I$47/100>=0.0008,"ON TARGET — consistent with ~2% annualized","COOL — downside risk / disinflationary"))) -> WARM — modestly above 2% target pace
A57: ="• CPI pass-through implies core PCE ≈ "&TEXT($I$47/100,"0.00%")&" m/m ("&TEXT((1+$I$47/100)^12-1,"0.0%")&" annualized) for "&TEXT(Engine!$B$5,"mmm-yy")&"; CPI-sourced components cover "&TEXT($C$33/100,"0%")&" of the core basket." -> • CPI pass-through implies core PCE ≈ 0.22% m/m (2.7% annualized) for May-26; CPI-sourced components cover 61% of the core basket. | K57: =MATCH(MAX($I$9:$I$32),$I$9:$I$32,0) -> 13
A58: {="• Biggest pass-through boost: "&INDEX($A$9:$A$32,$K$57)&" ("&TEXT(INDEX($G$9:$G$32,$K$57),"+0.00%;-0.00%")&" m/m → "&TEXT(INDEX($I$9:$I$32,$K$57),"+0.000;-0.000")&"pp); biggest drag: "&INDEX($A$9:$A$32,$K$58)&" ("&TEXT(INDEX($G$9:$G$32,$K$58),"+0.00%;-0.00%")&" → "&TEXT(INDEX($I$9:$I$32,$K$58),"+0.000;-0.000")&"pp)."} -> • Biggest pass-through boost: Imputed rental of owner-occupied housing (+0.30% m/m → +0.040pp); biggest drag: Other motor vehicle services (-4.21% → -0.027pp). | K58: =MATCH(MIN($I$9:$I$32),$I$9:$I$32,0) -> 16
...

Sheet PCE Source Data
A1: Table 2.4.4 U-D. Price Indexes for PCE: Source Data | D1: 46073
A4: Item | B4: PCE Component | C4: Series Code | D4: Price index source data* | E4: Seasonal Status
A5: 1 | B5: Personal consumption expenditures by type of product | C5: E1PCE1
A6: 2 | B6: Goods | C6: E1GDS1
A7: 3 | B7: Durable goods | C7: E1DUR1
A8: 4 | B8: Motor vehicles and parts | C8: E1MOT1
A9: 5 | B9: New motor vehicles | C9: E1NMV1
A10: 6 | B10: New autos | C10: E1NEA1
A11: 7 | B11: New domestic autos | C11: E1NDC1 | D11: CPI New cars | E11: SA
A12: 8 | B12: New foreign autos | C12: E1NFC1 | D12: CPI New cars | E12: SA
A13: 9 | B13: New light trucks | C13: E1NWT1 | D13: CPI New trucks | E13: SA
A14: 10 | B14: New domestic light trucks | C14: E1DTN1 | D14: CPI New trucks | E14: SA
A15: 11 | B15: New foreign light trucks | C15: E1FTN1 | D15: CPI New trucks | E15: SA
A16: 12 | B16: Net purchases of used motor vehicles | C16: E1NPV1
A17: 13 | B17: Used autos | C17: E1NPU1
A18: 14 | B18: Net transactions in used autos | C18: E1NET1 | D18: CPI Used cars and trucks | E18: SA
A19: 15 | B19: Used auto margin | C19: E1MAR1 | D19: CPI Used cars and trucks | E19: SA
A20: 16 | B20: Employee reimbursement | C20: E1REE1 | D20: CPI Car and truck rental | E20: SA
A21: 17 | B21: Used light trucks | C21: E1UTR1
A22: 18 | B22: Net transactions in used trucks | C22: E1UTN1 | D22: CPI Used cars and trucks | E22: SA
A23: 19 | B23: Used truck margin | C23: E1UTM1 | D23: CPI Used cars and trucks | E23: SA
A24: 20 | B24: Motor vehicles parts and accessories | C24: E1MVP1
A25: 21 | B25: Tires | C25: E1TAT1 | D25: CPI Tires | E25: NSA
A26: 22 | B26: Accessories and parts | C26: E1PAA1 | D26: CPI Vehicle parts and equipment other than tires | E26: NSA
A27: 23 | B27: Furnishings and durable household equipment | C27: E1FDH1
A28: 24 | B28: Furniture and furnishings | C28: E1FFF1
A29: 25 | B29: Furniture | C29: E1FNR1 | D29: CPI Furniture and bedding | E29: NSA
A30: 26 | B30: Clocks, lamps, lighting fixtures, and other household decorative items | C30: E1CLF1 | D30: CPI Clocks, lamps, and decorator items | E30: NSA
A31: 27 | B31: Carpets and other floor coverings | C31: E1FLR1 | D31: CPI Floor coverings | E31: NSA
A32: 28 | B32: Window coverings | C32: E1WCT1 | D32: CPI Window coverings | E32: NSA
A33: 29 | B33: Household appliances | C33: E1APP1
A34: 30 | B34: Major household appliances | C34: E1MHA1 | D34: CPI Major appliances | E34: SA
A35: 31 | B35: Small electric household appliances | C35: E1SEA1 | D35: CPI Other appliances | E35: SA
A36: 32 | B36: Glassware, tableware, and household utensils | C36: E1UTE1
A37: 33 | B37: Dishes and flatware | C37: E1CHN1 | D37: CPI Dishes and flatware | E37: NSA
A38: 34 | B38: Nonelectric cookware and tableware | C38: E1NEC1 | D38: CPI Nonelectric cookware and tableware | E38: SA
A39: 35 | B39: Tools and equipment for house and garden | C39: E1TOO1
A40: 36 | B40: Tools, hardware, and supplies | C40: E1HDW1 | D40: CPI Tools, hardware, and supplies | E40: SA
A41: 37 | B41: Outdoor equipment and supplies | C41: E1LWN1 | D41: CPI Outdoor equipment and supplies | E41: NSA
A42: 38 | B42: Recreational goods and vehicles | C42: E1REQ1
...

Sheet Macrobond
A3: United States
