Workbook
Name Macrobond_Object1: Macrobond!$A$3:$BP$1052
Name Macrobond_Object2: Macrobond!$C$4:$WW$1054

Sheet Dashboard
B1: U.S. EMPLOYMENT SITUATION DASHBOARD
B2: ="Latest: "&TEXT(Engine!$B$4,"mmmm yyyy")&" • Auto-updates when a new vintage lands in the Macrobond tab • Seasonally adjusted unless noted" -> Latest: May 2026 • Auto-updates when a new vintage lands in the Macrobond tab • Seasonally adjusted unless noted
B3: ="U-3 "&TEXT($B$7,"0.0")&"% (unrounded "&TEXT($D$7,"0.000")&", MoM "&TEXT($D$8,"+0.000;-0.000")&") • EPOP "&TEXT($F$7,"0.0")&" ("&TEXT($F$8,"+0.0;-0.0")&"pp) • HH emp "&TEXT($L$8,"+#,##0;-#,##0")&"k MoM • Sahm "&TEXT($C$57,"0.00")&IF($C$57>=0.5," ⚠ TRIGGERED"," (no trigger)") -> U-3 4.3% (unrounded 4.296, MoM -0.041) • EPOP 59.2 (+0.1pp) • HH emp +149k MoM • Sahm 0.10 (no trigger) | T3: ="HH vs CES YoY: "&TEXT($T$7,"+#,##0;-#,##0")&"k vs "&TEXT($W$7,"+#,##0;-#,##0")&"k → gap "&TEXT($Z$7,"+#,##0;-#,##0")&"k" -> HH vs CES YoY: -473k vs +435k → gap -908k | AK3: ="NFP "&TEXT($AK$7,"+#,##0;-#,##0")&"k • 3M "&TEXT($AQ$7,"+#,##0;-#,##0")&"k • YoY "&TEXT($AT$7,"+#,##0;-#,##0")&"k • AWE "&TEXT($AZ$7,"+0.0%;-0.0%")&" YoY • breadth "&TEXT($AY$79,"0%")&" • best: "&LEFT($AL$56,38)&" • worst: "&LEFT($AL$67,38) -> NFP +172k • 3M +188k • YoY +503k • AWE +3.7% YoY • breadth 58% • best: Trade, Transportation & Utilities, Tra • worst: Trade, Transportation & Utilities, Tra
B4: HOUSEHOLD SURVEY (CPS) | T4: CONCEPT RECONCILIATION — CPS vs CES | AK4: ESTABLISHMENT SURVEY (CES) — seasonally adjusted
B6: U-3 headline | D6: U-3 unrounded (3dp) | F6: EPOP | H6: LFPR | J6: Labor force (mn) | L6: Employed (mn) | T6: HH employ YoY (k) | W6: Payrolls YoY (k) | Z6: HH−CES YoY gap (k) | AK6: Nonfarm payrolls Δ (k) | AN6: Private Δ (k) | AQ6: 3M avg pace (k) | AT6: Payrolls YoY (k) | AW6: Avg wkly hrs (priv) | AZ6: Avg wkly earn YoY
B7: {=INDEX(Macrobond!$IT:$IT,Engine!$B$3)} -> 4.3 | D7: {=INDEX(Macrobond!$IS:$IS,Engine!$B$3)/INDEX(Macrobond!$IO:$IO,Engine!$B$3)*100} -> 4.2962641 | F7: {=INDEX(Macrobond!$IR:$IR,Engine!$B$3)} -> 59.2 | H7: {=INDEX(Macrobond!$IP:$IP,Engine!$B$3)} -> 61.8 | J7: {=INDEX(Macrobond!$IO:$IO,Engine!$B$3)/1000000} -> 170.078 | L7: {=INDEX(Macrobond!$IQ:$IQ,Engine!$B$3)/1000000} -> 162.771 | T7: {=(INDEX(Macrobond!$IQ:$IQ,Engine!$B$3)-INDEX(Macrobond!$IQ:$IQ,Engine!$B$3-12))/1000} -> -473 | W7: {=(INDEX(Macrobond!$AI:$AI,Engine!$B$3)-INDEX(Macrobond!$AI:$AI,Engine!$B$3-12))/1000} -> 435 | Z7: =$T$7-$W$7 -> -908 | AK7: {=(INDEX(Macrobond!$QG:$QG,Engine!$B$3)-INDEX(Macrobond!$QG:$QG,Engine!$B$3-1))/1000} -> 172 | AN7: {=(INDEX(Macrobond!$QH:$QH,Engine!$B$3)-INDEX(Macrobond!$QH:$QH,Engine!$B$3-1))/1000} -> 120 | AQ7: {=(INDEX(Macrobond!$QG:$QG,Engine!$B$3)-INDEX(Macrobond!$QG:$QG,Engine!$B$3-3))/3/1000} -> 188.33333 | AT7: {=(INDEX(Macrobond!$QG:$QG,Engine!$B$3)-INDEX(Macrobond!$QG:$QG,Engine!$B$3-12))/1000} -> 503 | AW7: {=INDEX(Macrobond!$GZ:$GZ,Engine!$B$3)} -> 34.3 | AZ7: {=INDEX(Macrobond!$HV:$HV,Engine!$B$3)/INDEX(Macrobond!$HV:$HV,Engine!$B$3-12)-1} -> 0.037476426
B8: {=INDEX(Macrobond!$IT:$IT,Engine!$B$3)-INDEX(Macrobond!$IT:$IT,Engine!$B$3-1)} -> 0 | D8: {=D7-INDEX(Macrobond!$IS:$IS,Engine!$B$3-1)/INDEX(Macrobond!$IO:$IO,Engine!$B$3-1)*100} -> -0.040922321 | F8: {=INDEX(Macrobond!$IR:$IR,Engine!$B$3)-INDEX(Macrobond!$IR:$IR,Engine!$B$3-1)} -> 0.1 | H8: {=INDEX(Macrobond!$IP:$IP,Engine!$B$3)-INDEX(Macrobond!$IP:$IP,Engine!$B$3-1)} -> 0 | J8: {=(INDEX(Macrobond!$IO:$IO,Engine!$B$3)-INDEX(Macrobond!$IO:$IO,Engine!$B$3-1))/1000} -> 83 | L8: {=(INDEX(Macrobond!$IQ:$IQ,Engine!$B$3)-INDEX(Macrobond!$IQ:$IQ,Engine!$B$3-1))/1000} -> 149
T9: YoY basis (seasonally neutral): CES here is NSA, so 12M change is the clean lens. Divergence reflects measurement (CPS counts persons incl. self-employed/ag; CES counts payroll jobs). MoM SA prints wire in once SA columns are added.
B10: Headline — rates & levels | C10: =Engine!B$10 -> 45778 | D10: =Engine!C$10 -> 45809 | E10: =Engine!D$10 -> 45839 | F10: =Engine!E$10 -> 45870 | G10: =Engine!F$10 -> 45901 | H10: =Engine!G$10 -> 45931 | I10: =Engine!H$10 -> 45962 | J10: =Engine!I$10 -> 45992 | ... O10: =Engine!N$10 -> 46143 | P10: MoM | Q10: 3M | R10: YoY | T10: YoY change (000s) | U10: =Engine!B$10 -> 45778 | V10: =Engine!C$10 -> 45809 | W10: =Engine!D$10 -> 45839 | X10: =Engine!E$10 -> 45870 | Y10: =Engine!F$10 -> 45901 | Z10: =Engine!G$10 -> 45931 | AA10: =Engine!H$10 -> 45962 | AB10: =Engine!I$10 -> 45992 | ... AG10: =Engine!N$10 -> 46143 | AH10: Latest | AK10: Sector employment, SA (000s) | AL10: =Engine!B$10 -> 45778 | AM10: =Engine!C$10 -> 45809 | AN10: =Engine!D$10 -> 45839 | AO10: =Engine!E$10 -> 45870 | AP10: =Engine!F$10 -> 45901 | AQ10: =Engine!G$10 -> 45931 | AR10: =Engine!H$10 -> 45962 | AS10: =Engine!I$10 -> 45992 | ... AX10: =Engine!N$10 -> 46143 | AY10: MoM(k) | AZ10: 3Mavg(k) | BA10: YoY(k) | BB10: %NFPΔ
B11: U-3 unemployment rate (%) | C11: {=INDEX(Macrobond!$IT:$IT,Engine!B$9)} -> 4.3 | D11: {=INDEX(Macrobond!$IT:$IT,Engine!C$9)} -> 4.1 | E11: {=INDEX(Macrobond!$IT:$IT,Engine!D$9)} -> 4.3 | F11: {=INDEX(Macrobond!$IT:$IT,Engine!E$9)} -> 4.3 | G11: {=INDEX(Macrobond!$IT:$IT,Engine!F$9)} -> 4.4 | H11: {=INDEX(Macrobond!$IT:$IT,Engine!G$9)} -> 4.4 | I11: {=INDEX(Macrobond!$IT:$IT,Engine!H$9)} -> 4.5 | J11: {=INDEX(Macrobond!$IT:$IT,Engine!I$9)} -> 4.4 | ... O11: {=INDEX(Macrobond!$IT:$IT,Engine!N$9)} -> 4.3 | P11: =$O11-$N11 -> 0 | Q11: =$O11-$L11 -> -0.1 | R11: =$O11-$C11 -> 0 | T11: HH employment YoY | U11: {=(INDEX(Macrobond!$IQ:$IQ,Engine!B$9)-INDEX(Macrobond!$IQ:$IQ,Engine!B$9-12))/1000} -> 2064 | V11: {=(INDEX(Macrobond!$IQ:$IQ,Engine!C$9)-INDEX(Macrobond!$IQ:$IQ,Engine!C$9-12))/1000} -> 2175 | W11: {=(INDEX(Macrobond!$IQ:$IQ,Engine!D$9)-INDEX(Macrobond!$IQ:$IQ,Engine!D$9-12))/1000} -> 1843 | X11: {=(INDEX(Macrobond!$IQ:$IQ,Engine!E$9)-INDEX(Macrobond!$IQ:$IQ,Engine!E$9-12))/1000} -> 1941 | Y11: {=(INDEX(Macrobond!$IQ:$IQ,Engine!F$9)-INDEX(Macrobond!$IQ:$IQ,Engine!F$9-12))/1000} -> 1843 | Z11: {=(INDEX(Macrobond!$IQ:$IQ,Engine!G$9)-INDEX(Macrobond!$IQ:$IQ,Engine!G$9-12))/1000} -> 2212 | AA11: {=(INDEX(Macrobond!$IQ:$IQ,Engine!H$9)-INDEX(Macrobond!$IQ:$IQ,Engine!H$9-12))/1000} -> 2601 | AB11: {=(INDEX(Macrobond!$IQ:$IQ,Engine!I$9)-INDEX(Macrobond!$IQ:$IQ,Engine!I$9-12))/1000} -> 2406 | ... AG11: {=(INDEX(Macrobond!$IQ:$IQ,Engine!N$9)-INDEX(Macrobond!$IQ:$IQ,Engine!N$9-12))/1000} -> -473 | AH11: =$AG11 -> -473 | AK11: Total nonfarm | AL11: {=INDEX(Macrobond!$QG:$QG,Engine!B$9)/1000} -> 158498 | AM11: {=INDEX(Macrobond!$QG:$QG,Engine!C$9)/1000} -> 158478 | AN11: {=INDEX(Macrobond!$QG:$QG,Engine!D$9)/1000} -> 158542 | AO11: {=INDEX(Macrobond!$QG:$QG,Engine!E$9)/1000} -> 158472 | AP11: {=INDEX(Macrobond!$QG:$QG,Engine!F$9)/1000} -> 158548 | AQ11: {=INDEX(Macrobond!$QG:$QG,Engine!G$9)/1000} -> 158408 | AR11: {=INDEX(Macrobond!$QG:$QG,Engine!H$9)/1000} -> 158449 | AS11: {=INDEX(Macrobond!$QG:$QG,Engine!I$9)/1000} -> 158432 | ... AX11: {=INDEX(Macrobond!$QG:$QG,Engine!N$9)/1000} -> 159001 | AY11: =AX11-AW11 -> 172 | AZ11: =(AX11-AU11)/3 -> 188.33333 | BA11: =AX11-AL11 -> 503 | BB11: =IF($AY$11=0,"",AY11/$AY$11) -> 1
B12: U-3 unrounded (3dp) | C12: {=INDEX(Macrobond!$IS:$IS,Engine!B$9)/INDEX(Macrobond!$IO:$IO,Engine!B$9)*100} -> 4.2512259 | D12: {=INDEX(Macrobond!$IS:$IS,Engine!C$9)/INDEX(Macrobond!$IO:$IO,Engine!C$9)*100} -> 4.1401573 | E12: {=INDEX(Macrobond!$IS:$IS,Engine!D$9)/INDEX(Macrobond!$IO:$IO,Engine!D$9)*100} -> 4.2673051 | F12: {=INDEX(Macrobond!$IS:$IS,Engine!E$9)/INDEX(Macrobond!$IO:$IO,Engine!E$9)*100} -> 4.3221083 | G12: {=INDEX(Macrobond!$IS:$IS,Engine!F$9)/INDEX(Macrobond!$IO:$IO,Engine!F$9)*100} -> 4.4405907 | H12: {=INDEX(Macrobond!$IS:$IS,Engine!G$9)/INDEX(Macrobond!$IO:$IO,Engine!G$9)*100} -> 4.4405907 | I12: {=INDEX(Macrobond!$IS:$IS,Engine!H$9)/INDEX(Macrobond!$IO:$IO,Engine!H$9)*100} -> 4.5359418 | J12: {=INDEX(Macrobond!$IS:$IS,Engine!I$9)/INDEX(Macrobond!$IO:$IO,Engine!I$9)*100} -> 4.3750547 | ... O12: {=INDEX(Macrobond!$IS:$IS,Engine!N$9)/INDEX(Macrobond!$IO:$IO,Engine!N$9)*100} -> 4.2962641 | P12: =$O12-$N12 -> -0.040922321 | Q12: =$O12-$L12 -> -0.14464793 | R12: =$O12-$C12 -> 0.045038203 | T12: Nonfarm payrolls YoY | U12: {=(INDEX(Macrobond!$AI:$AI,Engine!B$9)-INDEX(Macrobond!$AI:$AI,Engine!B$9-12))/1000} -> 915 | V12: {=(INDEX(Macrobond!$AI:$AI,Engine!C$9)-INDEX(Macrobond!$AI:$AI,Engine!C$9-12))/1000} -> 786 | W12: {=(INDEX(Macrobond!$AI:$AI,Engine!D$9)-INDEX(Macrobond!$AI:$AI,Engine!D$9-12))/1000} -> 782 | X12: {=(INDEX(Macrobond!$AI:$AI,Engine!E$9)-INDEX(Macrobond!$AI:$AI,Engine!E$9-12))/1000} -> 712 | Y12: {=(INDEX(Macrobond!$AI:$AI,Engine!F$9)-INDEX(Macrobond!$AI:$AI,Engine!F$9-12))/1000} -> 618 | Z12: {=(INDEX(Macrobond!$AI:$AI,Engine!G$9)-INDEX(Macrobond!$AI:$AI,Engine!G$9-12))/1000} -> 502 | AA12: {=(INDEX(Macrobond!$AI:$AI,Engine!H$9)-INDEX(Macrobond!$AI:$AI,Engine!H$9-12))/1000} -> 264 | AB12: {=(INDEX(Macrobond!$AI:$AI,Engine!I$9)-INDEX(Macrobond!$AI:$AI,Engine!I$9-12))/1000} -> 69 | ... AG12: {=(INDEX(Macrobond!$AI:$AI,Engine!N$9)-INDEX(Macrobond!$AI:$AI,Engine!N$9-12))/1000} -> 435 | AH12: =$AG12 -> 435 | AK12: Total private | AL12: {=INDEX(Macrobond!$QH:$QH,Engine!B$9)/1000} -> 134937 | AM12: {=INDEX(Macrobond!$QH:$QH,Engine!C$9)/1000} -> 134892 | AN12: {=INDEX(Macrobond!$QH:$QH,Engine!D$9)/1000} -> 134957 | AO12: {=INDEX(Macrobond!$QH:$QH,Engine!E$9)/1000} -> 134937 | AP12: {=INDEX(Macrobond!$QH:$QH,Engine!F$9)/1000} -> 135005 | AQ12: {=INDEX(Macrobond!$QH:$QH,Engine!G$9)/1000} -> 135018 | AR12: {=INDEX(Macrobond!$QH:$QH,Engine!H$9)/1000} -> 135090 | AS12: {=INDEX(Macrobond!$QH:$QH,Engine!I$9)/1000} -> 135083 | ... AX12: {=INDEX(Macrobond!$QH:$QH,Engine!N$9)/1000} -> 135614 | AY12: =AX12-AW12 -> 120 | AZ12: =(AX12-AU12)/3 -> 166.33333 | BA12: =AX12-AL12 -> 677 | BB12: =IF($AY$11=0,"",AY12/$AY$11) -> 0.69767442
B13: Employment-population ratio (%) | C13: {=INDEX(Macrobond!$IR:$IR,Engine!B$9)} -> 59.7 | D13: {=INDEX(Macrobond!$IR:$IR,Engine!C$9)} -> 59.7 | E13: {=INDEX(Macrobond!$IR:$IR,Engine!D$9)} -> 59.6 | F13: {=INDEX(Macrobond!$IR:$IR,Engine!E$9)} -> 59.6 | G13: {=INDEX(Macrobond!$IR:$IR,Engine!F$9)} -> 59.7 | H13: {=INDEX(Macrobond!$IR:$IR,Engine!G$9)} -> 59.7 | I13: {=INDEX(Macrobond!$IR:$IR,Engine!H$9)} -> 59.6 | J13: {=INDEX(Macrobond!$IR:$IR,Engine!I$9)} -> 59.7 | ... O13: {=INDEX(Macrobond!$IR:$IR,Engine!N$9)} -> 59.2 | P13: =$O13-$N13 -> 0.1 | Q13: =$O13-$L13 -> -0.1 | R13: =$O13-$C13 -> -0.5 | T13: Gap (HH − CES) | U13: =U11-U12 -> 1149 | V13: =V11-V12 -> 1389 | W13: =W11-W12 -> 1061 | X13: =X11-X12 -> 1229 | Y13: =Y11-Y12 -> 1225 | Z13: =Z11-Z12 -> 1710 | AA13: =AA11-AA12 -> 2337 | AB13: =AB11-AB12 -> 2337 | ... AG13: =AG11-AG12 -> -908 | AH13: =$AG13 -> -908 | AK13: Goods-producing | AL13: {=INDEX(Macrobond!$QI:$QI,Engine!B$9)/1000} -> 21538 | AM13: {=INDEX(Macrobond!$QI:$QI,Engine!C$9)/1000} -> 21519 | AN13: {=INDEX(Macrobond!$QI:$QI,Engine!D$9)/1000} -> 21496 | AO13: {=INDEX(Macrobond!$QI:$QI,Engine!E$9)/1000} -> 21461 | AP13: {=INDEX(Macrobond!$QI:$QI,Engine!F$9)/1000} -> 21472 | AQ13: {=INDEX(Macrobond!$QI:$QI,Engine!G$9)/1000} -> 21452 | AR13: {=INDEX(Macrobond!$QI:$QI,Engine!H$9)/1000} -> 21477 | AS13: {=INDEX(Macrobond!$QI:$QI,Engine!I$9)/1000} -> 21456 | ... AX13: {=INDEX(Macrobond!$QI:$QI,Engine!N$9)/1000} -> 21555 | AY13: =AX13-AW13 -> 28 | AZ13: =(AX13-AU13)/3 -> 25 | BA13: =AX13-AL13 -> 17 | BB13: =IF($AY$11=0,"",AY13/$AY$11) -> 0.1627907
B14: Labor force participation rate (%) | C14: {=INDEX(Macrobond!$IP:$IP,Engine!B$9)} -> 62.4 | D14: {=INDEX(Macrobond!$IP:$IP,Engine!C$9)} -> 62.3 | E14: {=INDEX(Macrobond!$IP:$IP,Engine!D$9)} -> 62.2 | F14: {=INDEX(Macrobond!$IP:$IP,Engine!E$9)} -> 62.3 | G14: {=INDEX(Macrobond!$IP:$IP,Engine!F$9)} -> 62.5 | H14: {=INDEX(Macrobond!$IP:$IP,Engine!G$9)} -> 62.5 | I14: {=INDEX(Macrobond!$IP:$IP,Engine!H$9)} -> 62.5 | J14: {=INDEX(Macrobond!$IP:$IP,Engine!I$9)} -> 62.4 | ... O14: {=INDEX(Macrobond!$IP:$IP,Engine!N$9)} -> 61.8 | P14: =$O14-$N14 -> 0 | Q14: =$O14-$L14 -> -0.2 | R14: =$O14-$C14 -> -0.6 | AK14: Mining & logging | AL14: {=INDEX(Macrobond!$QJ:$QJ,Engine!B$9)/1000} -> 618 | AM14: {=INDEX(Macrobond!$QJ:$QJ,Engine!C$9)/1000} -> 616 | AN14: {=INDEX(Macrobond!$QJ:$QJ,Engine!D$9)/1000} -> 610 | AO14: {=INDEX(Macrobond!$QJ:$QJ,Engine!E$9)/1000} -> 607 | AP14: {=INDEX(Macrobond!$QJ:$QJ,Engine!F$9)/1000} -> 605 | AQ14: {=INDEX(Macrobond!$QJ:$QJ,Engine!G$9)/1000} -> 606 | AR14: {=INDEX(Macrobond!$QJ:$QJ,Engine!H$9)/1000} -> 605 | AS14: {=INDEX(Macrobond!$QJ:$QJ,Engine!I$9)/1000} -> 604 | ... AX14: {=INDEX(Macrobond!$QJ:$QJ,Engine!N$9)/1000} -> 613 | AY14: =AX14-AW14 -> 4 | AZ14: =(AX14-AU14)/3 -> 4 | BA14: =AX14-AL14 -> -5 | BB14: =IF($AY$11=0,"",AY14/$AY$11) -> 0.023255814
B15: Civilian labor force (000s) | C15: {=INDEX(Macrobond!$IO:$IO,Engine!B$9)/1000} -> 170492 | D15: {=INDEX(Macrobond!$IO:$IO,Engine!C$9)/1000} -> 170380 | E15: {=INDEX(Macrobond!$IO:$IO,Engine!D$9)/1000} -> 170412 | F15: {=INDEX(Macrobond!$IO:$IO,Engine!E$9)/1000} -> 170750 | G15: {=INDEX(Macrobond!$IO:$IO,Engine!F$9)/1000} -> 171261 | H15: {=INDEX(Macrobond!$IO:$IO,Engine!G$9)/1000} -> 171261 | I15: {=INDEX(Macrobond!$IO:$IO,Engine!H$9)/1000} -> 171541 | J15: {=INDEX(Macrobond!$IO:$IO,Engine!I$9)/1000} -> 171495 | ... O15: {=INDEX(Macrobond!$IO:$IO,Engine!N$9)/1000} -> 170078 | P15: =$O15-$N15 -> 83 | Q15: =$O15-$L15 -> -405 | R15: =$O15-$C15 -> -414 | AK15: Construction | AL15: {=INDEX(Macrobond!$QS:$QS,Engine!B$9)/1000} -> 8269 | AM15: {=INDEX(Macrobond!$QS:$QS,Engine!C$9)/1000} -> 8267 | AN15: {=INDEX(Macrobond!$QS:$QS,Engine!D$9)/1000} -> 8261 | AO15: {=INDEX(Macrobond!$QS:$QS,Engine!E$9)/1000} -> 8239 | AP15: {=INDEX(Macrobond!$QS:$QS,Engine!F$9)/1000} -> 8255 | AQ15: {=INDEX(Macrobond!$QS:$QS,Engine!G$9)/1000} -> 8243 | AR15: {=INDEX(Macrobond!$QS:$QS,Engine!H$9)/1000} -> 8279 | AS15: {=INDEX(Macrobond!$QS:$QS,Engine!I$9)/1000} -> 8272 | ... AX15: {=INDEX(Macrobond!$QS:$QS,Engine!N$9)/1000} -> 8337 | AY15: =AX15-AW15 -> 17 | AZ15: =(AX15-AU15)/3 -> 13.666667 | BA15: =AX15-AL15 -> 68 | BB15: =IF($AY$11=0,"",AY15/$AY$11) -> 0.098837209
B16: Employed (000s) | C16: {=INDEX(Macrobond!$IQ:$IQ,Engine!B$9)/1000} -> 163244 | D16: {=INDEX(Macrobond!$IQ:$IQ,Engine!C$9)/1000} -> 163327 | E16: {=INDEX(Macrobond!$IQ:$IQ,Engine!D$9)/1000} -> 163140 | F16: {=INDEX(Macrobond!$IQ:$IQ,Engine!E$9)/1000} -> 163370 | G16: {=INDEX(Macrobond!$IQ:$IQ,Engine!F$9)/1000} -> 163656 | H16: {=INDEX(Macrobond!$IQ:$IQ,Engine!G$9)/1000} -> 163656 | I16: {=INDEX(Macrobond!$IQ:$IQ,Engine!H$9)/1000} -> 163760 | J16: {=INDEX(Macrobond!$IQ:$IQ,Engine!I$9)/1000} -> 163992 | ... O16: {=INDEX(Macrobond!$IQ:$IQ,Engine!N$9)/1000} -> 162771 | P16: =$O16-$N16 -> 149 | Q16: =$O16-$L16 -> -141 | R16: =$O16-$C16 -> -473 | AK16: Manufacturing | AL16: {=INDEX(Macrobond!$RA:$RA,Engine!B$9)/1000} -> 12651 | AM16: {=INDEX(Macrobond!$RA:$RA,Engine!C$9)/1000} -> 12636 | AN16: {=INDEX(Macrobond!$RA:$RA,Engine!D$9)/1000} -> 12625 | AO16: {=INDEX(Macrobond!$RA:$RA,Engine!E$9)/1000} -> 12615 | AP16: {=INDEX(Macrobond!$RA:$RA,Engine!F$9)/1000} -> 12612 | AQ16: {=INDEX(Macrobond!$RA:$RA,Engine!G$9)/1000} -> 12603 | AR16: {=INDEX(Macrobond!$RA:$RA,Engine!H$9)/1000} -> 12593 | AS16: {=INDEX(Macrobond!$RA:$RA,Engine!I$9)/1000} -> 12580 | ... AX16: {=INDEX(Macrobond!$RA:$RA,Engine!N$9)/1000} -> 12605 | AY16: =AX16-AW16 -> 7 | AZ16: =(AX16-AU16)/3 -> 7.3333333 | BA16: =AX16-AL16 -> -46 | BB16: =IF($AY$11=0,"",AY16/$AY$11) -> 0.040697674
B17: Unemployed (000s) | C17: {=INDEX(Macrobond!$IS:$IS,Engine!B$9)/1000} -> 7248 | D17: {=INDEX(Macrobond!$IS:$IS,Engine!C$9)/1000} -> 7054 | E17: {=INDEX(Macrobond!$IS:$IS,Engine!D$9)/1000} -> 7272 | F17: {=INDEX(Macrobond!$IS:$IS,Engine!E$9)/1000} -> 7380 | G17: {=INDEX(Macrobond!$IS:$IS,Engine!F$9)/1000} -> 7605 | H17: {=INDEX(Macrobond!$IS:$IS,Engine!G$9)/1000} -> 7605 | I17: {=INDEX(Macrobond!$IS:$IS,Engine!H$9)/1000} -> 7781 | J17: {=INDEX(Macrobond!$IS:$IS,Engine!I$9)/1000} -> 7503 | ... O17: {=INDEX(Macrobond!$IS:$IS,Engine!N$9)/1000} -> 7307 | P17: =$O17-$N17 -> -66 | Q17: =$O17-$L17 -> -264 | R17: =$O17-$C17 -> 59 | AK17: Private services | AL17: {=INDEX(Macrobond!$SD:$SD,Engine!B$9)/1000} -> 113399 | AM17: {=INDEX(Macrobond!$SD:$SD,Engine!C$9)/1000} -> 113373 | AN17: {=INDEX(Macrobond!$SD:$SD,Engine!D$9)/1000} -> 113461 | AO17: {=INDEX(Macrobond!$SD:$SD,Engine!E$9)/1000} -> 113476 | AP17: {=INDEX(Macrobond!$SD:$SD,Engine!F$9)/1000} -> 113533 | AQ17: {=INDEX(Macrobond!$SD:$SD,Engine!G$9)/1000} -> 113566 | AR17: {=INDEX(Macrobond!$SD:$SD,Engine!H$9)/1000} -> 113613 | AS17: {=INDEX(Macrobond!$SD:$SD,Engine!I$9)/1000} -> 113627 | ... AX17: {=INDEX(Macrobond!$SD:$SD,Engine!N$9)/1000} -> 114059 | AY17: =AX17-AW17 -> 92 | AZ17: =(AX17-AU17)/3 -> 141.33333 | BA17: =AX17-AL17 -> 660 | BB17: =IF($AY$11=0,"",AY17/$AY$11) -> 0.53488372
B18: Not in labor force (000s) | C18: {=INDEX(Macrobond!$IU:$IU,Engine!B$9)/1000} -> 102893 | D18: {=INDEX(Macrobond!$IU:$IU,Engine!C$9)/1000} -> 103205 | E18: {=INDEX(Macrobond!$IU:$IU,Engine!D$9)/1000} -> 103373 | F18: {=INDEX(Macrobond!$IU:$IU,Engine!E$9)/1000} -> 103251 | G18: {=INDEX(Macrobond!$IU:$IU,Engine!F$9)/1000} -> 102964 | H18: {=INDEX(Macrobond!$IU:$IU,Engine!G$9)/1000} -> 102964 | I18: {=INDEX(Macrobond!$IU:$IU,Engine!H$9)/1000} -> 103092 | J18: {=INDEX(Macrobond!$IU:$IU,Engine!I$9)/1000} -> 103321 | ... O18: {=INDEX(Macrobond!$IU:$IU,Engine!N$9)/1000} -> 104976 | P18: =$O18-$N18 -> 17 | Q18: =$O18-$L18 -> 693 | R18: =$O18-$C18 -> 2083 | AK18: Trade, transp & util | AL18: {=INDEX(Macrobond!$SE:$SE,Engine!B$9)/1000} -> 28765 | AM18: {=INDEX(Macrobond!$SE:$SE,Engine!C$9)/1000} -> 28741 | AN18: {=INDEX(Macrobond!$SE:$SE,Engine!D$9)/1000} -> 28744 | AO18: {=INDEX(Macrobond!$SE:$SE,Engine!E$9)/1000} -> 28743 | AP18: {=INDEX(Macrobond!$SE:$SE,Engine!F$9)/1000} -> 28725 | AQ18: {=INDEX(Macrobond!$SE:$SE,Engine!G$9)/1000} -> 28714 | AR18: {=INDEX(Macrobond!$SE:$SE,Engine!H$9)/1000} -> 28649 | AS18: {=INDEX(Macrobond!$SE:$SE,Engine!I$9)/1000} -> 28616 | ... AX18: {=INDEX(Macrobond!$SE:$SE,Engine!N$9)/1000} -> 28709 | AY18: =AX18-AW18 -> -3 | AZ18: =(AX18-AU18)/3 -> 30.333333 | BA18: =AX18-AL18 -> -56 | BB18: =IF($AY$11=0,"",AY18/$AY$11) -> -0.01744186
B19: NILF – want a job now (000s) | C19: {=INDEX(Macrobond!$IV:$IV,Engine!B$9)/1000} -> 6008 | D19: {=INDEX(Macrobond!$IV:$IV,Engine!C$9)/1000} -> 6032 | E19: {=INDEX(Macrobond!$IV:$IV,Engine!D$9)/1000} -> 6186 | F19: {=INDEX(Macrobond!$IV:$IV,Engine!E$9)/1000} -> 6347 | G19: {=INDEX(Macrobond!$IV:$IV,Engine!F$9)/1000} -> 5943 | H19: {=INDEX(Macrobond!$IV:$IV,Engine!G$9)/1000} -> 5943 | I19: {=INDEX(Macrobond!$IV:$IV,Engine!H$9)/1000} -> 6139 | J19: {=INDEX(Macrobond!$IV:$IV,Engine!I$9)/1000} -> 6208 | ... O19: {=INDEX(Macrobond!$IV:$IV,Engine!N$9)/1000} -> 6187 | P19: =$O19-$N19 -> 76 | Q19: =$O19-$L19 -> 213 | R19: =$O19-$C19 -> 179 | AK19: Information | AL19: {=INDEX(Macrobond!$TM:$TM,Engine!B$9)/1000} -> 2864 | AM19: {=INDEX(Macrobond!$TM:$TM,Engine!C$9)/1000} -> 2863 | AN19: {=INDEX(Macrobond!$TM:$TM,Engine!D$9)/1000} -> 2861 | AO19: {=INDEX(Macrobond!$TM:$TM,Engine!E$9)/1000} -> 2860 | AP19: {=INDEX(Macrobond!$TM:$TM,Engine!F$9)/1000} -> 2859 | AQ19: {=INDEX(Macrobond!$TM:$TM,Engine!G$9)/1000} -> 2853 | AR19: {=INDEX(Macrobond!$TM:$TM,Engine!H$9)/1000} -> 2848 | AS19: {=INDEX(Macrobond!$TM:$TM,Engine!I$9)/1000} -> 2842 | ... AX19: {=INDEX(Macrobond!$TM:$TM,Engine!N$9)/1000} -> 2783 | AY19: =AX19-AW19 -> -2 | AZ19: =(AX19-AU19)/3 -> -3 | BA19: =AX19-AL19 -> -81 | BB19: =IF($AY$11=0,"",AY19/$AY$11) -> -0.011627907
AK20: Financial activities | AL20: {=INDEX(Macrobond!$TT:$TT,Engine!B$9)/1000} -> 9211 | AM20: {=INDEX(Macrobond!$TT:$TT,Engine!C$9)/1000} -> 9204 | AN20: {=INDEX(Macrobond!$TT:$TT,Engine!D$9)/1000} -> 9204 | AO20: {=INDEX(Macrobond!$TT:$TT,Engine!E$9)/1000} -> 9185 | AP20: {=INDEX(Macrobond!$TT:$TT,Engine!F$9)/1000} -> 9189 | AQ20: {=INDEX(Macrobond!$TT:$TT,Engine!G$9)/1000} -> 9184 | AR20: {=INDEX(Macrobond!$TT:$TT,Engine!H$9)/1000} -> 9185 | AS20: {=INDEX(Macrobond!$TT:$TT,Engine!I$9)/1000} -> 9186 | ... AX20: {=INDEX(Macrobond!$TT:$TT,Engine!N$9)/1000} -> 9104 | AY20: =AX20-AW20 -> -22 | AZ20: =(AX20-AU20)/3 -> -15 | BA20: =AX20-AL20 -> -107 | BB20: =IF($AY$11=0,"",AY20/$AY$11) -> -0.12790698
B21: 3-digit rounding watch | C21: =TEXT(((ROUND($O$12,1)+0.05)-$O$12)*100,"0.0")&" bp to round UP to "&TEXT(ROUND($O$12,1)+0.1,"0.0")&"%" -> 5.4 bp to round UP to 4.4% | H21: =TEXT(($O$12-(ROUND($O$12,1)-0.05))*100,"0.0")&" bp to round DOWN to "&TEXT(ROUND($O$12,1)-0.1,"0.0")&"%" -> 4.6 bp to round DOWN to 4.2% | AK21: Prof & business svcs | AL21: {=INDEX(Macrobond!$UH:$UH,Engine!B$9)/1000} -> 22450 | AM21: {=INDEX(Macrobond!$UH:$UH,Engine!C$9)/1000} -> 22419 | AN21: {=INDEX(Macrobond!$UH:$UH,Engine!D$9)/1000} -> 22403 | AO21: {=INDEX(Macrobond!$UH:$UH,Engine!E$9)/1000} -> 22375 | AP21: {=INDEX(Macrobond!$UH:$UH,Engine!F$9)/1000} -> 22359 | AQ21: {=INDEX(Macrobond!$UH:$UH,Engine!G$9)/1000} -> 22335 | AR21: {=INDEX(Macrobond!$UH:$UH,Engine!H$9)/1000} -> 22391 | AS21: {=INDEX(Macrobond!$UH:$UH,Engine!I$9)/1000} -> 22372 | ... AX21: {=INDEX(Macrobond!$UH:$UH,Engine!N$9)/1000} -> 22468 | AY21: =AX21-AW21 -> 6 | AZ21: =(AX21-AU21)/3 -> 18.666667 | BA21: =AX21-AL21 -> 18 | BB21: =IF($AY$11=0,"",AY21/$AY$11) -> 0.034883721
AK22: Education & health | AL22: {=INDEX(Macrobond!$VF:$VF,Engine!B$9)/1000} -> 27276 | AM22: {=INDEX(Macrobond!$VF:$VF,Engine!C$9)/1000} -> 27325 | AN22: {=INDEX(Macrobond!$VF:$VF,Engine!D$9)/1000} -> 27412 | AO22: {=INDEX(Macrobond!$VF:$VF,Engine!E$9)/1000} -> 27435 | AP22: {=INDEX(Macrobond!$VF:$VF,Engine!F$9)/1000} -> 27489 | AQ22: {=INDEX(Macrobond!$VF:$VF,Engine!G$9)/1000} -> 27533 | AR22: {=INDEX(Macrobond!$VF:$VF,Engine!H$9)/1000} -> 27589 | AS22: {=INDEX(Macrobond!$VF:$VF,Engine!I$9)/1000} -> 27627 | ... AX22: {=INDEX(Macrobond!$VF:$VF,Engine!N$9)/1000} -> 27886 | AY22: =AX22-AW22 -> 40 | AZ22: =(AX22-AU22)/3 -> 63 | BA22: =AX22-AL22 -> 610 | BB22: =IF($AY$11=0,"",AY22/$AY$11) -> 0.23255814
B23: Labor-force accounting — MoM change (000s) | C23: =Engine!B$10 -> 45778 | D23: =Engine!C$10 -> 45809 | E23: =Engine!D$10 -> 45839 | F23: =Engine!E$10 -> 45870 | G23: =Engine!F$10 -> 45901 | H23: =Engine!G$10 -> 45931 | I23: =Engine!H$10 -> 45962 | J23: =Engine!I$10 -> 45992 | ... O23: =Engine!N$10 -> 46143 | P23: Latest | Q23: 3M avg | R23: 12M sum | AK23: Leisure & hospitality | AL23: {=INDEX(Macrobond!$WB:$WB,Engine!B$9)/1000} -> 16839 | AM23: {=INDEX(Macrobond!$WB:$WB,Engine!C$9)/1000} -> 16837 | AN23: {=INDEX(Macrobond!$WB:$WB,Engine!D$9)/1000} -> 16848 | AO23: {=INDEX(Macrobond!$WB:$WB,Engine!E$9)/1000} -> 16870 | AP23: {=INDEX(Macrobond!$WB:$WB,Engine!F$9)/1000} -> 16907 | AQ23: {=INDEX(Macrobond!$WB:$WB,Engine!G$9)/1000} -> 16948 | AR23: {=INDEX(Macrobond!$WB:$WB,Engine!H$9)/1000} -> 16936 | AS23: {=INDEX(Macrobond!$WB:$WB,Engine!I$9)/1000} -> 16961 | ... AX23: {=INDEX(Macrobond!$WB:$WB,Engine!N$9)/1000} -> 17079 | AY23: =AX23-AW23 -> 70 | AZ23: =(AX23-AU23)/3 -> 48 | BA23: =AX23-AL23 -> 240 | BB23: =IF($AY$11=0,"",AY23/$AY$11) -> 0.40697674
B24: Δ Civilian labor force | C24: {=(INDEX(Macrobond!$IO:$IO,Engine!B$9)-INDEX(Macrobond!$IO:$IO,Engine!B$9-1))/1000} -> -562 | D24: {=(INDEX(Macrobond!$IO:$IO,Engine!C$9)-INDEX(Macrobond!$IO:$IO,Engine!C$9-1))/1000} -> -112 | E24: {=(INDEX(Macrobond!$IO:$IO,Engine!D$9)-INDEX(Macrobond!$IO:$IO,Engine!D$9-1))/1000} -> 32 | F24: {=(INDEX(Macrobond!$IO:$IO,Engine!E$9)-INDEX(Macrobond!$IO:$IO,Engine!E$9-1))/1000} -> 338 | G24: {=(INDEX(Macrobond!$IO:$IO,Engine!F$9)-INDEX(Macrobond!$IO:$IO,Engine!F$9-1))/1000} -> 511 | H24: {=(INDEX(Macrobond!$IO:$IO,Engine!G$9)-INDEX(Macrobond!$IO:$IO,Engine!G$9-1))/1000} -> 0 | I24: {=(INDEX(Macrobond!$IO:$IO,Engine!H$9)-INDEX(Macrobond!$IO:$IO,Engine!H$9-1))/1000} -> 280 | J24: {=(INDEX(Macrobond!$IO:$IO,Engine!I$9)-INDEX(Macrobond!$IO:$IO,Engine!I$9-1))/1000} -> -46 | ... O24: {=(INDEX(Macrobond!$IO:$IO,Engine!N$9)-INDEX(Macrobond!$IO:$IO,Engine!N$9-1))/1000} -> 83 | P24: =$O24 -> 83 | Q24: =AVERAGE($M24:$O24) -> -135 | R24: =SUM($D24:$O24) -> -414 | AK24: Other services | AL24: {=INDEX(Macrobond!$WJ:$WJ,Engine!B$9)/1000} -> 5994 | AM24: {=INDEX(Macrobond!$WJ:$WJ,Engine!C$9)/1000} -> 5984 | AN24: {=INDEX(Macrobond!$WJ:$WJ,Engine!D$9)/1000} -> 5989 | AO24: {=INDEX(Macrobond!$WJ:$WJ,Engine!E$9)/1000} -> 6008 | AP24: {=INDEX(Macrobond!$WJ:$WJ,Engine!F$9)/1000} -> 6005 | AQ24: {=INDEX(Macrobond!$WJ:$WJ,Engine!G$9)/1000} -> 5999 | AR24: {=INDEX(Macrobond!$WJ:$WJ,Engine!H$9)/1000} -> 6015 | AS24: {=INDEX(Macrobond!$WJ:$WJ,Engine!I$9)/1000} -> 6023 | ... AX24: {=INDEX(Macrobond!$WJ:$WJ,Engine!N$9)/1000} -> 6030 | AY24: =AX24-AW24 -> 3 | AZ24: =(AX24-AU24)/3 -> -0.66666667 | BA24: =AX24-AL24 -> 36 | BB24: =IF($AY$11=0,"",AY24/$AY$11) -> 0.01744186
B25: = Δ Employed | C25: {=(INDEX(Macrobond!$IQ:$IQ,Engine!B$9)-INDEX(Macrobond!$IQ:$IQ,Engine!B$9-1))/1000} -> -654 | D25: {=(INDEX(Macrobond!$IQ:$IQ,Engine!C$9)-INDEX(Macrobond!$IQ:$IQ,Engine!C$9-1))/1000} -> 83 | E25: {=(INDEX(Macrobond!$IQ:$IQ,Engine!D$9)-INDEX(Macrobond!$IQ:$IQ,Engine!D$9-1))/1000} -> -187 | F25: {=(INDEX(Macrobond!$IQ:$IQ,Engine!E$9)-INDEX(Macrobond!$IQ:$IQ,Engine!E$9-1))/1000} -> 230 | G25: {=(INDEX(Macrobond!$IQ:$IQ,Engine!F$9)-INDEX(Macrobond!$IQ:$IQ,Engine!F$9-1))/1000} -> 286 | H25: {=(INDEX(Macrobond!$IQ:$IQ,Engine!G$9)-INDEX(Macrobond!$IQ:$IQ,Engine!G$9-1))/1000} -> 0 | I25: {=(INDEX(Macrobond!$IQ:$IQ,Engine!H$9)-INDEX(Macrobond!$IQ:$IQ,Engine!H$9-1))/1000} -> 104 | J25: {=(INDEX(Macrobond!$IQ:$IQ,Engine!I$9)-INDEX(Macrobond!$IQ:$IQ,Engine!I$9-1))/1000} -> 232 | ... O25: {=(INDEX(Macrobond!$IQ:$IQ,Engine!N$9)-INDEX(Macrobond!$IQ:$IQ,Engine!N$9-1))/1000} -> 149 | P25: =$O25 -> 149 | Q25: =AVERAGE($M25:$O25) -> -47 | R25: =SUM($D25:$O25) -> -473 | AK25: Government | AL25: {=INDEX(Macrobond!$WN:$WN,Engine!B$9)/1000} -> 23561 | AM25: {=INDEX(Macrobond!$WN:$WN,Engine!C$9)/1000} -> 23586 | AN25: {=INDEX(Macrobond!$WN:$WN,Engine!D$9)/1000} -> 23585 | AO25: {=INDEX(Macrobond!$WN:$WN,Engine!E$9)/1000} -> 23535 | AP25: {=INDEX(Macrobond!$WN:$WN,Engine!F$9)/1000} -> 23543 | AQ25: {=INDEX(Macrobond!$WN:$WN,Engine!G$9)/1000} -> 23390 | AR25: {=INDEX(Macrobond!$WN:$WN,Engine!H$9)/1000} -> 23359 | AS25: {=INDEX(Macrobond!$WN:$WN,Engine!I$9)/1000} -> 23349 | ... AX25: {=INDEX(Macrobond!$WN:$WN,Engine!N$9)/1000} -> 23387 | AY25: =AX25-AW25 -> 52 | AZ25: =(AX25-AU25)/3 -> 22 | BA25: =AX25-AL25 -> -174 | BB25: =IF($AY$11=0,"",AY25/$AY$11) -> 0.30232558
B26: + Δ Unemployed | C26: {=(INDEX(Macrobond!$IS:$IS,Engine!B$9)-INDEX(Macrobond!$IS:$IS,Engine!B$9-1))/1000} -> 93 | D26: {=(INDEX(Macrobond!$IS:$IS,Engine!C$9)-INDEX(Macrobond!$IS:$IS,Engine!C$9-1))/1000} -> -194 | E26: {=(INDEX(Macrobond!$IS:$IS,Engine!D$9)-INDEX(Macrobond!$IS:$IS,Engine!D$9-1))/1000} -> 218 | F26: {=(INDEX(Macrobond!$IS:$IS,Engine!E$9)-INDEX(Macrobond!$IS:$IS,Engine!E$9-1))/1000} -> 108 | G26: {=(INDEX(Macrobond!$IS:$IS,Engine!F$9)-INDEX(Macrobond!$IS:$IS,Engine!F$9-1))/1000} -> 225 | H26: {=(INDEX(Macrobond!$IS:$IS,Engine!G$9)-INDEX(Macrobond!$IS:$IS,Engine!G$9-1))/1000} -> 0 | I26: {=(INDEX(Macrobond!$IS:$IS,Engine!H$9)-INDEX(Macrobond!$IS:$IS,Engine!H$9-1))/1000} -> 176 | J26: {=(INDEX(Macrobond!$IS:$IS,Engine!I$9)-INDEX(Macrobond!$IS:$IS,Engine!I$9-1))/1000} -> -278 | ... O26: {=(INDEX(Macrobond!$IS:$IS,Engine!N$9)-INDEX(Macrobond!$IS:$IS,Engine!N$9-1))/1000} -> -66 | P26: =$O26 -> -66 | Q26: =AVERAGE($M26:$O26) -> -88 | R26: =SUM($D26:$O26) -> 59
B27: Δ Not in labor force | C27: {=(INDEX(Macrobond!$IU:$IU,Engine!B$9)-INDEX(Macrobond!$IU:$IU,Engine!B$9-1))/1000} -> 750 | D27: {=(INDEX(Macrobond!$IU:$IU,Engine!C$9)-INDEX(Macrobond!$IU:$IU,Engine!C$9-1))/1000} -> 312 | E27: {=(INDEX(Macrobond!$IU:$IU,Engine!D$9)-INDEX(Macrobond!$IU:$IU,Engine!D$9-1))/1000} -> 168 | F27: {=(INDEX(Macrobond!$IU:$IU,Engine!E$9)-INDEX(Macrobond!$IU:$IU,Engine!E$9-1))/1000} -> -122 | G27: {=(INDEX(Macrobond!$IU:$IU,Engine!F$9)-INDEX(Macrobond!$IU:$IU,Engine!F$9-1))/1000} -> -287 | H27: {=(INDEX(Macrobond!$IU:$IU,Engine!G$9)-INDEX(Macrobond!$IU:$IU,Engine!G$9-1))/1000} -> 0 | I27: {=(INDEX(Macrobond!$IU:$IU,Engine!H$9)-INDEX(Macrobond!$IU:$IU,Engine!H$9-1))/1000} -> 128 | J27: {=(INDEX(Macrobond!$IU:$IU,Engine!I$9)-INDEX(Macrobond!$IU:$IU,Engine!I$9-1))/1000} -> 229 | ... O27: {=(INDEX(Macrobond!$IU:$IU,Engine!N$9)-INDEX(Macrobond!$IU:$IU,Engine!N$9-1))/1000} -> 17 | P27: =$O27 -> 17 | Q27: =AVERAGE($M27:$O27) -> 231 | R27: =SUM($D27:$O27) -> 2083 | AK27: Avg weekly hours, SA | AL27: =Engine!B$10 -> 45778 | AM27: =Engine!C$10 -> 45809 | AN27: =Engine!D$10 -> 45839 | AO27: =Engine!E$10 -> 45870 | AP27: =Engine!F$10 -> 45901 | AQ27: =Engine!G$10 -> 45931 | AR27: =Engine!H$10 -> 45962 | AS27: =Engine!I$10 -> 45992 | ... AX27: =Engine!N$10 -> 46143 | AY27: MoM | AZ27: 3M | BA27: YoY
B28: check: ΔLF − (ΔEmp+ΔUnemp) | C28: =$C24-($C25+$C26) -> -1 | D28: =$C24-($C25+$C26) -> -1 | E28: =$C24-($C25+$C26) -> -1 | F28: =$C24-($C25+$C26) -> -1 | G28: =$C24-($C25+$C26) -> -1 | H28: =$C24-($C25+$C26) -> -1 | I28: =$C24-($C25+$C26) -> -1 | J28: =$C24-($C25+$C26) -> -1 | ... O28: =$C24-($C25+$C26) -> -1 | AK28: Total private | AL28: {=INDEX(Macrobond!$GZ:$GZ,Engine!B$9)} -> 34.2 | AM28: {=INDEX(Macrobond!$GZ:$GZ,Engine!C$9)} -> 34.2 | AN28: {=INDEX(Macrobond!$GZ:$GZ,Engine!D$9)} -> 34.2 | AO28: {=INDEX(Macrobond!$GZ:$GZ,Engine!E$9)} -> 34.2 | AP28: {=INDEX(Macrobond!$GZ:$GZ,Engine!F$9)} -> 34.2 | AQ28: {=INDEX(Macrobond!$GZ:$GZ,Engine!G$9)} -> 34.2 | AR28: {=INDEX(Macrobond!$GZ:$GZ,Engine!H$9)} -> 34.3 | AS28: {=INDEX(Macrobond!$GZ:$GZ,Engine!I$9)} -> 34.2 | ... AX28: {=INDEX(Macrobond!$GZ:$GZ,Engine!N$9)} -> 34.3 | AY28: =AX28-AW28 -> 0 | AZ28: =AX28-AU28 -> 0 | BA28: =AX28-AL28 -> 0.1
AK29: Goods-producing | AL29: {=INDEX(Macrobond!$HA:$HA,Engine!B$9)} -> 39.8 | AM29: {=INDEX(Macrobond!$HA:$HA,Engine!C$9)} -> 39.8 | AN29: {=INDEX(Macrobond!$HA:$HA,Engine!D$9)} -> 39.9 | AO29: {=INDEX(Macrobond!$HA:$HA,Engine!E$9)} -> 39.7 | AP29: {=INDEX(Macrobond!$HA:$HA,Engine!F$9)} -> 39.7 | AQ29: {=INDEX(Macrobond!$HA:$HA,Engine!G$9)} -> 39.7 | AR29: {=INDEX(Macrobond!$HA:$HA,Engine!H$9)} -> 39.9 | AS29: {=INDEX(Macrobond!$HA:$HA,Engine!I$9)} -> 39.7 | ... AX29: {=INDEX(Macrobond!$HA:$HA,Engine!N$9)} -> 40.1 | AY29: =AX29-AW29 -> 0 | AZ29: =AX29-AU29 -> 0 | BA29: =AX29-AL29 -> 0.3
B30: Unemployment by reason (000s) — mix shift at right | C30: =Engine!B$10 -> 45778 | D30: =Engine!C$10 -> 45809 | E30: =Engine!D$10 -> 45839 | F30: =Engine!E$10 -> 45870 | G30: =Engine!F$10 -> 45901 | H30: =Engine!G$10 -> 45931 | I30: =Engine!H$10 -> 45962 | J30: =Engine!I$10 -> 45992 | ... O30: =Engine!N$10 -> 46143 | P30: Share now | Q30: Share 3M ago | R30: Share 12M ago | AK30: Manufacturing | AL30: {=INDEX(Macrobond!$HD:$HD,Engine!B$9)} -> 40.1 | AM30: {=INDEX(Macrobond!$HD:$HD,Engine!C$9)} -> 40.1 | AN30: {=INDEX(Macrobond!$HD:$HD,Engine!D$9)} -> 40.2 | AO30: {=INDEX(Macrobond!$HD:$HD,Engine!E$9)} -> 40 | AP30: {=INDEX(Macrobond!$HD:$HD,Engine!F$9)} -> 40 | AQ30: {=INDEX(Macrobond!$HD:$HD,Engine!G$9)} -> 40 | AR30: {=INDEX(Macrobond!$HD:$HD,Engine!H$9)} -> 40.1 | AS30: {=INDEX(Macrobond!$HD:$HD,Engine!I$9)} -> 40 | ... AX30: {=INDEX(Macrobond!$HD:$HD,Engine!N$9)} -> 40.4 | AY30: =AX30-AW30 -> 0 | AZ30: =AX30-AU30 -> 0.2 | BA30: =AX30-AL30 -> 0.3
B31: Permanent job losers | C31: {=INDEX(Macrobond!$G:$G,Engine!B$9)/1000} -> 1913 | D31: {=INDEX(Macrobond!$G:$G,Engine!C$9)/1000} -> 1892 | E31: {=INDEX(Macrobond!$G:$G,Engine!D$9)/1000} -> 1894 | F31: {=INDEX(Macrobond!$G:$G,Engine!E$9)/1000} -> 1931 | G31: {=INDEX(Macrobond!$G:$G,Engine!F$9)/1000} -> 2012 | H31: {=INDEX(Macrobond!$G:$G,Engine!G$9)/1000} -> 2012 | I31: {=INDEX(Macrobond!$G:$G,Engine!H$9)/1000} -> 1936 | J31: {=INDEX(Macrobond!$G:$G,Engine!I$9)/1000} -> 1969 | ... O31: {=INDEX(Macrobond!$G:$G,Engine!N$9)/1000} -> 1927 | P31: =$O31/$O$37 -> 0.26371972 | Q31: =$L31/$L$37 -> 0.26905297 | R31: =$C31/$C$37 -> 0.26393488 | AK31: Trade, transp & util | AL31: {=INDEX(Macrobond!$HH:$HH,Engine!B$9)} -> 34 | AM31: {=INDEX(Macrobond!$HH:$HH,Engine!C$9)} -> 34 | AN31: {=INDEX(Macrobond!$HH:$HH,Engine!D$9)} -> 34.1 | AO31: {=INDEX(Macrobond!$HH:$HH,Engine!E$9)} -> 34.1 | AP31: {=INDEX(Macrobond!$HH:$HH,Engine!F$9)} -> 34 | AQ31: {=INDEX(Macrobond!$HH:$HH,Engine!G$9)} -> 34.1 | AR31: {=INDEX(Macrobond!$HH:$HH,Engine!H$9)} -> 34 | AS31: {=INDEX(Macrobond!$HH:$HH,Engine!I$9)} -> 34 | ... AX31: {=INDEX(Macrobond!$HH:$HH,Engine!N$9)} -> 34.2 | AY31: =AX31-AW31 -> 0.1 | AZ31: =AX31-AU31 -> 0.1 | BA31: =AX31-AL31 -> 0.2
B32: Job losers on temporary layoff | C32: {=INDEX(Macrobond!$D:$D,Engine!B$9)/1000} -> 879 | D32: {=INDEX(Macrobond!$D:$D,Engine!C$9)/1000} -> 867 | E32: {=INDEX(Macrobond!$D:$D,Engine!D$9)/1000} -> 940 | F32: {=INDEX(Macrobond!$D:$D,Engine!E$9)/1000} -> 890 | G32: {=INDEX(Macrobond!$D:$D,Engine!F$9)/1000} -> 844 | H32: {=INDEX(Macrobond!$D:$D,Engine!G$9)/1000} -> 844 | I32: {=INDEX(Macrobond!$D:$D,Engine!H$9)/1000} -> 1002 | J32: {=INDEX(Macrobond!$D:$D,Engine!I$9)/1000} -> 929 | ... O32: {=INDEX(Macrobond!$D:$D,Engine!N$9)/1000} -> 778 | P32: =$O32/$O$37 -> 0.10647324 | Q32: =$L32/$L$37 -> 0.12217673 | R32: =$C32/$C$37 -> 0.12127483 | AK32: Prof & business svcs | AL32: {=INDEX(Macrobond!$HO:$HO,Engine!B$9)} -> 36.5 | AM32: {=INDEX(Macrobond!$HO:$HO,Engine!C$9)} -> 36.4 | AN32: {=INDEX(Macrobond!$HO:$HO,Engine!D$9)} -> 36.4 | AO32: {=INDEX(Macrobond!$HO:$HO,Engine!E$9)} -> 36.5 | AP32: {=INDEX(Macrobond!$HO:$HO,Engine!F$9)} -> 36.5 | AQ32: {=INDEX(Macrobond!$HO:$HO,Engine!G$9)} -> 36.6 | AR32: {=INDEX(Macrobond!$HO:$HO,Engine!H$9)} -> 36.6 | AS32: {=INDEX(Macrobond!$HO:$HO,Engine!I$9)} -> 36.5 | ... AX32: {=INDEX(Macrobond!$HO:$HO,Engine!N$9)} -> 36.7 | AY32: =AX32-AW32 -> 0.1 | AZ32: =AX32-AU32 -> 0.1 | BA32: =AX32-AL32 -> 0.2
B33: Persons who completed temp jobs | C33: {=INDEX(Macrobond!$H:$H,Engine!B$9)/1000} -> 666 | D33: {=INDEX(Macrobond!$H:$H,Engine!C$9)/1000} -> 546 | E33: {=INDEX(Macrobond!$H:$H,Engine!D$9)/1000} -> 578 | F33: {=INDEX(Macrobond!$H:$H,Engine!E$9)/1000} -> 627 | G33: {=INDEX(Macrobond!$H:$H,Engine!F$9)/1000} -> 668 | H33: {=INDEX(Macrobond!$H:$H,Engine!G$9)/1000} -> 668 | I33: {=INDEX(Macrobond!$H:$H,Engine!H$9)/1000} -> 623 | J33: {=INDEX(Macrobond!$H:$H,Engine!I$9)/1000} -> 575 | ... O33: {=INDEX(Macrobond!$H:$H,Engine!N$9)/1000} -> 680 | P33: =$O33/$O$37 -> 0.093061448 | Q33: =$L33/$L$37 -> 0.08691058 | R33: =$C33/$C$37 -> 0.091887417 | AK33: Leisure & hospitality | AL33: {=INDEX(Macrobond!$HQ:$HQ,Engine!B$9)} -> 25.6 | AM33: {=INDEX(Macrobond!$HQ:$HQ,Engine!C$9)} -> 25.5 | AN33: {=INDEX(Macrobond!$HQ:$HQ,Engine!D$9)} -> 25.5 | AO33: {=INDEX(Macrobond!$HQ:$HQ,Engine!E$9)} -> 25.5 | AP33: {=INDEX(Macrobond!$HQ:$HQ,Engine!F$9)} -> 25.5 | AQ33: {=INDEX(Macrobond!$HQ:$HQ,Engine!G$9)} -> 25.6 | AR33: {=INDEX(Macrobond!$HQ:$HQ,Engine!H$9)} -> 25.6 | AS33: {=INDEX(Macrobond!$HQ:$HQ,Engine!I$9)} -> 25.6 | ... AX33: {=INDEX(Macrobond!$HQ:$HQ,Engine!N$9)} -> 25.4 | AY33: =AX33-AW33 -> -0.1 | AZ33: =AX33-AU33 -> -0.1 | BA33: =AX33-AL33 -> -0.2
B34: Job leavers | C34: {=INDEX(Macrobond!$I:$I,Engine!B$9)/1000} -> 706 | D34: {=INDEX(Macrobond!$I:$I,Engine!C$9)/1000} -> 825 | E34: {=INDEX(Macrobond!$I:$I,Engine!D$9)/1000} -> 785 | F34: {=INDEX(Macrobond!$I:$I,Engine!E$9)/1000} -> 785 | G34: {=INDEX(Macrobond!$I:$I,Engine!F$9)/1000} -> 860 | H34: {=INDEX(Macrobond!$I:$I,Engine!G$9)/1000} -> 860 | I34: {=INDEX(Macrobond!$I:$I,Engine!H$9)/1000} -> 861 | J34: {=INDEX(Macrobond!$I:$I,Engine!I$9)/1000} -> 832 | ... O34: {=INDEX(Macrobond!$I:$I,Engine!N$9)/1000} -> 916 | P34: =$O34/$O$37 -> 0.12535924 | Q34: =$L34/$L$37 -> 0.11451592 | R34: =$C34/$C$37 -> 0.097406181
B35: Reentrants | C35: {=INDEX(Macrobond!$J:$J,Engine!B$9)/1000} -> 2291 | D35: {=INDEX(Macrobond!$J:$J,Engine!C$9)/1000} -> 2160 | E35: {=INDEX(Macrobond!$J:$J,Engine!D$9)/1000} -> 2199 | F35: {=INDEX(Macrobond!$J:$J,Engine!E$9)/1000} -> 2302 | G35: {=INDEX(Macrobond!$J:$J,Engine!F$9)/1000} -> 2336 | H35: {=INDEX(Macrobond!$J:$J,Engine!G$9)/1000} -> 2336 | I35: {=INDEX(Macrobond!$J:$J,Engine!H$9)/1000} -> 2600 | J35: {=INDEX(Macrobond!$J:$J,Engine!I$9)/1000} -> 2337 | ... O35: {=INDEX(Macrobond!$J:$J,Engine!N$9)/1000} -> 2209 | P35: =$O35/$O$37 -> 0.30231285 | Q35: =$L35/$L$37 -> 0.30643244 | R35: =$C35/$C$37 -> 0.3160872 | AK35: Avg weekly earnings, SA (USD) | AL35: =Engine!B$10 -> 45778 | AM35: =Engine!C$10 -> 45809 | AN35: =Engine!D$10 -> 45839 | AO35: =Engine!E$10 -> 45870 | AP35: =Engine!F$10 -> 45901 | AQ35: =Engine!G$10 -> 45931 | AR35: =Engine!H$10 -> 45962 | AS35: =Engine!I$10 -> 45992 | ... AX35: =Engine!N$10 -> 46143 | AY35: MoM% | AZ35: 3M% | BA35: YoY%
B36: New entrants | C36: {=INDEX(Macrobond!$K:$K,Engine!B$9)/1000} -> 734 | D36: {=INDEX(Macrobond!$K:$K,Engine!C$9)/1000} -> 723 | E36: {=INDEX(Macrobond!$K:$K,Engine!D$9)/1000} -> 982 | F36: {=INDEX(Macrobond!$K:$K,Engine!E$9)/1000} -> 792 | G36: {=INDEX(Macrobond!$K:$K,Engine!F$9)/1000} -> 813 | H36: {=INDEX(Macrobond!$K:$K,Engine!G$9)/1000} -> 813 | I36: {=INDEX(Macrobond!$K:$K,Engine!H$9)/1000} -> 774 | J36: {=INDEX(Macrobond!$K:$K,Engine!I$9)/1000} -> 840 | ... O36: {=INDEX(Macrobond!$K:$K,Engine!N$9)/1000} -> 818 | P36: =$O36/$O$37 -> 0.11194745 | Q36: =$L36/$L$37 -> 0.10632677 | R36: =$C36/$C$37 -> 0.10126932 | AK36: Total private | AL36: {=INDEX(Macrobond!$HV:$HV,Engine!B$9)} -> 1240.78 | AM36: {=INDEX(Macrobond!$HV:$HV,Engine!C$9)} -> 1243.51 | AN36: {=INDEX(Macrobond!$HV:$HV,Engine!D$9)} -> 1247.27 | AO36: {=INDEX(Macrobond!$HV:$HV,Engine!E$9)} -> 1252.4 | AP36: {=INDEX(Macrobond!$HV:$HV,Engine!F$9)} -> 1255.14 | AQ36: {=INDEX(Macrobond!$HV:$HV,Engine!G$9)} -> 1260.27 | AR36: {=INDEX(Macrobond!$HV:$HV,Engine!H$9)} -> 1269.1 | AS36: {=INDEX(Macrobond!$HV:$HV,Engine!I$9)} -> 1266.08 | ... AX36: {=INDEX(Macrobond!$HV:$HV,Engine!N$9)} -> 1287.28 | AY36: =AX36/AW36-1 -> 0.0032108233 | AZ36: =AX36/AU36-1 -> 0.0069776902 | BA36: =AX36/AL36-1 -> 0.037476426
B37: Total unemployed (memo) | C37: {=INDEX(Macrobond!$IS:$IS,Engine!B$9)/1000} -> 7248 | D37: {=INDEX(Macrobond!$IS:$IS,Engine!C$9)/1000} -> 7054 | E37: {=INDEX(Macrobond!$IS:$IS,Engine!D$9)/1000} -> 7272 | F37: {=INDEX(Macrobond!$IS:$IS,Engine!E$9)/1000} -> 7380 | G37: {=INDEX(Macrobond!$IS:$IS,Engine!F$9)/1000} -> 7605 | H37: {=INDEX(Macrobond!$IS:$IS,Engine!G$9)/1000} -> 7605 | I37: {=INDEX(Macrobond!$IS:$IS,Engine!H$9)/1000} -> 7781 | J37: {=INDEX(Macrobond!$IS:$IS,Engine!I$9)/1000} -> 7503 | ... O37: {=INDEX(Macrobond!$IS:$IS,Engine!N$9)/1000} -> 7307 | P37: =$O37/$O$37 -> 1 | Q37: =$L37/$L$37 -> 1 | R37: =$C37/$C$37 -> 1 | AK37: Goods-producing | AL37: {=INDEX(Macrobond!$HW:$HW,Engine!B$9)} -> 1473.79 | AM37: {=INDEX(Macrobond!$HW:$HW,Engine!C$9)} -> 1477.77 | AN37: {=INDEX(Macrobond!$HW:$HW,Engine!D$9)} -> 1486.28 | AO37: {=INDEX(Macrobond!$HW:$HW,Engine!E$9)} -> 1484.38 | AP37: {=INDEX(Macrobond!$HW:$HW,Engine!F$9)} -> 1487.56 | AQ37: {=INDEX(Macrobond!$HW:$HW,Engine!G$9)} -> 1493.91 | AR37: {=INDEX(Macrobond!$HW:$HW,Engine!H$9)} -> 1506.62 | AS37: {=INDEX(Macrobond!$HW:$HW,Engine!I$9)} -> 1503.44 | ... AX37: {=INDEX(Macrobond!$HW:$HW,Engine!N$9)} -> 1546.66 | AY37: =AX37/AW37-1 -> 0.0028594586 | AZ37: =AX37/AU37-1 -> 0.010479414 | BA37: =AX37/AL37-1 -> 0.049443951
AK38: Manufacturing | AL38: {=INDEX(Macrobond!$HZ:$HZ,Engine!B$9)} -> 1415.93 | AM38: {=INDEX(Macrobond!$HZ:$HZ,Engine!C$9)} -> 1418.34 | AN38: {=INDEX(Macrobond!$HZ:$HZ,Engine!D$9)} -> 1427.5 | AO38: {=INDEX(Macrobond!$HZ:$HZ,Engine!E$9)} -> 1423.2 | AP38: {=INDEX(Macrobond!$HZ:$HZ,Engine!F$9)} -> 1428 | AQ38: {=INDEX(Macrobond!$HZ:$HZ,Engine!G$9)} -> 1434.8 | AR38: {=INDEX(Macrobond!$HZ:$HZ,Engine!H$9)} -> 1443.2 | AS38: {=INDEX(Macrobond!$HZ:$HZ,Engine!I$9)} -> 1443.2 | ... AX38: {=INDEX(Macrobond!$HZ:$HZ,Engine!N$9)} -> 1483.08 | AY38: =AX38/AW38-1 -> 0.001363888 | AZ38: =AX38/AU38-1 -> 0.013808378 | BA38: =AX38/AL38-1 -> 0.047424661
B39: Duration of unemployment | C39: =Engine!B$10 -> 45778 | D39: =Engine!C$10 -> 45809 | E39: =Engine!D$10 -> 45839 | F39: =Engine!E$10 -> 45870 | G39: =Engine!F$10 -> 45901 | H39: =Engine!G$10 -> 45931 | I39: =Engine!H$10 -> 45962 | J39: =Engine!I$10 -> 45992 | ... O39: =Engine!N$10 -> 46143 | P39: MoM | Q39: 3M | R39: YoY | AK39: Trade, transp & util | AL39: {=INDEX(Macrobond!$ID:$ID,Engine!B$9)} -> 1047.88 | AM39: {=INDEX(Macrobond!$ID:$ID,Engine!C$9)} -> 1049.24 | AN39: {=INDEX(Macrobond!$ID:$ID,Engine!D$9)} -> 1057.1 | AO39: {=INDEX(Macrobond!$ID:$ID,Engine!E$9)} -> 1060.51 | AP39: {=INDEX(Macrobond!$ID:$ID,Engine!F$9)} -> 1060.46 | AQ39: {=INDEX(Macrobond!$ID:$ID,Engine!G$9)} -> 1067.67 | AR39: {=INDEX(Macrobond!$ID:$ID,Engine!H$9)} -> 1070.32 | AS39: {=INDEX(Macrobond!$ID:$ID,Engine!I$9)} -> 1073.04 | ... AX39: {=INDEX(Macrobond!$ID:$ID,Engine!N$9)} -> 1091.66 | AY39: =AX39/AW39-1 -> 0.0051284884 | AZ39: =AX39/AU39-1 -> 0.008937236 | BA39: =AX39/AL39-1 -> 0.041779593
B40: Mean duration (weeks) | C40: {=INDEX(Macrobond!$AA:$AA,Engine!B$9)} -> 21.9 | D40: {=INDEX(Macrobond!$AA:$AA,Engine!C$9)} -> 23.1 | E40: {=INDEX(Macrobond!$AA:$AA,Engine!D$9)} -> 24 | F40: {=INDEX(Macrobond!$AA:$AA,Engine!E$9)} -> 24.5 | G40: {=INDEX(Macrobond!$AA:$AA,Engine!F$9)} -> 24.1 | H40: {=INDEX(Macrobond!$AA:$AA,Engine!G$9)} -> 24.1 | I40: {=INDEX(Macrobond!$AA:$AA,Engine!H$9)} -> 23.1 | J40: {=INDEX(Macrobond!$AA:$AA,Engine!I$9)} -> 24.4 | ... O40: {=INDEX(Macrobond!$AA:$AA,Engine!N$9)} -> 26 | P40: =$O40-$N40 -> 1.6 | Q40: =$O40-$L40 -> 0.3 | R40: =$O40-$C40 -> 4.1 | AK40: Prof & business svcs | AL40: {=INDEX(Macrobond!$IK:$IK,Engine!B$9)} -> 1606 | AM40: {=INDEX(Macrobond!$IK:$IK,Engine!C$9)} -> 1609.24 | AN40: {=INDEX(Macrobond!$IK:$IK,Engine!D$9)} -> 1616.16 | AO40: {=INDEX(Macrobond!$IK:$IK,Engine!E$9)} -> 1628.63 | AP40: {=INDEX(Macrobond!$IK:$IK,Engine!F$9)} -> 1633.01 | AQ40: {=INDEX(Macrobond!$IK:$IK,Engine!G$9)} -> 1643.34 | AR40: {=INDEX(Macrobond!$IK:$IK,Engine!H$9)} -> 1644.07 | AS40: {=INDEX(Macrobond!$IK:$IK,Engine!I$9)} -> 1641.04 | ... AX40: {=INDEX(Macrobond!$IK:$IK,Engine!N$9)} -> 1672.79 | AY40: =AX40/AW40-1 -> 0.0062681593 | AZ40: =AX40/AU40-1 -> 0.010718709 | BA40: =AX40/AL40-1 -> 0.041587796
B41: Median duration (weeks) | C41: {=INDEX(Macrobond!$AB:$AB,Engine!B$9)} -> 9.5 | D41: {=INDEX(Macrobond!$AB:$AB,Engine!C$9)} -> 10.1 | E41: {=INDEX(Macrobond!$AB:$AB,Engine!D$9)} -> 10.2 | F41: {=INDEX(Macrobond!$AB:$AB,Engine!E$9)} -> 9.9 | G41: {=INDEX(Macrobond!$AB:$AB,Engine!F$9)} -> 10.1 | H41: {=INDEX(Macrobond!$AB:$AB,Engine!G$9)} -> 10.1 | I41: {=INDEX(Macrobond!$AB:$AB,Engine!H$9)} -> 9.8 | J41: {=INDEX(Macrobond!$AB:$AB,Engine!I$9)} -> 11.4 | ... O41: {=INDEX(Macrobond!$AB:$AB,Engine!N$9)} -> 11.6 | P41: =$O41-$N41 -> 0.6 | Q41: =$O41-$L41 -> 0.5 | R41: =$O41-$C41 -> 2.1 | AK41: Leisure & hospitality | AL41: {=INDEX(Macrobond!$IM:$IM,Engine!B$9)} -> 580.61 | AM41: {=INDEX(Macrobond!$IM:$IM,Engine!C$9)} -> 579.87 | AN41: {=INDEX(Macrobond!$IM:$IM,Engine!D$9)} -> 581.66 | AO41: {=INDEX(Macrobond!$IM:$IM,Engine!E$9)} -> 584.46 | AP41: {=INDEX(Macrobond!$IM:$IM,Engine!F$9)} -> 586.5 | AQ41: {=INDEX(Macrobond!$IM:$IM,Engine!G$9)} -> 589.06 | AR41: {=INDEX(Macrobond!$IM:$IM,Engine!H$9)} -> 593.15 | AS41: {=INDEX(Macrobond!$IM:$IM,Engine!I$9)} -> 595.2 | ... AX41: {=INDEX(Macrobond!$IM:$IM,Engine!N$9)} -> 598.93 | AY41: =AX41/AW41-1 -> -0.0013838869 | AZ41: =AX41/AU41-1 -> 0.0037372214 | BA41: =AX41/AL41-1 -> 0.031553022
...

Sheet Macrobond
C4: United States
