Workbook
Name Ann3_Core: OFFSET('Calc Engine'!$AV$6,PPI_N-24,0,24,1)
Name Ann3_Headline: OFFSET('Calc Engine'!$AS$6,PPI_N-24,0,24,1)
Name Ann6_Core: OFFSET('Calc Engine'!$BJ$6,PPI_N-24,0,24,1)
Name Ann6_Headline: OFFSET('Calc Engine'!$BG$6,PPI_N-24,0,24,1)
Name ChartDates: OFFSET('Calc Engine'!$P$6,PPI_N-24,0,24,1)
Name Macrobond_Object1: 'Macrobond Imports'!$A$3:$GW$953
Name MM_Core: OFFSET('Calc Engine'!$T$6,PPI_N-24,0,24,1)
Name MM_Headline: OFFSET('Calc Engine'!$Q$6,PPI_N-24,0,24,1)
Name PPI_N: COUNT('Calc Engine'!$A$6:$A$960)
Name Transport_YY: OFFSET('Calc Engine'!$CB$6,PPI_N-24,0,24,1)
Name UnprocEnergy_YY: OFFSET('Calc Engine'!$CA$6,PPI_N-24,0,24,1)
Name YY_Core: OFFSET('Calc Engine'!$AH$6,PPI_N-24,0,24,1)
Name YY_Headline: OFFSET('Calc Engine'!$AE$6,PPI_N-24,0,24,1)

Sheet Dashboard
A1: US PPI — MORNING DASHBOARD | J1: Latest data: | L1: {=INDEX('Calc Engine'!A6:A960,PPI_N)} -> 46113
A2: Final Demand – Intermediate Demand (FD-ID) system | Source: BLS via Macrobond | Auto-refresh on import
A4: HEADLINE READ — latest month | J4: MOMENTUM & BASE EFFECTS
A5: Series | B5: Index | C5: M/M | D5: Y/Y | E5: 3m ann. | F5: 6m ann. | G5: Prior M/M | H5: Momentum | J5: Series | K5: M/M | L5: 3m ann. | M5: 6m ann. | N5: Y/Y | O5: 3m vs 6m
A6: Headline Final Demand | B6: {=INDEX('Calc Engine'!B:B,PPI_N+5)} -> 156.496 | C6: {=INDEX('Calc Engine'!Q:Q,PPI_N+5)} -> 0.013758972 | D6: {=INDEX('Calc Engine'!AE:AE,PPI_N+5)} -> 0.059876062 | E6: {=INDEX('Calc Engine'!AS:AS,PPI_N+5)} -> 0.110898 | F6: {=INDEX('Calc Engine'!BG:BG,PPI_N+5)} -> 0.082145374 | G6: {=INDEX('Calc Engine'!Q:Q,PPI_N+4)} -> 0.0069928245 | H6: =IF(OR(E6="",F6=""),"",IF(E6>F6,"▲ ACCEL","▼ decel")) -> ▲ ACCEL | J6: Headline FD | K6: =C6 -> 0.013758972 | L6: =E6 -> 0.110898 | M6: =F6 -> 0.082145374 | N6: =D6 -> 0.059876062 | O6: =IF(OR(L6="",M6=""),"",IF(L6>M6,"▲ ACCEL","▼ decel")) -> ▲ ACCEL
A7: Core FD (ex Food & Energy) | B7: {=INDEX('Calc Engine'!E:E,PPI_N+5)} -> 154.056 | C7: {=INDEX('Calc Engine'!T:T,PPI_N+5)} -> 0.010329156 | D7: {=INDEX('Calc Engine'!AH:AH,PPI_N+5)} -> 0.05240291 | E7: {=INDEX('Calc Engine'!AV:AV,PPI_N+5)} -> 0.067041328 | F7: {=INDEX('Calc Engine'!BJ:BJ,PPI_N+5)} -> 0.065881647 | G7: {=INDEX('Calc Engine'!T:T,PPI_N+4)} -> 0.0022742959 | H7: =IF(OR(E7="",F7=""),"",IF(E7>F7,"▲ ACCEL","▼ decel")) -> ▲ ACCEL | J7: Core (ex F&E) | K7: =C7 -> 0.010329156 | L7: =E7 -> 0.067041328 | M7: =F7 -> 0.065881647 | N7: =D7 -> 0.05240291 | O7: =IF(OR(L7="",M7=""),"",IF(L7>M7,"▲ ACCEL","▼ decel")) -> ▲ ACCEL
A8: FD ex Food | B8: {=INDEX('Calc Engine'!F:F,PPI_N+5)} -> 153.992 | C8: {=INDEX('Calc Engine'!U:U,PPI_N+5)} -> 0.014413322 | D8: {=INDEX('Calc Engine'!AI:AI,PPI_N+5)} -> 0.061984497 | E8: {=INDEX('Calc Engine'!AW:AW,PPI_N+5)} -> 0.11276566 | F8: {=INDEX('Calc Engine'!BK:BK,PPI_N+5)} -> 0.086558325 | G8: {=INDEX('Calc Engine'!U:U,PPI_N+4)} -> 0.0077537906 | H8: =IF(OR(E8="",F8=""),"",IF(E8>F8,"▲ ACCEL","▼ decel")) -> ▲ ACCEL | J8: FD ex Food, Energy & Trade | K8: =C11 -> 0.0056604983 | L8: =E11 -> 0.052884395 | M8: =F11 -> 0.044492549 | N8: =D11 -> 0.044357194 | O8: =IF(OR(L8="",M8=""),"",IF(L8>M8,"▲ ACCEL","▼ decel")) -> ▲ ACCEL
A9: FD ex Energy | B9: {=INDEX('Calc Engine'!G:G,PPI_N+5)} -> 154.102 | C9: {=INDEX('Calc Engine'!V:V,PPI_N+5)} -> 0.0098691971 | D9: {=INDEX('Calc Engine'!AJ:AJ,PPI_N+5)} -> 0.050736051 | E9: {=INDEX('Calc Engine'!AX:AX,PPI_N+5)} -> 0.067696342 | F9: {=INDEX('Calc Engine'!BL:BL,PPI_N+5)} -> 0.062455932 | G9: {=INDEX('Calc Engine'!V:V,PPI_N+4)} -> 0.0017922441 | H9: =IF(OR(E9="",F9=""),"",IF(E9>F9,"▲ ACCEL","▼ decel")) -> ▲ ACCEL | J9: FD Goods | K9: =C12 -> 0.019600916 | L9: =E12 -> 0.21435262 | M9: =F12 -> 0.1145686 | N9: =D12 -> 0.073903846 | O9: =IF(OR(L9="",M9=""),"",IF(L9>M9,"▲ ACCEL","▼ decel")) -> ▲ ACCEL
A10: FD ex Trade Services | B10: {=INDEX('Calc Engine'!H:H,PPI_N+5)} -> 151.521 | C10: {=INDEX('Calc Engine'!W:W,PPI_N+5)} -> 0.010577917 | D10: {=INDEX('Calc Engine'!AK:AK,PPI_N+5)} -> 0.05473416 | E10: {=INDEX('Calc Engine'!AY:AY,PPI_N+5)} -> 0.10915644 | F10: {=INDEX('Calc Engine'!BM:BM,PPI_N+5)} -> 0.067358836 | G10: {=INDEX('Calc Engine'!W:W,PPI_N+4)} -> 0.0080341536 | H10: =IF(OR(E10="",F10=""),"",IF(E10>F10,"▲ ACCEL","▼ decel")) -> ▲ ACCEL | J10: FD Services | K10: =C13 -> 0.011797935 | L10: =E13 -> 0.073285997 | M10: =F13 -> 0.070819385 | N10: =D13 -> 0.054866574 | O10: =IF(OR(L10="",M10=""),"",IF(L10>M10,"▲ ACCEL","▼ decel")) -> ▲ ACCEL
A11: FD ex Food, Energy & Trade | B11: {=INDEX('Calc Engine'!I:I,PPI_N+5)} -> 141.242 | C11: {=INDEX('Calc Engine'!X:X,PPI_N+5)} -> 0.0056604983 | D11: {=INDEX('Calc Engine'!AL:AL,PPI_N+5)} -> 0.044357194 | E11: {=INDEX('Calc Engine'!AZ:AZ,PPI_N+5)} -> 0.052884395 | F11: {=INDEX('Calc Engine'!BN:BN,PPI_N+5)} -> 0.044492549 | G11: {=INDEX('Calc Engine'!X:X,PPI_N+4)} -> 0.0021334589 | H11: =IF(OR(E11="",F11=""),"",IF(E11>F11,"▲ ACCEL","▼ decel")) -> ▲ ACCEL
A12: FD Goods | B12: {=INDEX('Calc Engine'!C:C,PPI_N+5)} -> 155.846 | C12: {=INDEX('Calc Engine'!R:R,PPI_N+5)} -> 0.019600916 | D12: {=INDEX('Calc Engine'!AF:AF,PPI_N+5)} -> 0.073903846 | E12: {=INDEX('Calc Engine'!AT:AT,PPI_N+5)} -> 0.21435262 | F12: {=INDEX('Calc Engine'!BH:BH,PPI_N+5)} -> 0.1145686 | G12: {=INDEX('Calc Engine'!R:R,PPI_N+4)} -> 0.019027174 | H12: =IF(OR(E12="",F12=""),"",IF(E12>F12,"▲ ACCEL","▼ decel")) -> ▲ ACCEL
A13: FD Services | B13: {=INDEX('Calc Engine'!D:D,PPI_N+5)} -> 155.827 | C13: {=INDEX('Calc Engine'!S:S,PPI_N+5)} -> 0.011797935 | D13: {=INDEX('Calc Engine'!AG:AG,PPI_N+5)} -> 0.054866574 | E13: {=INDEX('Calc Engine'!AU:AU,PPI_N+5)} -> 0.073285997 | F13: {=INDEX('Calc Engine'!BI:BI,PPI_N+5)} -> 0.070819385 | G13: {=INDEX('Calc Engine'!S:S,PPI_N+4)} -> 0.0020886335 | H13: =IF(OR(E13="",F13=""),"",IF(E13>F13,"▲ ACCEL","▼ decel")) -> ▲ ACCEL
A14: FD Trade Services | B14: {=INDEX('Calc Engine'!J:J,PPI_N+5)} -> 170.285 | C14: {=INDEX('Calc Engine'!Y:Y,PPI_N+5)} -> 0.026771986 | D14: {=INDEX('Calc Engine'!AM:AM,PPI_N+5)} -> 0.081181468 | E14: {=INDEX('Calc Engine'!BA:BA,PPI_N+5)} -> 0.11781475 | F14: {=INDEX('Calc Engine'!BO:BO,PPI_N+5)} -> 0.14522898 | G14: {=INDEX('Calc Engine'!Y:Y,PPI_N+4)} -> 0.0027753256 | H14: =IF(OR(E14="",F14=""),"",IF(E14>F14,"▲ ACCEL","▼ decel")) -> ▼ decel
A17: SURPRISE MATRIX vs STREET CONSENSUS
A18: Enter consensus (blue) from Bloomberg/survey. Surprise = Actual − Consensus, shown in bp.
A19: Metric | B19: Actual | C19: Consensus | D19: Surprise (bp) | E19: Signal
A20: Headline M/M | B20: =C6 -> 0.013758972 | D20: =IF(C20="","",(B20-C20)*10000) | E20: =IF(C20="","set cons.",IF(D20>0,"HOT ▲",IF(D20<0,"COOL ▼","in line"))) -> set cons.
A21: Headline Y/Y | B21: =D6 -> 0.059876062 | D21: =IF(C21="","",(B21-C21)*10000) | E21: =IF(C21="","set cons.",IF(D21>0,"HOT ▲",IF(D21<0,"COOL ▼","in line"))) -> set cons.
A22: Core M/M | B22: =C7 -> 0.010329156 | D22: =IF(C22="","",(B22-C22)*10000) | E22: =IF(C22="","set cons.",IF(D22>0,"HOT ▲",IF(D22<0,"COOL ▼","in line"))) -> set cons.
A23: Core Y/Y | B23: =D7 -> 0.05240291 | D23: =IF(C23="","",(B23-C23)*10000) | E23: =IF(C23="","set cons.",IF(D23>0,"HOT ▲",IF(D23<0,"COOL ▼","in line"))) -> set cons.
A26: MARGIN & PIPELINE TRACKER
A27: Trade services = wholesale/retail margins. Spread = Intermediate (input) − Final (output) inflation. Positive & widening spread → margin squeeze.
A28: Series | B28: M/M | C28: 3m ann. | D28: Y/Y
A29: Final Demand Trade Services | B29: {=INDEX('Calc Engine'!Y:Y,PPI_N+5)} -> 0.026771986 | C29: {=INDEX('Calc Engine'!BA:BA,PPI_N+5)} -> 0.11781475 | D29: {=INDEX('Calc Engine'!AM:AM,PPI_N+5)} -> 0.081181468
A30: Intermediate Processed Goods | B30: {=INDEX('Calc Engine'!Z:Z,PPI_N+5)} -> 0.026788339 | C30: {=INDEX('Calc Engine'!BB:BB,PPI_N+5)} -> 0.318865 | D30: {=INDEX('Calc Engine'!AN:AN,PPI_N+5)} -> 0.093267012
A31: Intermediate Unprocessed Goods | B31: {=INDEX('Calc Engine'!AA:AA,PPI_N+5)} -> 0.040827942 | C31: {=INDEX('Calc Engine'!BC:BC,PPI_N+5)} -> 0.6677408 | D31: {=INDEX('Calc Engine'!AO:AO,PPI_N+5)} -> 0.21226575
A32: SPREAD: Processed Interm − FD Goods | B32: {=INDEX('Calc Engine'!Z:Z,PPI_N+5)-INDEX('Calc Engine'!R:R,PPI_N+5)} -> 0.0071874235 | C32: {=INDEX('Calc Engine'!BB:BB,PPI_N+5)-INDEX('Calc Engine'!AT:AT,PPI_N+5)} -> 0.10451238 | D32: {=INDEX('Calc Engine'!AN:AN,PPI_N+5)-INDEX('Calc Engine'!AF:AF,PPI_N+5)} -> 0.019363166 | E32: =IF(D32="","",IF(D32>0,"⚠ Input>Output: margin squeeze","Output>Input: margin relief")) -> ⚠ Input>Output: margin squeeze
A33: SPREAD: Unprocessed − Processed | B33: {=INDEX('Calc Engine'!AA:AA,PPI_N+5)-INDEX('Calc Engine'!Z:Z,PPI_N+5)} -> 0.014039603 | C33: {=INDEX('Calc Engine'!BC:BC,PPI_N+5)-INDEX('Calc Engine'!BB:BB,PPI_N+5)} -> 0.3488758 | D33: {=INDEX('Calc Engine'!AO:AO,PPI_N+5)-INDEX('Calc Engine'!AN:AN,PPI_N+5)} -> 0.11899874 | E33: =IF(D33="","",IF(D33>0,"⚠ Early-stage pressure building","Early-stage easing")) -> ⚠ Early-stage pressure building
A75: CONTRIBUTION DECOMPOSITION — bp to Headline FD M/M
A76: Contribution = FD relative-importance weight × component M/M. M/M pulled live from Calc Engine where available (green). Weights = BLS FD-ID relative importance (Dec-2025 reweight); adjust in blue cells if BLS updates.
A77: Component | B77: FD weight | C77: M/M % | D77: Contrib (bp) | E77: % of headline
A78: Final Demand Goods | B78: 0.333 | C78: =C12 -> 0.019600916 | D78: =IF(OR(B78="",C78=""),"",B78*C78*10000) -> 65.27105 | E78: =IF(D78="","",D78/$D$83) -> 0.46598893
A79: Final Demand Services — of which: | B79: 0.634 | C79: =C13 -> 0.011797935 | D79: =IF(OR(B79="",C79=""),"",B79*C79*10000) -> 74.798909 | E79: =IF(D79="","",D79/$D$83) -> 0.53401107
A80: Trade services (margins) | B80: 0.195 | C80: =C14 -> 0.026771986 | D80: =IF(OR(B80="",C80=""),"",B80*C80*10000) -> 52.205372 | E80: =IF(D80="","",D80/$D$83) -> 0.37270927
A81: Transportation & warehousing | B81: 0.05 | D81: =IF(OR(B81="",C81=""),"",B81*C81*10000) | E81: =IF(D81="","",D81/$D$83)
A82: Services less trade & transport | B82: 0.389 | D82: =IF(OR(B82="",C82=""),"",B82*C82*10000) | E82: =IF(D82="","",D82/$D$83)
A83: TOTAL (Goods + Services + resid.) | B83: =B78+B79 -> 0.967 | C83: =C6 -> 0.013758972 | D83: =D78+D79 -> 140.06996 | E83: =IF(D83="","",D83/D83) -> 1
A84: Headline FD M/M (actual, for tie-out) | D84: =C6*10000 -> 137.58972 | E84: bp
A85: Note: Trade/Transport/Other are sub-rows of Services (not added to total). Weighted contributions are approximate — BLS does not publish exact bp contributions; small residual vs actual headline is expected.
A87: TOP MOVERS — April 2026 commodity detail
...

Sheet Calc Engine
A1: PPI CALC ENGINE — live links to Macrobond Imports (row N here = row N+? mirrored)
A2: Raw indices pulled from Macrobond. Transformations (M/M, Y/Y, 3m/6m ann.) reference these columns. Series labels in row 4, BLS code in row 3. | Q2: M/M % CHANGE (SA) | AE2: Y/Y % CHANGE (NSA-on-SA index) | AS2: 3-MONTH ANNUALIZED % | BG2: 6-MONTH ANNUALIZED %
A3: Macrobond col → | B3: B | C3: C | D3: Z | E3: BH | F3: BJ | G3: BK | H3: BL | I3: BS | J3: AA | K3: DF | L3: EA | M3: FA | N3: FC | BX3: FG | BY3: AI
A4: Date | B4: Headline FD | C4: FD Goods | D4: FD Services | E4: Core (ex F&E) | F4: FD ex Food | G4: FD ex Energy | H4: FD ex Trade Svcs | I4: FD ex F,E,Trade | J4: FD Trade Svcs | K4: Interm Processed | L4: Interm Unprocessed | M4: Proc Energy Gds | N4: Proc ex F&E | P4: Date | Q4: Headline FD | R4: FD Goods | S4: FD Services | T4: Core (ex F&E) | U4: FD ex Food | V4: FD ex Energy | W4: FD ex Trade Svcs | X4: FD ex F,E,Trade | Y4: FD Trade Svcs | Z4: Interm Processed | AA4: Interm Unprocessed | AB4: Proc Energy Gds | AC4: Proc ex F&E | AE4: Headline FD | AF4: FD Goods | AG4: FD Services | AH4: Core (ex F&E) | AI4: FD ex Food | AJ4: FD ex Energy | AK4: FD ex Trade Svcs | AL4: FD ex F,E,Trade | AM4: FD Trade Svcs | AN4: Interm Processed | AO4: Interm Unprocessed | AP4: Proc Energy Gds | AQ4: Proc ex F&E | AS4: Headline FD | AT4: FD Goods | AU4: FD Services | AV4: Core (ex F&E) | AW4: FD ex Food | AX4: FD ex Energy | AY4: FD ex Trade Svcs | AZ4: FD ex F,E,Trade | BA4: FD Trade Svcs | BB4: Interm Processed | BC4: Interm Unprocessed | BD4: Proc Energy Gds | BE4: Proc ex F&E | BG4: Headline FD | BH4: FD Goods | BI4: FD Services | BJ4: Core (ex F&E) | BK4: FD ex Food | BL4: FD ex Energy | BM4: FD ex Trade Svcs | BN4: FD ex F,E,Trade | BO4: FD Trade Svcs | BP4: Interm Processed | BQ4: Interm Unprocessed | BR4: Proc Energy Gds | BS4: Proc ex F&E | BX4: Unproc Energy (FG) | BY4: FD Transport&Whse (AI) | CA4: Unproc Energy Y/Y | CB4: Transport&Whse Y/Y
CB5: ChartDate | CC5: Headline M/M | CD5: Core M/M | CE5: Headline Y/Y | CF5: Core Y/Y | CG5: Headline 3m ann | CH5: Headline 6m ann | CK5: Date | CL5: Unproc Energy Y/Y | CM5: Transport&Whse Y/Y | DA5: Subcomponent | DB5: MBcol | DC5: Index | DD5: Prior | DE5: M/M | DF5: Type
A6: =IF('Macrobond Imports'!A5="","",'Macrobond Imports'!A5) -> 17258 | B6: =IF('Macrobond Imports'!B5="","",'Macrobond Imports'!B5) | C6: =IF('Macrobond Imports'!C5="","",'Macrobond Imports'!C5) | D6: =IF('Macrobond Imports'!Z5="","",'Macrobond Imports'!Z5) | E6: =IF('Macrobond Imports'!BH5="","",'Macrobond Imports'!BH5) | F6: =IF('Macrobond Imports'!BJ5="","",'Macrobond Imports'!BJ5) | G6: =IF('Macrobond Imports'!BK5="","",'Macrobond Imports'!BK5) | H6: =IF('Macrobond Imports'!BL5="","",'Macrobond Imports'!BL5) | I6: =IF('Macrobond Imports'!BS5="","",'Macrobond Imports'!BS5) | J6: =IF('Macrobond Imports'!AA5="","",'Macrobond Imports'!AA5) | K6: =IF('Macrobond Imports'!DF5="","",'Macrobond Imports'!DF5) -> 23.1 | L6: =IF('Macrobond Imports'!EA5="","",'Macrobond Imports'!EA5) -> 30.7 | M6: =IF('Macrobond Imports'!FA5="","",'Macrobond Imports'!FA5) | N6: =IF('Macrobond Imports'!FC5="","",'Macrobond Imports'!FC5) | P6: =A6 -> 17258 | Q6: =IF(OR(B6="",N(B5)=0),"",B6/B5-1) | R6: =IF(OR(C6="",N(C5)=0),"",C6/C5-1) | S6: =IF(OR(D6="",N(D5)=0),"",D6/D5-1) | T6: =IF(OR(E6="",N(E5)=0),"",E6/E5-1) | U6: =IF(OR(F6="",N(F5)=0),"",F6/F5-1) | V6: =IF(OR(G6="",N(G5)=0),"",G6/G5-1) | W6: =IF(OR(H6="",N(H5)=0),"",H6/H5-1) | X6: =IF(OR(I6="",N(I5)=0),"",I6/I5-1) | ... AC6: =IF(OR(N6="",N(N5)=0),"",N6/N5-1) | AE6: =IFERROR(IF(OR(B6="",OFFSET(B6,-12,0)=""),"",B6/OFFSET(B6,-12,0)-1),"") | AF6: =IFERROR(IF(OR(C6="",OFFSET(C6,-12,0)=""),"",C6/OFFSET(C6,-12,0)-1),"") | AG6: =IFERROR(IF(OR(D6="",OFFSET(D6,-12,0)=""),"",D6/OFFSET(D6,-12,0)-1),"") | AH6: =IFERROR(IF(OR(E6="",OFFSET(E6,-12,0)=""),"",E6/OFFSET(E6,-12,0)-1),"") | AI6: =IFERROR(IF(OR(F6="",OFFSET(F6,-12,0)=""),"",F6/OFFSET(F6,-12,0)-1),"") | AJ6: =IFERROR(IF(OR(G6="",OFFSET(G6,-12,0)=""),"",G6/OFFSET(G6,-12,0)-1),"") | AK6: =IFERROR(IF(OR(H6="",OFFSET(H6,-12,0)=""),"",H6/OFFSET(H6,-12,0)-1),"") | AL6: =IFERROR(IF(OR(I6="",OFFSET(I6,-12,0)=""),"",I6/OFFSET(I6,-12,0)-1),"") | ... AQ6: =IFERROR(IF(OR(N6="",OFFSET(N6,-12,0)=""),"",N6/OFFSET(N6,-12,0)-1),"") | AS6: =IFERROR(IF(OR(B6="",OFFSET(B6,-3,0)=""),"",(B6/OFFSET(B6,-3,0))^4-1),"") | AT6: =IFERROR(IF(OR(C6="",OFFSET(C6,-3,0)=""),"",(C6/OFFSET(C6,-3,0))^4-1),"") | AU6: =IFERROR(IF(OR(D6="",OFFSET(D6,-3,0)=""),"",(D6/OFFSET(D6,-3,0))^4-1),"") | AV6: =IFERROR(IF(OR(E6="",OFFSET(E6,-3,0)=""),"",(E6/OFFSET(E6,-3,0))^4-1),"") | AW6: =IFERROR(IF(OR(F6="",OFFSET(F6,-3,0)=""),"",(F6/OFFSET(F6,-3,0))^4-1),"") | AX6: =IFERROR(IF(OR(G6="",OFFSET(G6,-3,0)=""),"",(G6/OFFSET(G6,-3,0))^4-1),"") | AY6: =IFERROR(IF(OR(H6="",OFFSET(H6,-3,0)=""),"",(H6/OFFSET(H6,-3,0))^4-1),"") | AZ6: =IFERROR(IF(OR(I6="",OFFSET(I6,-3,0)=""),"",(I6/OFFSET(I6,-3,0))^4-1),"") | ... BE6: =IFERROR(IF(OR(N6="",OFFSET(N6,-3,0)=""),"",(N6/OFFSET(N6,-3,0))^4-1),"") | BG6: =IFERROR(IF(OR(B6="",OFFSET(B6,-6,0)=""),"",(B6/OFFSET(B6,-6,0))^2-1),"") | BH6: =IFERROR(IF(OR(C6="",OFFSET(C6,-6,0)=""),"",(C6/OFFSET(C6,-6,0))^2-1),"") | BI6: =IFERROR(IF(OR(D6="",OFFSET(D6,-6,0)=""),"",(D6/OFFSET(D6,-6,0))^2-1),"") | BJ6: =IFERROR(IF(OR(E6="",OFFSET(E6,-6,0)=""),"",(E6/OFFSET(E6,-6,0))^2-1),"") | BK6: =IFERROR(IF(OR(F6="",OFFSET(F6,-6,0)=""),"",(F6/OFFSET(F6,-6,0))^2-1),"") | BL6: =IFERROR(IF(OR(G6="",OFFSET(G6,-6,0)=""),"",(G6/OFFSET(G6,-6,0))^2-1),"") | BM6: =IFERROR(IF(OR(H6="",OFFSET(H6,-6,0)=""),"",(H6/OFFSET(H6,-6,0))^2-1),"") | BN6: =IFERROR(IF(OR(I6="",OFFSET(I6,-6,0)=""),"",(I6/OFFSET(I6,-6,0))^2-1),"") | ... BS6: =IFERROR(IF(OR(N6="",OFFSET(N6,-6,0)=""),"",(N6/OFFSET(N6,-6,0))^2-1),"") | BX6: =IF('Macrobond Imports'!FG5="","",'Macrobond Imports'!FG5) | BY6: =IF('Macrobond Imports'!AI5="","",'Macrobond Imports'!AI5) | CA6: =IFERROR(IF(OR(BX6="",OFFSET(BX6,-12,0)=""),"",BX6/OFFSET(BX6,-12,0)-1),"") | CB6: =IFERROR(IF(OR(BY6="",OFFSET(BY6,-12,0)=""),"",BY6/OFFSET(BY6,-12,0)-1),"") | CC6: {=INDEX(MM_Headline,ROW()-5)} -> 0.00018724384 | CD6: {=INDEX(MM_Core,ROW()-5)} -> 0.0026260578 | CE6: {=INDEX(YY_Headline,ROW()-5)} -> 0.025673119 | CF6: {=INDEX(YY_Core,ROW()-5)} -> 0.026970311 | CG6: {=INDEX(Ann3_Headline,ROW()-5)} -> 0.024440283 | CH6: {=INDEX(Ann6_Headline,ROW()-5)} -> 0.026733575 | CK6: {=INDEX(ChartDates,ROW()-5)} -> 45413 | CL6: {=INDEX(UnprocEnergy_YY,ROW()-5)} -> 0.05107398 | CM6: {=INDEX(Transport_YY,ROW()-5)} -> 0.0022079796 | DA6: Machinery & Vehicle Wholesaling | DB6: FQ | DC6: =INDEX('Macrobond Imports'!FQ:FQ,MATCH(MAX('Macrobond Imports'!$A:$A),'Macrobond Imports'!$A:$A,0)) -> 162.021 | DD6: {=INDEX('Macrobond Imports'!FQ:FQ,MATCH(MAX('Macrobond Imports'!$A:$A),'Macrobond Imports'!$A:$A,0)-1)} -> 153.77 | DE6: =IFERROR(IF(OR(DC6="",DD6="",DC6=0,DD6=0),"",DC6/DD6-1),"") -> 0.053658061 | DF6: WH | DG6: =IF(DE6="","",DE6+ROW()*0.000000001) -> 0.053658067
A7: =IF('Macrobond Imports'!A6="","",'Macrobond Imports'!A6) -> 17288 | B7: =IF('Macrobond Imports'!B6="","",'Macrobond Imports'!B6) | C7: =IF('Macrobond Imports'!C6="","",'Macrobond Imports'!C6) | D7: =IF('Macrobond Imports'!Z6="","",'Macrobond Imports'!Z6) | E7: =IF('Macrobond Imports'!BH6="","",'Macrobond Imports'!BH6) | F7: =IF('Macrobond Imports'!BJ6="","",'Macrobond Imports'!BJ6) | G7: =IF('Macrobond Imports'!BK6="","",'Macrobond Imports'!BK6) | H7: =IF('Macrobond Imports'!BL6="","",'Macrobond Imports'!BL6) | I7: =IF('Macrobond Imports'!BS6="","",'Macrobond Imports'!BS6) | J7: =IF('Macrobond Imports'!AA6="","",'Macrobond Imports'!AA6) | K7: =IF('Macrobond Imports'!DF6="","",'Macrobond Imports'!DF6) -> 23 | L7: =IF('Macrobond Imports'!EA6="","",'Macrobond Imports'!EA6) -> 30.4 | M7: =IF('Macrobond Imports'!FA6="","",'Macrobond Imports'!FA6) | N7: =IF('Macrobond Imports'!FC6="","",'Macrobond Imports'!FC6) | P7: =A7 -> 17288 | Q7: =IF(OR(B7="",N(B6)=0),"",B7/B6-1) | R7: =IF(OR(C7="",N(C6)=0),"",C7/C6-1) | S7: =IF(OR(D7="",N(D6)=0),"",D7/D6-1) | T7: =IF(OR(E7="",N(E6)=0),"",E7/E6-1) | U7: =IF(OR(F7="",N(F6)=0),"",F7/F6-1) | V7: =IF(OR(G7="",N(G6)=0),"",G7/G6-1) | W7: =IF(OR(H7="",N(H6)=0),"",H7/H6-1) | X7: =IF(OR(I7="",N(I6)=0),"",I7/I6-1) | ... AC7: =IF(OR(N7="",N(N6)=0),"",N7/N6-1) | AE7: =IFERROR(IF(OR(B7="",OFFSET(B7,-12,0)=""),"",B7/OFFSET(B7,-12,0)-1),"") | AF7: =IFERROR(IF(OR(C7="",OFFSET(C7,-12,0)=""),"",C7/OFFSET(C7,-12,0)-1),"") | AG7: =IFERROR(IF(OR(D7="",OFFSET(D7,-12,0)=""),"",D7/OFFSET(D7,-12,0)-1),"") | AH7: =IFERROR(IF(OR(E7="",OFFSET(E7,-12,0)=""),"",E7/OFFSET(E7,-12,0)-1),"") | AI7: =IFERROR(IF(OR(F7="",OFFSET(F7,-12,0)=""),"",F7/OFFSET(F7,-12,0)-1),"") | AJ7: =IFERROR(IF(OR(G7="",OFFSET(G7,-12,0)=""),"",G7/OFFSET(G7,-12,0)-1),"") | AK7: =IFERROR(IF(OR(H7="",OFFSET(H7,-12,0)=""),"",H7/OFFSET(H7,-12,0)-1),"") | AL7: =IFERROR(IF(OR(I7="",OFFSET(I7,-12,0)=""),"",I7/OFFSET(I7,-12,0)-1),"") | ... AQ7: =IFERROR(IF(OR(N7="",OFFSET(N7,-12,0)=""),"",N7/OFFSET(N7,-12,0)-1),"") | AS7: =IFERROR(IF(OR(B7="",OFFSET(B7,-3,0)=""),"",(B7/OFFSET(B7,-3,0))^4-1),"") | AT7: =IFERROR(IF(OR(C7="",OFFSET(C7,-3,0)=""),"",(C7/OFFSET(C7,-3,0))^4-1),"") | AU7: =IFERROR(IF(OR(D7="",OFFSET(D7,-3,0)=""),"",(D7/OFFSET(D7,-3,0))^4-1),"") | AV7: =IFERROR(IF(OR(E7="",OFFSET(E7,-3,0)=""),"",(E7/OFFSET(E7,-3,0))^4-1),"") | AW7: =IFERROR(IF(OR(F7="",OFFSET(F7,-3,0)=""),"",(F7/OFFSET(F7,-3,0))^4-1),"") | AX7: =IFERROR(IF(OR(G7="",OFFSET(G7,-3,0)=""),"",(G7/OFFSET(G7,-3,0))^4-1),"") | AY7: =IFERROR(IF(OR(H7="",OFFSET(H7,-3,0)=""),"",(H7/OFFSET(H7,-3,0))^4-1),"") | AZ7: =IFERROR(IF(OR(I7="",OFFSET(I7,-3,0)=""),"",(I7/OFFSET(I7,-3,0))^4-1),"") | ... BE7: =IFERROR(IF(OR(N7="",OFFSET(N7,-3,0)=""),"",(N7/OFFSET(N7,-3,0))^4-1),"") | BG7: =IFERROR(IF(OR(B7="",OFFSET(B7,-6,0)=""),"",(B7/OFFSET(B7,-6,0))^2-1),"") | BH7: =IFERROR(IF(OR(C7="",OFFSET(C7,-6,0)=""),"",(C7/OFFSET(C7,-6,0))^2-1),"") | BI7: =IFERROR(IF(OR(D7="",OFFSET(D7,-6,0)=""),"",(D7/OFFSET(D7,-6,0))^2-1),"") | BJ7: =IFERROR(IF(OR(E7="",OFFSET(E7,-6,0)=""),"",(E7/OFFSET(E7,-6,0))^2-1),"") | BK7: =IFERROR(IF(OR(F7="",OFFSET(F7,-6,0)=""),"",(F7/OFFSET(F7,-6,0))^2-1),"") | BL7: =IFERROR(IF(OR(G7="",OFFSET(G7,-6,0)=""),"",(G7/OFFSET(G7,-6,0))^2-1),"") | BM7: =IFERROR(IF(OR(H7="",OFFSET(H7,-6,0)=""),"",(H7/OFFSET(H7,-6,0))^2-1),"") | BN7: =IFERROR(IF(OR(I7="",OFFSET(I7,-6,0)=""),"",(I7/OFFSET(I7,-6,0))^2-1),"") | ... BS7: =IFERROR(IF(OR(N7="",OFFSET(N7,-6,0)=""),"",(N7/OFFSET(N7,-6,0))^2-1),"") | BX7: =IF('Macrobond Imports'!FG6="","",'Macrobond Imports'!FG6) | BY7: =IF('Macrobond Imports'!AI6="","",'Macrobond Imports'!AI6) | CA7: =IFERROR(IF(OR(BX7="",OFFSET(BX7,-12,0)=""),"",BX7/OFFSET(BX7,-12,0)-1),"") | CB7: =IFERROR(IF(OR(BY7="",OFFSET(BY7,-12,0)=""),"",BY7/OFFSET(BY7,-12,0)-1),"") | CC7: {=INDEX(MM_Headline,ROW()-5)} -> 0.0044722099 | CD7: {=INDEX(MM_Core,ROW()-5)} -> 0.0059826839 | CE7: {=INDEX(YY_Headline,ROW()-5)} -> 0.029645055 | CF7: {=INDEX(YY_Core,ROW()-5)} -> 0.032883448 | CG7: {=INDEX(Ann3_Headline,ROW()-5)} -> 0.038102035 | CH7: {=INDEX(Ann6_Headline,ROW()-5)} -> 0.038402071 | CK7: {=INDEX(ChartDates,ROW()-5)} -> 45444 | CL7: {=INDEX(UnprocEnergy_YY,ROW()-5)} -> 0.11386231 | CM7: {=INDEX(Transport_YY,ROW()-5)} -> 0.0043137044 | DA7: Parts & Supplies Machinery Wholesaling | DB7: FP | DC7: =INDEX('Macrobond Imports'!FP:FP,MATCH(MAX('Macrobond Imports'!$A:$A),'Macrobond Imports'!$A:$A,0)) -> 235.79 | DD7: {=INDEX('Macrobond Imports'!FP:FP,MATCH(MAX('Macrobond Imports'!$A:$A),'Macrobond Imports'!$A:$A,0)-1)} -> 233.95 | DE7: =IFERROR(IF(OR(DC7="",DD7="",DC7=0,DD7=0),"",DC7/DD7-1),"") -> 0.0078649284 | DF7: WH | DG7: =IF(DE7="","",DE7+ROW()*0.000000001) -> 0.0078649354
A8: =IF('Macrobond Imports'!A7="","",'Macrobond Imports'!A7) -> 17319 | B8: =IF('Macrobond Imports'!B7="","",'Macrobond Imports'!B7) | C8: =IF('Macrobond Imports'!C7="","",'Macrobond Imports'!C7) | D8: =IF('Macrobond Imports'!Z7="","",'Macrobond Imports'!Z7) | E8: =IF('Macrobond Imports'!BH7="","",'Macrobond Imports'!BH7) | F8: =IF('Macrobond Imports'!BJ7="","",'Macrobond Imports'!BJ7) | G8: =IF('Macrobond Imports'!BK7="","",'Macrobond Imports'!BK7) | H8: =IF('Macrobond Imports'!BL7="","",'Macrobond Imports'!BL7) | I8: =IF('Macrobond Imports'!BS7="","",'Macrobond Imports'!BS7) | J8: =IF('Macrobond Imports'!AA7="","",'Macrobond Imports'!AA7) | K8: =IF('Macrobond Imports'!DF7="","",'Macrobond Imports'!DF7) -> 23.2 | L8: =IF('Macrobond Imports'!EA7="","",'Macrobond Imports'!EA7) -> 30.6 | M8: =IF('Macrobond Imports'!FA7="","",'Macrobond Imports'!FA7) | N8: =IF('Macrobond Imports'!FC7="","",'Macrobond Imports'!FC7) | P8: =A8 -> 17319 | Q8: =IF(OR(B8="",N(B7)=0),"",B8/B7-1) | R8: =IF(OR(C8="",N(C7)=0),"",C8/C7-1) | S8: =IF(OR(D8="",N(D7)=0),"",D8/D7-1) | T8: =IF(OR(E8="",N(E7)=0),"",E8/E7-1) | U8: =IF(OR(F8="",N(F7)=0),"",F8/F7-1) | V8: =IF(OR(G8="",N(G7)=0),"",G8/G7-1) | W8: =IF(OR(H8="",N(H7)=0),"",H8/H7-1) | X8: =IF(OR(I8="",N(I7)=0),"",I8/I7-1) | ... AC8: =IF(OR(N8="",N(N7)=0),"",N8/N7-1) | AE8: =IFERROR(IF(OR(B8="",OFFSET(B8,-12,0)=""),"",B8/OFFSET(B8,-12,0)-1),"") | AF8: =IFERROR(IF(OR(C8="",OFFSET(C8,-12,0)=""),"",C8/OFFSET(C8,-12,0)-1),"") | AG8: =IFERROR(IF(OR(D8="",OFFSET(D8,-12,0)=""),"",D8/OFFSET(D8,-12,0)-1),"") | AH8: =IFERROR(IF(OR(E8="",OFFSET(E8,-12,0)=""),"",E8/OFFSET(E8,-12,0)-1),"") | AI8: =IFERROR(IF(OR(F8="",OFFSET(F8,-12,0)=""),"",F8/OFFSET(F8,-12,0)-1),"") | AJ8: =IFERROR(IF(OR(G8="",OFFSET(G8,-12,0)=""),"",G8/OFFSET(G8,-12,0)-1),"") | AK8: =IFERROR(IF(OR(H8="",OFFSET(H8,-12,0)=""),"",H8/OFFSET(H8,-12,0)-1),"") | AL8: =IFERROR(IF(OR(I8="",OFFSET(I8,-12,0)=""),"",I8/OFFSET(I8,-12,0)-1),"") | ... AQ8: =IFERROR(IF(OR(N8="",OFFSET(N8,-12,0)=""),"",N8/OFFSET(N8,-12,0)-1),"") | AS8: =IFERROR(IF(OR(B8="",OFFSET(B8,-3,0)=""),"",(B8/OFFSET(B8,-3,0))^4-1),"") | AT8: =IFERROR(IF(OR(C8="",OFFSET(C8,-3,0)=""),"",(C8/OFFSET(C8,-3,0))^4-1),"") | AU8: =IFERROR(IF(OR(D8="",OFFSET(D8,-3,0)=""),"",(D8/OFFSET(D8,-3,0))^4-1),"") | AV8: =IFERROR(IF(OR(E8="",OFFSET(E8,-3,0)=""),"",(E8/OFFSET(E8,-3,0))^4-1),"") | AW8: =IFERROR(IF(OR(F8="",OFFSET(F8,-3,0)=""),"",(F8/OFFSET(F8,-3,0))^4-1),"") | AX8: =IFERROR(IF(OR(G8="",OFFSET(G8,-3,0)=""),"",(G8/OFFSET(G8,-3,0))^4-1),"") | AY8: =IFERROR(IF(OR(H8="",OFFSET(H8,-3,0)=""),"",(H8/OFFSET(H8,-3,0))^4-1),"") | AZ8: =IFERROR(IF(OR(I8="",OFFSET(I8,-3,0)=""),"",(I8/OFFSET(I8,-3,0))^4-1),"") | ... BE8: =IFERROR(IF(OR(N8="",OFFSET(N8,-3,0)=""),"",(N8/OFFSET(N8,-3,0))^4-1),"") | BG8: =IFERROR(IF(OR(B8="",OFFSET(B8,-6,0)=""),"",(B8/OFFSET(B8,-6,0))^2-1),"") | BH8: =IFERROR(IF(OR(C8="",OFFSET(C8,-6,0)=""),"",(C8/OFFSET(C8,-6,0))^2-1),"") | BI8: =IFERROR(IF(OR(D8="",OFFSET(D8,-6,0)=""),"",(D8/OFFSET(D8,-6,0))^2-1),"") | BJ8: =IFERROR(IF(OR(E8="",OFFSET(E8,-6,0)=""),"",(E8/OFFSET(E8,-6,0))^2-1),"") | BK8: =IFERROR(IF(OR(F8="",OFFSET(F8,-6,0)=""),"",(F8/OFFSET(F8,-6,0))^2-1),"") | BL8: =IFERROR(IF(OR(G8="",OFFSET(G8,-6,0)=""),"",(G8/OFFSET(G8,-6,0))^2-1),"") | BM8: =IFERROR(IF(OR(H8="",OFFSET(H8,-6,0)=""),"",(H8/OFFSET(H8,-6,0))^2-1),"") | BN8: =IFERROR(IF(OR(I8="",OFFSET(I8,-6,0)=""),"",(I8/OFFSET(I8,-6,0))^2-1),"") | ... BS8: =IFERROR(IF(OR(N8="",OFFSET(N8,-6,0)=""),"",(N8/OFFSET(N8,-6,0))^2-1),"") | BX8: =IF('Macrobond Imports'!FG7="","",'Macrobond Imports'!FG7) | BY8: =IF('Macrobond Imports'!AI7="","",'Macrobond Imports'!AI7) | CA8: =IFERROR(IF(OR(BX8="",OFFSET(BX8,-12,0)=""),"",BX8/OFFSET(BX8,-12,0)-1),"") | CB8: =IFERROR(IF(OR(BY8="",OFFSET(BY8,-12,0)=""),"",BY8/OFFSET(BY8,-12,0)-1),"") | CC8: {=INDEX(MM_Headline,ROW()-5)} -> 0.00036584777 | CD8: {=INDEX(MM_Core,ROW()-5)} -> -0.00053747304 | CE8: {=INDEX(YY_Headline,ROW()-5)} -> 0.024292328 | CF8: {=INDEX(YY_Core,ROW()-5)} -> 0.025966954 | CG8: {=INDEX(Ann3_Headline,ROW()-5)} -> 0.02026356 | CH8: {=INDEX(Ann6_Headline,ROW()-5)} -> 0.033179511 | CK8: {=INDEX(ChartDates,ROW()-5)} -> 45474 | CL8: {=INDEX(UnprocEnergy_YY,ROW()-5)} -> 0.044292007 | CM8: {=INDEX(Transport_YY,ROW()-5)} -> 0.014167746 | DA8: Professional & Commercial Equip Wholesaling | DB8: FR | DC8: =INDEX('Macrobond Imports'!FR:FR,MATCH(MAX('Macrobond Imports'!$A:$A),'Macrobond Imports'!$A:$A,0)) -> 112.233 | DD8: {=INDEX('Macrobond Imports'!FR:FR,MATCH(MAX('Macrobond Imports'!$A:$A),'Macrobond Imports'!$A:$A,0)-1)} -> 108.385 | DE8: =IFERROR(IF(OR(DC8="",DD8="",DC8=0,DD8=0),"",DC8/DD8-1),"") -> 0.035503068 | DF8: WH | DG8: =IF(DE8="","",DE8+ROW()*0.000000001) -> 0.035503076
A9: =IF('Macrobond Imports'!A8="","",'Macrobond Imports'!A8) -> 17349 | B9: =IF('Macrobond Imports'!B8="","",'Macrobond Imports'!B8) | C9: =IF('Macrobond Imports'!C8="","",'Macrobond Imports'!C8) | D9: =IF('Macrobond Imports'!Z8="","",'Macrobond Imports'!Z8) | E9: =IF('Macrobond Imports'!BH8="","",'Macrobond Imports'!BH8) | F9: =IF('Macrobond Imports'!BJ8="","",'Macrobond Imports'!BJ8) | G9: =IF('Macrobond Imports'!BK8="","",'Macrobond Imports'!BK8) | H9: =IF('Macrobond Imports'!BL8="","",'Macrobond Imports'!BL8) | I9: =IF('Macrobond Imports'!BS8="","",'Macrobond Imports'!BS8) | J9: =IF('Macrobond Imports'!AA8="","",'Macrobond Imports'!AA8) | K9: =IF('Macrobond Imports'!DF8="","",'Macrobond Imports'!DF8) -> 23.2 | L9: =IF('Macrobond Imports'!EA8="","",'Macrobond Imports'!EA8) -> 31 | M9: =IF('Macrobond Imports'!FA8="","",'Macrobond Imports'!FA8) | N9: =IF('Macrobond Imports'!FC8="","",'Macrobond Imports'!FC8) | P9: =A9 -> 17349 | Q9: =IF(OR(B9="",N(B8)=0),"",B9/B8-1) | R9: =IF(OR(C9="",N(C8)=0),"",C9/C8-1) | S9: =IF(OR(D9="",N(D8)=0),"",D9/D8-1) | T9: =IF(OR(E9="",N(E8)=0),"",E9/E8-1) | U9: =IF(OR(F9="",N(F8)=0),"",F9/F8-1) | V9: =IF(OR(G9="",N(G8)=0),"",G9/G8-1) | W9: =IF(OR(H9="",N(H8)=0),"",H9/H8-1) | X9: =IF(OR(I9="",N(I8)=0),"",I9/I8-1) | ... AC9: =IF(OR(N9="",N(N8)=0),"",N9/N8-1) | AE9: =IFERROR(IF(OR(B9="",OFFSET(B9,-12,0)=""),"",B9/OFFSET(B9,-12,0)-1),"") | AF9: =IFERROR(IF(OR(C9="",OFFSET(C9,-12,0)=""),"",C9/OFFSET(C9,-12,0)-1),"") | AG9: =IFERROR(IF(OR(D9="",OFFSET(D9,-12,0)=""),"",D9/OFFSET(D9,-12,0)-1),"") | AH9: =IFERROR(IF(OR(E9="",OFFSET(E9,-12,0)=""),"",E9/OFFSET(E9,-12,0)-1),"") | AI9: =IFERROR(IF(OR(F9="",OFFSET(F9,-12,0)=""),"",F9/OFFSET(F9,-12,0)-1),"") | AJ9: =IFERROR(IF(OR(G9="",OFFSET(G9,-12,0)=""),"",G9/OFFSET(G9,-12,0)-1),"") | AK9: =IFERROR(IF(OR(H9="",OFFSET(H9,-12,0)=""),"",H9/OFFSET(H9,-12,0)-1),"") | AL9: =IFERROR(IF(OR(I9="",OFFSET(I9,-12,0)=""),"",I9/OFFSET(I9,-12,0)-1),"") | ... AQ9: =IFERROR(IF(OR(N9="",OFFSET(N9,-12,0)=""),"",N9/OFFSET(N9,-12,0)-1),"") | AS9: =IFERROR(IF(OR(B9="",OFFSET(B9,-3,0)=""),"",(B9/OFFSET(B9,-3,0))^4-1),"") | AT9: =IFERROR(IF(OR(C9="",OFFSET(C9,-3,0)=""),"",(C9/OFFSET(C9,-3,0))^4-1),"") | AU9: =IFERROR(IF(OR(D9="",OFFSET(D9,-3,0)=""),"",(D9/OFFSET(D9,-3,0))^4-1),"") | AV9: =IFERROR(IF(OR(E9="",OFFSET(E9,-3,0)=""),"",(E9/OFFSET(E9,-3,0))^4-1),"") | AW9: =IFERROR(IF(OR(F9="",OFFSET(F9,-3,0)=""),"",(F9/OFFSET(F9,-3,0))^4-1),"") | AX9: =IFERROR(IF(OR(G9="",OFFSET(G9,-3,0)=""),"",(G9/OFFSET(G9,-3,0))^4-1),"") | AY9: =IFERROR(IF(OR(H9="",OFFSET(H9,-3,0)=""),"",(H9/OFFSET(H9,-3,0))^4-1),"") | AZ9: =IFERROR(IF(OR(I9="",OFFSET(I9,-3,0)=""),"",(I9/OFFSET(I9,-3,0))^4-1),"") | ... BE9: =IFERROR(IF(OR(N9="",OFFSET(N9,-3,0)=""),"",(N9/OFFSET(N9,-3,0))^4-1),"") | BG9: =IFERROR(IF(OR(B9="",OFFSET(B9,-6,0)=""),"",(B9/OFFSET(B9,-6,0))^2-1),"") | BH9: =IFERROR(IF(OR(C9="",OFFSET(C9,-6,0)=""),"",(C9/OFFSET(C9,-6,0))^2-1),"") | BI9: =IFERROR(IF(OR(D9="",OFFSET(D9,-6,0)=""),"",(D9/OFFSET(D9,-6,0))^2-1),"") | BJ9: =IFERROR(IF(OR(E9="",OFFSET(E9,-6,0)=""),"",(E9/OFFSET(E9,-6,0))^2-1),"") | BK9: =IFERROR(IF(OR(F9="",OFFSET(F9,-6,0)=""),"",(F9/OFFSET(F9,-6,0))^2-1),"") | BL9: =IFERROR(IF(OR(G9="",OFFSET(G9,-6,0)=""),"",(G9/OFFSET(G9,-6,0))^2-1),"") | BM9: =IFERROR(IF(OR(H9="",OFFSET(H9,-6,0)=""),"",(H9/OFFSET(H9,-6,0))^2-1),"") | BN9: =IFERROR(IF(OR(I9="",OFFSET(I9,-6,0)=""),"",(I9/OFFSET(I9,-6,0))^2-1),"") | ... BS9: =IFERROR(IF(OR(N9="",OFFSET(N9,-6,0)=""),"",(N9/OFFSET(N9,-6,0))^2-1),"") | BX9: =IF('Macrobond Imports'!FG8="","",'Macrobond Imports'!FG8) | BY9: =IF('Macrobond Imports'!AI8="","",'Macrobond Imports'!AI8) | CA9: =IFERROR(IF(OR(BX9="",OFFSET(BX9,-12,0)=""),"",BX9/OFFSET(BX9,-12,0)-1),"") | CB9: =IFERROR(IF(OR(BY9="",OFFSET(BY9,-12,0)=""),"",BY9/OFFSET(BY9,-12,0)-1),"") | CC9: {=INDEX(MM_Headline,ROW()-5)} -> 0.0033604284 | CD9: {=INDEX(MM_Core,ROW()-5)} -> 0.004357968 | CE9: {=INDEX(YY_Headline,ROW()-5)} -> 0.021066084 | CF9: {=INDEX(YY_Core,ROW()-5)} -> 0.028396942 | CG9: {=INDEX(Ann3_Headline,ROW()-5)} -> 0.03327282 | CH9: {=INDEX(Ann6_Headline,ROW()-5)} -> 0.028847073 | CK9: {=INDEX(ChartDates,ROW()-5)} -> 45505 | CL9: {=INDEX(UnprocEnergy_YY,ROW()-5)} -> -0.081049979 | CM9: {=INDEX(Transport_YY,ROW()-5)} -> 0.0058462281 | DA9: Furnishings Wholesaling | DB9: FS | DC9: =INDEX('Macrobond Imports'!FS:FS,MATCH(MAX('Macrobond Imports'!$A:$A),'Macrobond Imports'!$A:$A,0)) -> 147.646 | DD9: {=INDEX('Macrobond Imports'!FS:FS,MATCH(MAX('Macrobond Imports'!$A:$A),'Macrobond Imports'!$A:$A,0)-1)} -> 147.479 | DE9: =IFERROR(IF(OR(DC9="",DD9="",DC9=0,DD9=0),"",DC9/DD9-1),"") -> 0.0011323646 | DF9: WH | DG9: =IF(DE9="","",DE9+ROW()*0.000000001) -> 0.0011323736
A10: =IF('Macrobond Imports'!A9="","",'Macrobond Imports'!A9) -> 17380 | B10: =IF('Macrobond Imports'!B9="","",'Macrobond Imports'!B9) | C10: =IF('Macrobond Imports'!C9="","",'Macrobond Imports'!C9) | D10: =IF('Macrobond Imports'!Z9="","",'Macrobond Imports'!Z9) | E10: =IF('Macrobond Imports'!BH9="","",'Macrobond Imports'!BH9) | F10: =IF('Macrobond Imports'!BJ9="","",'Macrobond Imports'!BJ9) | G10: =IF('Macrobond Imports'!BK9="","",'Macrobond Imports'!BK9) | H10: =IF('Macrobond Imports'!BL9="","",'Macrobond Imports'!BL9) | I10: =IF('Macrobond Imports'!BS9="","",'Macrobond Imports'!BS9) | J10: =IF('Macrobond Imports'!AA9="","",'Macrobond Imports'!AA9) | K10: =IF('Macrobond Imports'!DF9="","",'Macrobond Imports'!DF9) -> 23.3 | L10: =IF('Macrobond Imports'!EA9="","",'Macrobond Imports'!EA9) -> 31.6 | M10: =IF('Macrobond Imports'!FA9="","",'Macrobond Imports'!FA9) | N10: =IF('Macrobond Imports'!FC9="","",'Macrobond Imports'!FC9) | P10: =A10 -> 17380 | Q10: =IF(OR(B10="",N(B9)=0),"",B10/B9-1) | R10: =IF(OR(C10="",N(C9)=0),"",C10/C9-1) | S10: =IF(OR(D10="",N(D9)=0),"",D10/D9-1) | T10: =IF(OR(E10="",N(E9)=0),"",E10/E9-1) | U10: =IF(OR(F10="",N(F9)=0),"",F10/F9-1) | V10: =IF(OR(G10="",N(G9)=0),"",G10/G9-1) | W10: =IF(OR(H10="",N(H9)=0),"",H10/H9-1) | X10: =IF(OR(I10="",N(I9)=0),"",I10/I9-1) | ... AC10: =IF(OR(N10="",N(N9)=0),"",N10/N9-1) | AE10: =IFERROR(IF(OR(B10="",OFFSET(B10,-12,0)=""),"",B10/OFFSET(B10,-12,0)-1),"") | AF10: =IFERROR(IF(OR(C10="",OFFSET(C10,-12,0)=""),"",C10/OFFSET(C10,-12,0)-1),"") | AG10: =IFERROR(IF(OR(D10="",OFFSET(D10,-12,0)=""),"",D10/OFFSET(D10,-12,0)-1),"") | AH10: =IFERROR(IF(OR(E10="",OFFSET(E10,-12,0)=""),"",E10/OFFSET(E10,-12,0)-1),"") | AI10: =IFERROR(IF(OR(F10="",OFFSET(F10,-12,0)=""),"",F10/OFFSET(F10,-12,0)-1),"") | AJ10: =IFERROR(IF(OR(G10="",OFFSET(G10,-12,0)=""),"",G10/OFFSET(G10,-12,0)-1),"") | AK10: =IFERROR(IF(OR(H10="",OFFSET(H10,-12,0)=""),"",H10/OFFSET(H10,-12,0)-1),"") | AL10: =IFERROR(IF(OR(I10="",OFFSET(I10,-12,0)=""),"",I10/OFFSET(I10,-12,0)-1),"") | ... AQ10: =IFERROR(IF(OR(N10="",OFFSET(N10,-12,0)=""),"",N10/OFFSET(N10,-12,0)-1),"") | AS10: =IFERROR(IF(OR(B10="",OFFSET(B10,-3,0)=""),"",(B10/OFFSET(B10,-3,0))^4-1),"") | AT10: =IFERROR(IF(OR(C10="",OFFSET(C10,-3,0)=""),"",(C10/OFFSET(C10,-3,0))^4-1),"") | AU10: =IFERROR(IF(OR(D10="",OFFSET(D10,-3,0)=""),"",(D10/OFFSET(D10,-3,0))^4-1),"") | AV10: =IFERROR(IF(OR(E10="",OFFSET(E10,-3,0)=""),"",(E10/OFFSET(E10,-3,0))^4-1),"") | AW10: =IFERROR(IF(OR(F10="",OFFSET(F10,-3,0)=""),"",(F10/OFFSET(F10,-3,0))^4-1),"") | AX10: =IFERROR(IF(OR(G10="",OFFSET(G10,-3,0)=""),"",(G10/OFFSET(G10,-3,0))^4-1),"") | AY10: =IFERROR(IF(OR(H10="",OFFSET(H10,-3,0)=""),"",(H10/OFFSET(H10,-3,0))^4-1),"") | AZ10: =IFERROR(IF(OR(I10="",OFFSET(I10,-3,0)=""),"",(I10/OFFSET(I10,-3,0))^4-1),"") | ... BE10: =IFERROR(IF(OR(N10="",OFFSET(N10,-3,0)=""),"",(N10/OFFSET(N10,-3,0))^4-1),"") | BG10: =IFERROR(IF(OR(B10="",OFFSET(B10,-6,0)=""),"",(B10/OFFSET(B10,-6,0))^2-1),"") | BH10: =IFERROR(IF(OR(C10="",OFFSET(C10,-6,0)=""),"",(C10/OFFSET(C10,-6,0))^2-1),"") | BI10: =IFERROR(IF(OR(D10="",OFFSET(D10,-6,0)=""),"",(D10/OFFSET(D10,-6,0))^2-1),"") | BJ10: =IFERROR(IF(OR(E10="",OFFSET(E10,-6,0)=""),"",(E10/OFFSET(E10,-6,0))^2-1),"") | BK10: =IFERROR(IF(OR(F10="",OFFSET(F10,-6,0)=""),"",(F10/OFFSET(F10,-6,0))^2-1),"") | BL10: =IFERROR(IF(OR(G10="",OFFSET(G10,-6,0)=""),"",(G10/OFFSET(G10,-6,0))^2-1),"") | BM10: =IFERROR(IF(OR(H10="",OFFSET(H10,-6,0)=""),"",(H10/OFFSET(H10,-6,0))^2-1),"") | BN10: =IFERROR(IF(OR(I10="",OFFSET(I10,-6,0)=""),"",(I10/OFFSET(I10,-6,0))^2-1),"") | ... BS10: =IFERROR(IF(OR(N10="",OFFSET(N10,-6,0)=""),"",(N10/OFFSET(N10,-6,0))^2-1),"") | BX10: =IF('Macrobond Imports'!FG9="","",'Macrobond Imports'!FG9) | BY10: =IF('Macrobond Imports'!AI9="","",'Macrobond Imports'!AI9) | CA10: =IFERROR(IF(OR(BX10="",OFFSET(BX10,-12,0)=""),"",BX10/OFFSET(BX10,-12,0)-1),"") | CB10: =IFERROR(IF(OR(BY10="",OFFSET(BY10,-12,0)=""),"",BY10/OFFSET(BY10,-12,0)-1),"") | CC10: {=INDEX(MM_Headline,ROW()-5)} -> 0.0027095984 | CD10: {=INDEX(MM_Core,ROW()-5)} -> 0.0043946874 | CE10: {=INDEX(YY_Headline,ROW()-5)} -> 0.021429973 | CF10: {=INDEX(YY_Core,ROW()-5)} -> 0.033064176 | CG10: {=INDEX(Ann3_Headline,ROW()-5)} -> 0.026039288 | CH10: {=INDEX(Ann6_Headline,ROW()-5)} -> 0.032053038 | CK10: {=INDEX(ChartDates,ROW()-5)} -> 45536 | CL10: {=INDEX(UnprocEnergy_YY,ROW()-5)} -> -0.22155365 | CM10: {=INDEX(Transport_YY,ROW()-5)} -> 0.0020138629 | DA10: Chemicals & Allied Products Wholesaling | DB10: FT | DC10: =INDEX('Macrobond Imports'!FT:FT,MATCH(MAX('Macrobond Imports'!$A:$A),'Macrobond Imports'!$A:$A,0)) -> 145.504 | DD10: {=INDEX('Macrobond Imports'!FT:FT,MATCH(MAX('Macrobond Imports'!$A:$A),'Macrobond Imports'!$A:$A,0)-1)} -> 135.553 | DE10: =IFERROR(IF(OR(DC10="",DD10="",DC10=0,DD10=0),"",DC10/DD10-1),"") -> 0.0734104 | DF10: WH | DG10: =IF(DE10="","",DE10+ROW()*0.000000001) -> 0.07341041
A11: =IF('Macrobond Imports'!A10="","",'Macrobond Imports'!A10) -> 17411 | B11: =IF('Macrobond Imports'!B10="","",'Macrobond Imports'!B10) | C11: =IF('Macrobond Imports'!C10="","",'Macrobond Imports'!C10) | D11: =IF('Macrobond Imports'!Z10="","",'Macrobond Imports'!Z10) | E11: =IF('Macrobond Imports'!BH10="","",'Macrobond Imports'!BH10) | F11: =IF('Macrobond Imports'!BJ10="","",'Macrobond Imports'!BJ10) | G11: =IF('Macrobond Imports'!BK10="","",'Macrobond Imports'!BK10) | H11: =IF('Macrobond Imports'!BL10="","",'Macrobond Imports'!BL10) | I11: =IF('Macrobond Imports'!BS10="","",'Macrobond Imports'!BS10) | J11: =IF('Macrobond Imports'!AA10="","",'Macrobond Imports'!AA10) | K11: =IF('Macrobond Imports'!DF10="","",'Macrobond Imports'!DF10) -> 23.7 | L11: =IF('Macrobond Imports'!EA10="","",'Macrobond Imports'!EA10) -> 32.4 | M11: =IF('Macrobond Imports'!FA10="","",'Macrobond Imports'!FA10) | N11: =IF('Macrobond Imports'!FC10="","",'Macrobond Imports'!FC10) | P11: =A11 -> 17411 | Q11: =IF(OR(B11="",N(B10)=0),"",B11/B10-1) | R11: =IF(OR(C11="",N(C10)=0),"",C11/C10-1) | S11: =IF(OR(D11="",N(D10)=0),"",D11/D10-1) | T11: =IF(OR(E11="",N(E10)=0),"",E11/E10-1) | U11: =IF(OR(F11="",N(F10)=0),"",F11/F10-1) | V11: =IF(OR(G11="",N(G10)=0),"",G11/G10-1) | W11: =IF(OR(H11="",N(H10)=0),"",H11/H10-1) | X11: =IF(OR(I11="",N(I10)=0),"",I11/I10-1) | ... AC11: =IF(OR(N11="",N(N10)=0),"",N11/N10-1) | AE11: =IFERROR(IF(OR(B11="",OFFSET(B11,-12,0)=""),"",B11/OFFSET(B11,-12,0)-1),"") | AF11: =IFERROR(IF(OR(C11="",OFFSET(C11,-12,0)=""),"",C11/OFFSET(C11,-12,0)-1),"") | AG11: =IFERROR(IF(OR(D11="",OFFSET(D11,-12,0)=""),"",D11/OFFSET(D11,-12,0)-1),"") | AH11: =IFERROR(IF(OR(E11="",OFFSET(E11,-12,0)=""),"",E11/OFFSET(E11,-12,0)-1),"") | AI11: =IFERROR(IF(OR(F11="",OFFSET(F11,-12,0)=""),"",F11/OFFSET(F11,-12,0)-1),"") | AJ11: =IFERROR(IF(OR(G11="",OFFSET(G11,-12,0)=""),"",G11/OFFSET(G11,-12,0)-1),"") | AK11: =IFERROR(IF(OR(H11="",OFFSET(H11,-12,0)=""),"",H11/OFFSET(H11,-12,0)-1),"") | AL11: =IFERROR(IF(OR(I11="",OFFSET(I11,-12,0)=""),"",I11/OFFSET(I11,-12,0)-1),"") | ... AQ11: =IFERROR(IF(OR(N11="",OFFSET(N11,-12,0)=""),"",N11/OFFSET(N11,-12,0)-1),"") | AS11: =IFERROR(IF(OR(B11="",OFFSET(B11,-3,0)=""),"",(B11/OFFSET(B11,-3,0))^4-1),"") | AT11: =IFERROR(IF(OR(C11="",OFFSET(C11,-3,0)=""),"",(C11/OFFSET(C11,-3,0))^4-1),"") | AU11: =IFERROR(IF(OR(D11="",OFFSET(D11,-3,0)=""),"",(D11/OFFSET(D11,-3,0))^4-1),"") | AV11: =IFERROR(IF(OR(E11="",OFFSET(E11,-3,0)=""),"",(E11/OFFSET(E11,-3,0))^4-1),"") | AW11: =IFERROR(IF(OR(F11="",OFFSET(F11,-3,0)=""),"",(F11/OFFSET(F11,-3,0))^4-1),"") | AX11: =IFERROR(IF(OR(G11="",OFFSET(G11,-3,0)=""),"",(G11/OFFSET(G11,-3,0))^4-1),"") | AY11: =IFERROR(IF(OR(H11="",OFFSET(H11,-3,0)=""),"",(H11/OFFSET(H11,-3,0))^4-1),"") | AZ11: =IFERROR(IF(OR(I11="",OFFSET(I11,-3,0)=""),"",(I11/OFFSET(I11,-3,0))^4-1),"") | ... BE11: =IFERROR(IF(OR(N11="",OFFSET(N11,-3,0)=""),"",(N11/OFFSET(N11,-3,0))^4-1),"") | BG11: =IFERROR(IF(OR(B11="",OFFSET(B11,-6,0)=""),"",(B11/OFFSET(B11,-6,0))^2-1),"") | BH11: =IFERROR(IF(OR(C11="",OFFSET(C11,-6,0)=""),"",(C11/OFFSET(C11,-6,0))^2-1),"") | BI11: =IFERROR(IF(OR(D11="",OFFSET(D11,-6,0)=""),"",(D11/OFFSET(D11,-6,0))^2-1),"") | BJ11: =IFERROR(IF(OR(E11="",OFFSET(E11,-6,0)=""),"",(E11/OFFSET(E11,-6,0))^2-1),"") | BK11: =IFERROR(IF(OR(F11="",OFFSET(F11,-6,0)=""),"",(F11/OFFSET(F11,-6,0))^2-1),"") | BL11: =IFERROR(IF(OR(G11="",OFFSET(G11,-6,0)=""),"",(G11/OFFSET(G11,-6,0))^2-1),"") | BM11: =IFERROR(IF(OR(H11="",OFFSET(H11,-6,0)=""),"",(H11/OFFSET(H11,-6,0))^2-1),"") | BN11: =IFERROR(IF(OR(I11="",OFFSET(I11,-6,0)=""),"",(I11/OFFSET(I11,-6,0))^2-1),"") | ... BS11: =IFERROR(IF(OR(N11="",OFFSET(N11,-6,0)=""),"",(N11/OFFSET(N11,-6,0))^2-1),"") | BX11: =IF('Macrobond Imports'!FG10="","",'Macrobond Imports'!FG10) | BY11: =IF('Macrobond Imports'!AI10="","",'Macrobond Imports'!AI10) | CA11: =IFERROR(IF(OR(BX11="",OFFSET(BX11,-12,0)=""),"",BX11/OFFSET(BX11,-12,0)-1),"") | CB11: =IFERROR(IF(OR(BY11="",OFFSET(BY11,-12,0)=""),"",BY11/OFFSET(BY11,-12,0)-1),"") | CC11: {=INDEX(MM_Headline,ROW()-5)} -> 0.0033675576 | CD11: {=INDEX(MM_Core,ROW()-5)} -> 0.0032608244 | CE11: {=INDEX(YY_Headline,ROW()-5)} -> 0.028436052 | CF11: {=INDEX(YY_Core,ROW()-5)} -> 0.035951217 | CG11: {=INDEX(Ann3_Headline,ROW()-5)} -> 0.038409812 | CH11: {=INDEX(Ann6_Headline,ROW()-5)} -> 0.029296697 | CK11: {=INDEX(ChartDates,ROW()-5)} -> 45566 | CL11: {=INDEX(UnprocEnergy_YY,ROW()-5)} -> -0.14423618 | CM11: {=INDEX(Transport_YY,ROW()-5)} -> 0.00089952026 | DA11: Paper & Plastics Wholesaling | DB11: FU | DC11: =INDEX('Macrobond Imports'!FU:FU,MATCH(MAX('Macrobond Imports'!$A:$A),'Macrobond Imports'!$A:$A,0)) -> 210.55 | DD11: {=INDEX('Macrobond Imports'!FU:FU,MATCH(MAX('Macrobond Imports'!$A:$A),'Macrobond Imports'!$A:$A,0)-1)} -> 216.409 | DE11: =IFERROR(IF(OR(DC11="",DD11="",DC11=0,DD11=0),"",DC11/DD11-1),"") -> -0.027073735 | DF11: WH | DG11: =IF(DE11="","",DE11+ROW()*0.000000001) -> -0.027073724
A12: =IF('Macrobond Imports'!A11="","",'Macrobond Imports'!A11) -> 17441 | B12: =IF('Macrobond Imports'!B11="","",'Macrobond Imports'!B11) | C12: =IF('Macrobond Imports'!C11="","",'Macrobond Imports'!C11) | D12: =IF('Macrobond Imports'!Z11="","",'Macrobond Imports'!Z11) | E12: =IF('Macrobond Imports'!BH11="","",'Macrobond Imports'!BH11) | F12: =IF('Macrobond Imports'!BJ11="","",'Macrobond Imports'!BJ11) | G12: =IF('Macrobond Imports'!BK11="","",'Macrobond Imports'!BK11) | H12: =IF('Macrobond Imports'!BL11="","",'Macrobond Imports'!BL11) | I12: =IF('Macrobond Imports'!BS11="","",'Macrobond Imports'!BS11) | J12: =IF('Macrobond Imports'!AA11="","",'Macrobond Imports'!AA11) | K12: =IF('Macrobond Imports'!DF11="","",'Macrobond Imports'!DF11) -> 24 | L12: =IF('Macrobond Imports'!EA11="","",'Macrobond Imports'!EA11) -> 33.7 | M12: =IF('Macrobond Imports'!FA11="","",'Macrobond Imports'!FA11) | N12: =IF('Macrobond Imports'!FC11="","",'Macrobond Imports'!FC11) | P12: =A12 -> 17441 | Q12: =IF(OR(B12="",N(B11)=0),"",B12/B11-1) | R12: =IF(OR(C12="",N(C11)=0),"",C12/C11-1) | S12: =IF(OR(D12="",N(D11)=0),"",D12/D11-1) | T12: =IF(OR(E12="",N(E11)=0),"",E12/E11-1) | U12: =IF(OR(F12="",N(F11)=0),"",F12/F11-1) | V12: =IF(OR(G12="",N(G11)=0),"",G12/G11-1) | W12: =IF(OR(H12="",N(H11)=0),"",H12/H11-1) | X12: =IF(OR(I12="",N(I11)=0),"",I12/I11-1) | ... AC12: =IF(OR(N12="",N(N11)=0),"",N12/N11-1) | AE12: =IFERROR(IF(OR(B12="",OFFSET(B12,-12,0)=""),"",B12/OFFSET(B12,-12,0)-1),"") | AF12: =IFERROR(IF(OR(C12="",OFFSET(C12,-12,0)=""),"",C12/OFFSET(C12,-12,0)-1),"") | AG12: =IFERROR(IF(OR(D12="",OFFSET(D12,-12,0)=""),"",D12/OFFSET(D12,-12,0)-1),"") | AH12: =IFERROR(IF(OR(E12="",OFFSET(E12,-12,0)=""),"",E12/OFFSET(E12,-12,0)-1),"") | AI12: =IFERROR(IF(OR(F12="",OFFSET(F12,-12,0)=""),"",F12/OFFSET(F12,-12,0)-1),"") | AJ12: =IFERROR(IF(OR(G12="",OFFSET(G12,-12,0)=""),"",G12/OFFSET(G12,-12,0)-1),"") | AK12: =IFERROR(IF(OR(H12="",OFFSET(H12,-12,0)=""),"",H12/OFFSET(H12,-12,0)-1),"") | AL12: =IFERROR(IF(OR(I12="",OFFSET(I12,-12,0)=""),"",I12/OFFSET(I12,-12,0)-1),"") | ... AQ12: =IFERROR(IF(OR(N12="",OFFSET(N12,-12,0)=""),"",N12/OFFSET(N12,-12,0)-1),"") | AS12: =IFERROR(IF(OR(B12="",OFFSET(B12,-3,0)=""),"",(B12/OFFSET(B12,-3,0))^4-1),"") | AT12: =IFERROR(IF(OR(C12="",OFFSET(C12,-3,0)=""),"",(C12/OFFSET(C12,-3,0))^4-1),"") | AU12: =IFERROR(IF(OR(D12="",OFFSET(D12,-3,0)=""),"",(D12/OFFSET(D12,-3,0))^4-1),"") | AV12: =IFERROR(IF(OR(E12="",OFFSET(E12,-3,0)=""),"",(E12/OFFSET(E12,-3,0))^4-1),"") | AW12: =IFERROR(IF(OR(F12="",OFFSET(F12,-3,0)=""),"",(F12/OFFSET(F12,-3,0))^4-1),"") | AX12: =IFERROR(IF(OR(G12="",OFFSET(G12,-3,0)=""),"",(G12/OFFSET(G12,-3,0))^4-1),"") | AY12: =IFERROR(IF(OR(H12="",OFFSET(H12,-3,0)=""),"",(H12/OFFSET(H12,-3,0))^4-1),"") | AZ12: =IFERROR(IF(OR(I12="",OFFSET(I12,-3,0)=""),"",(I12/OFFSET(I12,-3,0))^4-1),"") | ... BE12: =IFERROR(IF(OR(N12="",OFFSET(N12,-3,0)=""),"",(N12/OFFSET(N12,-3,0))^4-1),"") | BG12: =IFERROR(IF(OR(B12="",OFFSET(B12,-6,0)=""),"",(B12/OFFSET(B12,-6,0))^2-1),"") | BH12: =IFERROR(IF(OR(C12="",OFFSET(C12,-6,0)=""),"",(C12/OFFSET(C12,-6,0))^2-1),"") | BI12: =IFERROR(IF(OR(D12="",OFFSET(D12,-6,0)=""),"",(D12/OFFSET(D12,-6,0))^2-1),"") | BJ12: =IFERROR(IF(OR(E12="",OFFSET(E12,-6,0)=""),"",(E12/OFFSET(E12,-6,0))^2-1),"") | BK12: =IFERROR(IF(OR(F12="",OFFSET(F12,-6,0)=""),"",(F12/OFFSET(F12,-6,0))^2-1),"") | BL12: =IFERROR(IF(OR(G12="",OFFSET(G12,-6,0)=""),"",(G12/OFFSET(G12,-6,0))^2-1),"") | BM12: =IFERROR(IF(OR(H12="",OFFSET(H12,-6,0)=""),"",(H12/OFFSET(H12,-6,0))^2-1),"") | BN12: =IFERROR(IF(OR(I12="",OFFSET(I12,-6,0)=""),"",(I12/OFFSET(I12,-6,0))^2-1),"") | ... BS12: =IFERROR(IF(OR(N12="",OFFSET(N12,-6,0)=""),"",(N12/OFFSET(N12,-6,0))^2-1),"") | BX12: =IF('Macrobond Imports'!FG11="","",'Macrobond Imports'!FG11) | BY12: =IF('Macrobond Imports'!AI11="","",'Macrobond Imports'!AI11) | CA12: =IFERROR(IF(OR(BX12="",OFFSET(BX12,-12,0)=""),"",BX12/OFFSET(BX12,-12,0)-1),"") | CB12: =IFERROR(IF(OR(BY12="",OFFSET(BY12,-12,0)=""),"",BY12/OFFSET(BY12,-12,0)-1),"") | CC12: {=INDEX(MM_Headline,ROW()-5)} -> 0.0010458392 | CD12: {=INDEX(MM_Core,ROW()-5)} -> -3.4503461e-05 | CE12: {=INDEX(YY_Headline,ROW()-5)} -> 0.02889682 | CF12: {=INDEX(YY_Core,ROW()-5)} -> 0.033713316 | CG12: {=INDEX(Ann3_Headline,ROW()-5)} -> 0.028861146 | CH12: {=INDEX(Ann6_Headline,ROW()-5)} -> 0.031064624 | CK12: {=INDEX(ChartDates,ROW()-5)} -> 45597 | CL12: {=INDEX(UnprocEnergy_YY,ROW()-5)} -> -0.12329211 | CM12: {=INDEX(Transport_YY,ROW()-5)} -> -0.0012733418 | DA12: Apparel Wholesaling | DB12: FV | DC12: =INDEX('Macrobond Imports'!FV:FV,MATCH(MAX('Macrobond Imports'!$A:$A),'Macrobond Imports'!$A:$A,0)) -> 132.77 | DD12: {=INDEX('Macrobond Imports'!FV:FV,MATCH(MAX('Macrobond Imports'!$A:$A),'Macrobond Imports'!$A:$A,0)-1)} -> 134.482 | DE12: =IFERROR(IF(OR(DC12="",DD12="",DC12=0,DD12=0),"",DC12/DD12-1),"") -> -0.012730328 | DF12: WH | DG12: =IF(DE12="","",DE12+ROW()*0.000000001) -> -0.012730316
A13: =IF('Macrobond Imports'!A12="","",'Macrobond Imports'!A12) -> 17472 | B13: =IF('Macrobond Imports'!B12="","",'Macrobond Imports'!B12) | C13: =IF('Macrobond Imports'!C12="","",'Macrobond Imports'!C12) | D13: =IF('Macrobond Imports'!Z12="","",'Macrobond Imports'!Z12) | E13: =IF('Macrobond Imports'!BH12="","",'Macrobond Imports'!BH12) | F13: =IF('Macrobond Imports'!BJ12="","",'Macrobond Imports'!BJ12) | G13: =IF('Macrobond Imports'!BK12="","",'Macrobond Imports'!BK12) | H13: =IF('Macrobond Imports'!BL12="","",'Macrobond Imports'!BL12) | I13: =IF('Macrobond Imports'!BS12="","",'Macrobond Imports'!BS12) | J13: =IF('Macrobond Imports'!AA12="","",'Macrobond Imports'!AA12) | K13: =IF('Macrobond Imports'!DF12="","",'Macrobond Imports'!DF12) -> 24.3 | L13: =IF('Macrobond Imports'!EA12="","",'Macrobond Imports'!EA12) -> 33.9 | M13: =IF('Macrobond Imports'!FA12="","",'Macrobond Imports'!FA12) | N13: =IF('Macrobond Imports'!FC12="","",'Macrobond Imports'!FC12) | P13: =A13 -> 17472 | Q13: =IF(OR(B13="",N(B12)=0),"",B13/B12-1) | R13: =IF(OR(C13="",N(C12)=0),"",C13/C12-1) | S13: =IF(OR(D13="",N(D12)=0),"",D13/D12-1) | T13: =IF(OR(E13="",N(E12)=0),"",E13/E12-1) | U13: =IF(OR(F13="",N(F12)=0),"",F13/F12-1) | V13: =IF(OR(G13="",N(G12)=0),"",G13/G12-1) | W13: =IF(OR(H13="",N(H12)=0),"",H13/H12-1) | X13: =IF(OR(I13="",N(I12)=0),"",I13/I12-1) | ... AC13: =IF(OR(N13="",N(N12)=0),"",N13/N12-1) | AE13: =IFERROR(IF(OR(B13="",OFFSET(B13,-12,0)=""),"",B13/OFFSET(B13,-12,0)-1),"") | AF13: =IFERROR(IF(OR(C13="",OFFSET(C13,-12,0)=""),"",C13/OFFSET(C13,-12,0)-1),"") | AG13: =IFERROR(IF(OR(D13="",OFFSET(D13,-12,0)=""),"",D13/OFFSET(D13,-12,0)-1),"") | AH13: =IFERROR(IF(OR(E13="",OFFSET(E13,-12,0)=""),"",E13/OFFSET(E13,-12,0)-1),"") | AI13: =IFERROR(IF(OR(F13="",OFFSET(F13,-12,0)=""),"",F13/OFFSET(F13,-12,0)-1),"") | AJ13: =IFERROR(IF(OR(G13="",OFFSET(G13,-12,0)=""),"",G13/OFFSET(G13,-12,0)-1),"") | AK13: =IFERROR(IF(OR(H13="",OFFSET(H13,-12,0)=""),"",H13/OFFSET(H13,-12,0)-1),"") | AL13: =IFERROR(IF(OR(I13="",OFFSET(I13,-12,0)=""),"",I13/OFFSET(I13,-12,0)-1),"") | ... AQ13: =IFERROR(IF(OR(N13="",OFFSET(N13,-12,0)=""),"",N13/OFFSET(N13,-12,0)-1),"") | AS13: =IFERROR(IF(OR(B13="",OFFSET(B13,-3,0)=""),"",(B13/OFFSET(B13,-3,0))^4-1),"") | AT13: =IFERROR(IF(OR(C13="",OFFSET(C13,-3,0)=""),"",(C13/OFFSET(C13,-3,0))^4-1),"") | AU13: =IFERROR(IF(OR(D13="",OFFSET(D13,-3,0)=""),"",(D13/OFFSET(D13,-3,0))^4-1),"") | AV13: =IFERROR(IF(OR(E13="",OFFSET(E13,-3,0)=""),"",(E13/OFFSET(E13,-3,0))^4-1),"") | AW13: =IFERROR(IF(OR(F13="",OFFSET(F13,-3,0)=""),"",(F13/OFFSET(F13,-3,0))^4-1),"") | AX13: =IFERROR(IF(OR(G13="",OFFSET(G13,-3,0)=""),"",(G13/OFFSET(G13,-3,0))^4-1),"") | AY13: =IFERROR(IF(OR(H13="",OFFSET(H13,-3,0)=""),"",(H13/OFFSET(H13,-3,0))^4-1),"") | AZ13: =IFERROR(IF(OR(I13="",OFFSET(I13,-3,0)=""),"",(I13/OFFSET(I13,-3,0))^4-1),"") | ... BE13: =IFERROR(IF(OR(N13="",OFFSET(N13,-3,0)=""),"",(N13/OFFSET(N13,-3,0))^4-1),"") | BG13: =IFERROR(IF(OR(B13="",OFFSET(B13,-6,0)=""),"",(B13/OFFSET(B13,-6,0))^2-1),"") | BH13: =IFERROR(IF(OR(C13="",OFFSET(C13,-6,0)=""),"",(C13/OFFSET(C13,-6,0))^2-1),"") | BI13: =IFERROR(IF(OR(D13="",OFFSET(D13,-6,0)=""),"",(D13/OFFSET(D13,-6,0))^2-1),"") | BJ13: =IFERROR(IF(OR(E13="",OFFSET(E13,-6,0)=""),"",(E13/OFFSET(E13,-6,0))^2-1),"") | BK13: =IFERROR(IF(OR(F13="",OFFSET(F13,-6,0)=""),"",(F13/OFFSET(F13,-6,0))^2-1),"") | BL13: =IFERROR(IF(OR(G13="",OFFSET(G13,-6,0)=""),"",(G13/OFFSET(G13,-6,0))^2-1),"") | BM13: =IFERROR(IF(OR(H13="",OFFSET(H13,-6,0)=""),"",(H13/OFFSET(H13,-6,0))^2-1),"") | BN13: =IFERROR(IF(OR(I13="",OFFSET(I13,-6,0)=""),"",(I13/OFFSET(I13,-6,0))^2-1),"") | ... BS13: =IFERROR(IF(OR(N13="",OFFSET(N13,-6,0)=""),"",(N13/OFFSET(N13,-6,0))^2-1),"") | BX13: =IF('Macrobond Imports'!FG12="","",'Macrobond Imports'!FG12) | BY13: =IF('Macrobond Imports'!AI12="","",'Macrobond Imports'!AI12) | CA13: =IFERROR(IF(OR(BX13="",OFFSET(BX13,-12,0)=""),"",BX13/OFFSET(BX13,-12,0)-1),"") | CB13: =IFERROR(IF(OR(BY13="",OFFSET(BY13,-12,0)=""),"",BY13/OFFSET(BY13,-12,0)-1),"") | CC13: {=INDEX(MM_Headline,ROW()-5)} -> 0.0041311874 | CD13: {=INDEX(MM_Core,ROW()-5)} -> 0.0031813288 | CE13: {=INDEX(YY_Headline,ROW()-5)} -> 0.03437555 | CF13: {=INDEX(YY_Core,ROW()-5)} -> 0.037327491 | CG13: {=INDEX(Ann3_Headline,ROW()-5)} -> 0.034708227 | CH13: {=INDEX(Ann6_Headline,ROW()-5)} -> 0.030364641 | CK13: {=INDEX(ChartDates,ROW()-5)} -> 45627 | CL13: {=INDEX(UnprocEnergy_YY,ROW()-5)} -> 0.024996944 | CM13: {=INDEX(Transport_YY,ROW()-5)} -> 0.029559592 | DA13: Food & Alcohol Wholesaling | DB13: FW | DC13: =INDEX('Macrobond Imports'!FW:FW,MATCH(MAX('Macrobond Imports'!$A:$A),'Macrobond Imports'!$A:$A,0)) -> 160.521 | DD13: {=INDEX('Macrobond Imports'!FW:FW,MATCH(MAX('Macrobond Imports'!$A:$A),'Macrobond Imports'!$A:$A,0)-1)} -> 160.745 | DE13: =IFERROR(IF(OR(DC13="",DD13="",DC13=0,DD13=0),"",DC13/DD13-1),"") -> -0.0013935115 | DF13: WH | DG13: =IF(DE13="","",DE13+ROW()*0.000000001) -> -0.0013934985
A14: =IF('Macrobond Imports'!A13="","",'Macrobond Imports'!A13) -> 17502 | B14: =IF('Macrobond Imports'!B13="","",'Macrobond Imports'!B13) | C14: =IF('Macrobond Imports'!C13="","",'Macrobond Imports'!C13) | D14: =IF('Macrobond Imports'!Z13="","",'Macrobond Imports'!Z13) | E14: =IF('Macrobond Imports'!BH13="","",'Macrobond Imports'!BH13) | F14: =IF('Macrobond Imports'!BJ13="","",'Macrobond Imports'!BJ13) | G14: =IF('Macrobond Imports'!BK13="","",'Macrobond Imports'!BK13) | H14: =IF('Macrobond Imports'!BL13="","",'Macrobond Imports'!BL13) | I14: =IF('Macrobond Imports'!BS13="","",'Macrobond Imports'!BS13) | J14: =IF('Macrobond Imports'!AA13="","",'Macrobond Imports'!AA13) | K14: =IF('Macrobond Imports'!DF13="","",'Macrobond Imports'!DF13) -> 24.5 | L14: =IF('Macrobond Imports'!EA13="","",'Macrobond Imports'!EA13) -> 35.3 | M14: =IF('Macrobond Imports'!FA13="","",'Macrobond Imports'!FA13) | N14: =IF('Macrobond Imports'!FC13="","",'Macrobond Imports'!FC13) | P14: =A14 -> 17502 | Q14: =IF(OR(B14="",N(B13)=0),"",B14/B13-1) | R14: =IF(OR(C14="",N(C13)=0),"",C14/C13-1) | S14: =IF(OR(D14="",N(D13)=0),"",D14/D13-1) | T14: =IF(OR(E14="",N(E13)=0),"",E14/E13-1) | U14: =IF(OR(F14="",N(F13)=0),"",F14/F13-1) | V14: =IF(OR(G14="",N(G13)=0),"",G14/G13-1) | W14: =IF(OR(H14="",N(H13)=0),"",H14/H13-1) | X14: =IF(OR(I14="",N(I13)=0),"",I14/I13-1) | ... AC14: =IF(OR(N14="",N(N13)=0),"",N14/N13-1) | AE14: =IFERROR(IF(OR(B14="",OFFSET(B14,-12,0)=""),"",B14/OFFSET(B14,-12,0)-1),"") | AF14: =IFERROR(IF(OR(C14="",OFFSET(C14,-12,0)=""),"",C14/OFFSET(C14,-12,0)-1),"") | AG14: =IFERROR(IF(OR(D14="",OFFSET(D14,-12,0)=""),"",D14/OFFSET(D14,-12,0)-1),"") | AH14: =IFERROR(IF(OR(E14="",OFFSET(E14,-12,0)=""),"",E14/OFFSET(E14,-12,0)-1),"") | AI14: =IFERROR(IF(OR(F14="",OFFSET(F14,-12,0)=""),"",F14/OFFSET(F14,-12,0)-1),"") | AJ14: =IFERROR(IF(OR(G14="",OFFSET(G14,-12,0)=""),"",G14/OFFSET(G14,-12,0)-1),"") | AK14: =IFERROR(IF(OR(H14="",OFFSET(H14,-12,0)=""),"",H14/OFFSET(H14,-12,0)-1),"") | AL14: =IFERROR(IF(OR(I14="",OFFSET(I14,-12,0)=""),"",I14/OFFSET(I14,-12,0)-1),"") | ... AQ14: =IFERROR(IF(OR(N14="",OFFSET(N14,-12,0)=""),"",N14/OFFSET(N14,-12,0)-1),"") | AS14: =IFERROR(IF(OR(B14="",OFFSET(B14,-3,0)=""),"",(B14/OFFSET(B14,-3,0))^4-1),"") | AT14: =IFERROR(IF(OR(C14="",OFFSET(C14,-3,0)=""),"",(C14/OFFSET(C14,-3,0))^4-1),"") | AU14: =IFERROR(IF(OR(D14="",OFFSET(D14,-3,0)=""),"",(D14/OFFSET(D14,-3,0))^4-1),"") | AV14: =IFERROR(IF(OR(E14="",OFFSET(E14,-3,0)=""),"",(E14/OFFSET(E14,-3,0))^4-1),"") | AW14: =IFERROR(IF(OR(F14="",OFFSET(F14,-3,0)=""),"",(F14/OFFSET(F14,-3,0))^4-1),"") | AX14: =IFERROR(IF(OR(G14="",OFFSET(G14,-3,0)=""),"",(G14/OFFSET(G14,-3,0))^4-1),"") | AY14: =IFERROR(IF(OR(H14="",OFFSET(H14,-3,0)=""),"",(H14/OFFSET(H14,-3,0))^4-1),"") | AZ14: =IFERROR(IF(OR(I14="",OFFSET(I14,-3,0)=""),"",(I14/OFFSET(I14,-3,0))^4-1),"") | ... BE14: =IFERROR(IF(OR(N14="",OFFSET(N14,-3,0)=""),"",(N14/OFFSET(N14,-3,0))^4-1),"") | BG14: =IFERROR(IF(OR(B14="",OFFSET(B14,-6,0)=""),"",(B14/OFFSET(B14,-6,0))^2-1),"") | BH14: =IFERROR(IF(OR(C14="",OFFSET(C14,-6,0)=""),"",(C14/OFFSET(C14,-6,0))^2-1),"") | BI14: =IFERROR(IF(OR(D14="",OFFSET(D14,-6,0)=""),"",(D14/OFFSET(D14,-6,0))^2-1),"") | BJ14: =IFERROR(IF(OR(E14="",OFFSET(E14,-6,0)=""),"",(E14/OFFSET(E14,-6,0))^2-1),"") | BK14: =IFERROR(IF(OR(F14="",OFFSET(F14,-6,0)=""),"",(F14/OFFSET(F14,-6,0))^2-1),"") | BL14: =IFERROR(IF(OR(G14="",OFFSET(G14,-6,0)=""),"",(G14/OFFSET(G14,-6,0))^2-1),"") | BM14: =IFERROR(IF(OR(H14="",OFFSET(H14,-6,0)=""),"",(H14/OFFSET(H14,-6,0))^2-1),"") | BN14: =IFERROR(IF(OR(I14="",OFFSET(I14,-6,0)=""),"",(I14/OFFSET(I14,-6,0))^2-1),"") | ... BS14: =IFERROR(IF(OR(N14="",OFFSET(N14,-6,0)=""),"",(N14/OFFSET(N14,-6,0))^2-1),"") | BX14: =IF('Macrobond Imports'!FG13="","",'Macrobond Imports'!FG13) | BY14: =IF('Macrobond Imports'!AI13="","",'Macrobond Imports'!AI13) | CA14: =IFERROR(IF(OR(BX14="",OFFSET(BX14,-12,0)=""),"",BX14/OFFSET(BX14,-12,0)-1),"") | CB14: =IFERROR(IF(OR(BY14="",OFFSET(BY14,-12,0)=""),"",BY14/OFFSET(BY14,-12,0)-1),"") | CC14: {=INDEX(MM_Headline,ROW()-5)} -> 0.0062766912 | CD14: {=INDEX(MM_Core,ROW()-5)} -> 0.005572027 | CE14: {=INDEX(YY_Headline,ROW()-5)} -> 0.037867523 | CF14: {=INDEX(YY_Core,ROW()-5)} -> 0.039096098 | CG14: {=INDEX(Ann3_Headline,ROW()-5)} -> 0.046760524 | CH14: {=INDEX(Ann6_Headline,ROW()-5)} -> 0.042576807 | CK14: {=INDEX(ChartDates,ROW()-5)} -> 45658 | CL14: {=INDEX(UnprocEnergy_YY,ROW()-5)} -> 0.081114412 | CM14: {=INDEX(Transport_YY,ROW()-5)} -> 0.036323725 | DA14: Food & Alcohol Retailing | DB14: FX | DC14: =INDEX('Macrobond Imports'!FX:FX,MATCH(MAX('Macrobond Imports'!$A:$A),'Macrobond Imports'!$A:$A,0)) -> 196.376 | DD14: {=INDEX('Macrobond Imports'!FX:FX,MATCH(MAX('Macrobond Imports'!$A:$A),'Macrobond Imports'!$A:$A,0)-1)} -> 198.562 | DE14: =IFERROR(IF(OR(DC14="",DD14="",DC14=0,DD14=0),"",DC14/DD14-1),"") -> -0.011009156 | DF14: RT | DG14: =IF(DE14="","",DE14+ROW()*0.000000001) -> -0.011009142
